#VRML_SIM R2023a utf8

EXTERNPROTO "https://raw.githubusercontent.com/cyberbotics/webots/R2023a/projects/objects/backgrounds/protos/TexturedBackground.proto"
EXTERNPROTO "https://raw.githubusercontent.com/cyberbotics/webots/R2023a/projects/objects/backgrounds/protos/TexturedBackgroundLight.proto"
EXTERNPROTO "https://raw.githubusercontent.com/cyberbotics/webots/R2023a/projects/objects/floors/protos/RectangleArena.proto"
EXTERNPROTO "https://raw.githubusercontent.com/cyberbotics/webots/R2023a/projects/appearances/protos/Parquetry.proto"

WorldInfo {
  contactProperties [
    ContactProperties {
      material1 "friction"
    }
  ]
}
Viewpoint {
  orientation 0.4671557620544871 -0.571096248394882 -0.6749922733250971 4.5213956897972984
  position 0.42052175409155546 -1.65847986813731 1.862045939043615
}
TexturedBackground {
}
TexturedBackgroundLight {
}
RectangleArena {
  translation -0.62 0 0
  floorSize 2.7 2.7
  floorTileSize 5 5
  floorAppearance Parquetry {
    type "dark strip"
    colorOverride 0 0 0
    textureTransform TextureTransform {
    }
  }
}
DEF box_3 Solid {
  translation 0.5103692567173933 -0.8462266134607015 0.08061452191172998
  rotation -0.9984651347138541 0.030483663179933135 0.046239820933667096 -1.5627634932603938
  children [
    DEF box_3_shape Shape {
      appearance PBRAppearance {
        baseColor 1 0 0
        metalness 0
      }
      geometry Box {
        size 0.05 0.05 0.05
      }
    }
  ]
  name "solid(4)"
  boundingObject USE box_3_shape
  physics Physics {
    density 100
  }
  linearVelocity 1.6691087348889123e-06 7.861183513764534e-07 -4.6521926558590684e-07
  angularVelocity 5.157655350105761e-05 -9.537996358731147e-07 3.157549733087682e-06
}
DEF box_2 Solid {
  translation -0.4297833904544947 -1.1 0.019997488640000012
  rotation 0.004838944287239184 0.11211223573827629 -0.9936837682160006 1.0969938164895408e-15
  children [
    DEF box_2_shape Shape {
      appearance PBRAppearance {
        baseColor 0 1 0
        metalness 0
      }
      geometry Box {
        size 0.04 0.04 0.04
      }
    }
  ]
  name "solid(3)"
  boundingObject USE box_2_shape
  physics Physics {
    density 100
  }
  linearVelocity 2.3786831606930416e-17 2.9608851297125995e-17 9.714451465470149e-17
  angularVelocity -1.3499587596865423e-15 7.264149259111547e-17 4.2812890989104265e-16
}
DEF box_1 Solid {
  translation 0.029126699999999922 -0.745511 0.014998940520000002
  rotation 1.7765575810855095e-15 1.1582750929219614e-16 -1 0.1723004993155839
  children [
    DEF box_1_shape Shape {
      appearance PBRAppearance {
        baseColor 0 0 1
        metalness 0
      }
      geometry Box {
        size 0.03 0.03 0.03
      }
    }
  ]
  name "solid(2)"
  boundingObject USE box_1_shape
  physics Physics {
    density 100
  }
  linearVelocity -3.5855444352237054e-17 -8.426866812554269e-17 -3.455007774933381e-23
  angularVelocity 3.2124508814385145e-15 -3.2124508814385425e-15 4.59465590047087e-16
}
DEF maze Solid {
  translation -1.93 1.32 -0.00589861
  rotation 1 0 0 1.5708
  scale 0.001 0.001 0.001
  children [
    DEF maze_shape Shape {
      appearance PBRAppearance {
        metalness 0
      }
      geometry Mesh {
        url [
          "../solid bodies/arena/webotsArena.STL"
        ]
      }
      castShadows FALSE
    }
  ]
}
DEF rebel Robot {
  translation 0.5034372131314366 -0.8947693177115641 0.03307704662127829
  rotation -0.00025764505605296373 -0.005052099920350543 0.9999872048708525 3.0652674341070343
  scale 1.1 1.1 1.1
  children [
    Camera {
      translation 2.30255e-07 0.0613628 0.0403528
      rotation -0.1294279597735375 0.1294279597735375 0.9831056944488314 1.58784
      name "rebelEye"
      fieldOfView 1.5
      width 480
      height 320
    }
    DEF BoxDSensor5 DistanceSensor {
      translation 0.04 0.1 -0.01
      rotation 0 0 1 1.5708003061004252
      name "box_sensor_side2.2"
    }
    DEF BoxDSensor4 DistanceSensor {
      translation -0.04 0.1 -0.01
      rotation 0 0 1 1.5708003061004252
      name "box_sensor_side1.2"
    }
    DEF BoxDSensor3 DistanceSensor {
      translation -0.01 0.1 -0.01
      rotation 0 0 1 1.5708003061004252
      name "box_sensor_side1"
    }
    DEF BoxDSensor2 DistanceSensor {
      translation 0.01 0.1 -0.01
      rotation 0 0 1 1.5708003061004252
      name "box_sensor_side2"
    }
    DEF ClasterWheel BallJoint {
      jointParameters BallJointParameters {
        position 300.92960734232327
        anchor 0 -0.05 -0.017
      }
      jointParameters2 JointParameters {
        position 2.016207611152513
      }
      jointParameters3 JointParameters {
        position 172.68184654024282
        axis 0 1 0
      }
      endPoint Solid {
        translation 2.865053047332563e-06 -0.049995645297964936 -0.016992573728368036
        rotation -0.987528099374774 -0.15710856047795085 0.010254421962864642 2.7734250110091776
        children [
          DEF Claster Shape {
            appearance PBRAppearance {
              baseColor 0 0 1
              metalness 0
            }
            geometry Sphere {
              radius 0.014
            }
          }
        ]
        name "solid(2)"
        boundingObject USE Claster
        physics Physics {
        }
        linearVelocity 3.319428852571037e-09 1.9422868049055985e-09 -2.0029642493117226e-10
        angularVelocity -6.54413455630933e-07 6.17660039701019e-07 -1.2553531597595088e-10
      }
    }
    DEF waist HingeJoint {
      jointParameters HingeJointParameters {
        position -10.99999994150141
        axis 0 0 1
        anchor 0 0.04 0.012
      }
      device [
        PositionSensor {
          name "waist_sensor"
        }
        RotationalMotor {
          name "waist_motor"
          maxVelocity 4
          maxTorque 100
        }
      ]
      endPoint Solid {
        translation 3.992282794997894e-08 0.060000079847695384 0.011998186410560274
        rotation -2.090743903340669e-09 -3.557773876352747e-08 -0.9999999999999994 3.141592463354603
        scale 0.2 0.2 0.2
        children [
          DEF waist Group {
            children [
              Transform {
                rotation 0 0 1 0.3926996938995747
                children [
                  Shape {
                    appearance Appearance {
                      material Material {
                        diffuseColor 0.231373 0.231373 0.231373
                      }
                    }
                    geometry Cylinder {
                      height 0.02
                      radius 0.15
                      subdivision 20
                    }
                  }
                ]
              }
              Transform {
                translation 0.1 0 0.11
                children [
                  Shape {
                    appearance Appearance {
                      material Material {
                        diffuseColor 0.231373 0.231373 0.231373
                      }
                    }
                    geometry Box {
                      size 0.01 0.1 0.2
                    }
                  }
                ]
              }
              Transform {
                translation -0.1 0 0.11
                children [
                  Shape {
                    appearance Appearance {
                      material Material {
                        diffuseColor 0.231373 0.231373 0.231373
                      }
                    }
                    geometry Box {
                      size 0.01 0.1 0.2
                    }
                  }
                ]
              }
              Transform {
                translation 0.1 0 0.21
                rotation 0 1 0 -1.5707953071795862
                children [
                  Shape {
                    appearance Appearance {
                      material Material {
                        diffuseColor 0.231373 0.231373 0.231373
                      }
                    }
                    geometry Cylinder {
                      height 0.02
                      radius 0.05
                      subdivision 20
                    }
                  }
                ]
              }
              Transform {
                translation -0.1 0 0.21
                rotation 0 1 0 -1.5707953071795862
                children [
                  Shape {
                    appearance Appearance {
                      material Material {
                        diffuseColor 0.231373 0.231373 0.231373
                      }
                    }
                    geometry Cylinder {
                      height 0.02
                      radius 0.05
                      subdivision 20
                    }
                  }
                ]
              }
            ]
          }
          DEF shourlder HingeJoint {
            jointParameters HingeJointParameters {
              position -0.7000000668702677
              anchor 0 0 0.21
            }
            device [
              PositionSensor {
                name "shoulder_sensor"
              }
              RotationalMotor {
                name "shoulder_motor"
                maxVelocity 4
                maxTorque 200
              }
            ]
            endPoint Solid {
              translation 0 0 0.21
              rotation -1 0 0 0.7000000668702681
              children [
                DEF amr Group {
                  children [
                    Transform {
                      rotation 0 1 0 -1.5707953071795862
                      children [
                        Shape {
                          appearance Appearance {
                            material Material {
                              diffuseColor 0.333333 0.333333 1
                            }
                          }
                          geometry Cylinder {
                            height 0.225
                            radius 0.008
                            subdivision 20
                          }
                        }
                      ]
                    }
                    Transform {
                      translation 0 0 0.03
                      children [
                        Shape {
                          appearance Appearance {
                            material Material {
                              diffuseColor 0.231373 0.231373 0.231373
                            }
                          }
                          geometry Box {
                            size 0.15 0.08 0.4
                          }
                        }
                      ]
                    }
                    Transform {
                      translation 0.07 0 0.28
                      children [
                        Shape {
                          appearance Appearance {
                            material Material {
                              diffuseColor 0.231373 0.231373 0.231373
                            }
                          }
                          geometry Box {
                            size 0.01 0.08 0.1
                          }
                        }
                      ]
                    }
                    Transform {
                      translation -0.07 0 0.28
                      children [
                        Shape {
                          appearance Appearance {
                            material Material {
                              diffuseColor 0.231373 0.231373 0.231373
                            }
                          }
                          geometry Box {
                            size 0.01 0.08 0.1
                          }
                        }
                      ]
                    }
                    Transform {
                      translation 0.07 0 0.33
                      rotation 0 1 0 -1.5707953071795862
                      children [
                        Shape {
                          appearance Appearance {
                            material Material {
                              diffuseColor 0.231373 0.231373 0.231373
                            }
                          }
                          geometry Cylinder {
                            height 0.02
                            radius 0.04
                            subdivision 20
                          }
                        }
                      ]
                    }
                    Transform {
                      translation -0.07 0 0.33
                      rotation 0 1 0 -1.5707953071795862
                      children [
                        Shape {
                          appearance Appearance {
                            material Material {
                              diffuseColor 0.231373 0.231373 0.231373
                            }
                          }
                          geometry Cylinder {
                            height 0.02
                            radius 0.04
                            subdivision 20
                          }
                        }
                      ]
                    }
                  ]
                }
                DEF elbow HingeJoint {
                  jointParameters HingeJointParameters {
                    position -1.0000000349224087
                    anchor 0 0 0.33
                  }
                  device [
                    PositionSensor {
                      name "elbow_sensor"
                    }
                    RotationalMotor {
                      name "elbow_motor"
                      maxVelocity 4
                      maxTorque 200
                    }
                  ]
                  endPoint Solid {
                    translation 0 0 0.33
                    rotation -0.9999999999999999 0 0 1.0000000349224087
                    children [
                      DEF forearm Group {
                        children [
                          Transform {
                            rotation 0 1 0 -1.5707953071795862
                            children [
                              Shape {
                                appearance Appearance {
                                  material Material {
                                    diffuseColor 0.333333 0.333333 1
                                  }
                                }
                                geometry Cylinder {
                                  height 0.165
                                  radius 0.006
                                  subdivision 20
                                }
                              }
                            ]
                          }
                          Transform {
                            translation 0 0 0.1
                            children [
                              Shape {
                                appearance Appearance {
                                  material Material {
                                    diffuseColor 0.231373 0.231373 0.231373
                                  }
                                }
                                geometry Box {
                                  size 0.1 0.06 0.34
                                }
                              }
                            ]
                          }
                          Transform {
                            translation 0 0 0.3
                            children [
                              Shape {
                                appearance Appearance {
                                  material Material {
                                    diffuseColor 0.231373 0.231373 0.231373
                                  }
                                }
                                geometry Cylinder {
                                  height 0.06
                                  radius 0.03
                                  subdivision 20
                                }
                              }
                            ]
                          }
                        ]
                      }
                      DEF wrist HingeJoint {
                        jointParameters HingeJointParameters {
                          position 8.68603125501426e-10
                          axis 0 0 1
                          anchor 0 0 0.34
                        }
                        device [
                          PositionSensor {
                            name "wrist_sensor"
                          }
                          RotationalMotor {
                            name "wrist_motor"
                            maxVelocity 4
                            maxTorque 50
                          }
                        ]
                        endPoint Solid {
                          translation 0 0 0.34
                          children [
                            DEF wrist Group {
                              children [
                                Transform {
                                  children [
                                    Shape {
                                      appearance Appearance {
                                        material Material {
                                          diffuseColor 0.333333 0.333333 1
                                        }
                                      }
                                      geometry Cylinder {
                                        height 0.02
                                        radius 0.05
                                        subdivision 20
                                      }
                                    }
                                  ]
                                }
                                Transform {
                                  translation 0.04 0 0.0225
                                  children [
                                    Shape {
                                      appearance Appearance {
                                        material Material {
                                          diffuseColor 0.333333 0.333333 1
                                        }
                                      }
                                      geometry Box {
                                        size 0.01 0.04 0.025
                                      }
                                    }
                                  ]
                                }
                                Transform {
                                  translation -0.04 0 0.0225
                                  children [
                                    Shape {
                                      appearance Appearance {
                                        material Material {
                                          diffuseColor 0.333333 0.333333 1
                                        }
                                      }
                                      geometry Box {
                                        size 0.01 0.04 0.025
                                      }
                                    }
                                  ]
                                }
                                Transform {
                                  translation 0.04 0 0.035
                                  rotation 0 1 0 -1.5707953071795862
                                  children [
                                    Shape {
                                      appearance Appearance {
                                        material Material {
                                          diffuseColor 0.333333 0.333333 1
                                        }
                                      }
                                      geometry Cylinder {
                                        height 0.012
                                        radius 0.02
                                        subdivision 20
                                      }
                                    }
                                  ]
                                }
                                Transform {
                                  translation -0.04 0 0.035
                                  rotation 0 1 0 -1.5707953071795862
                                  children [
                                    Shape {
                                      appearance Appearance {
                                        material Material {
                                          diffuseColor 0.333333 0.333333 1
                                        }
                                      }
                                      geometry Cylinder {
                                        height 0.012
                                        radius 0.02
                                        subdivision 20
                                      }
                                    }
                                  ]
                                }
                              ]
                            }
                            DEF pitch HingeJoint {
                              jointParameters HingeJointParameters {
                                position -1.469999998290004
                                anchor 0 0 0.035
                              }
                              device [
                                PositionSensor {
                                  name "pitch_sensor"
                                }
                                RotationalMotor {
                                  name "pitch_motor"
                                  acceleration 1
                                  maxVelocity 4
                                  maxTorque 50
                                }
                              ]
                              endPoint Solid {
                                translation 0 0 0.035
                                rotation -1 0 0 1.469999998290004
                                children [
                                  DEF right_a HingeJoint {
                                    jointParameters HingeJointParameters {
                                      position -0.006190923615110033
                                      axis 0 1 0
                                      anchor 0.14 0 0.09
                                    }
                                    device [
                                      DEF right_finger_sensor PositionSensor {
                                      }
                                      RotationalMotor {
                                        name "right_finger_motor"
                                        maxTorque 50
                                      }
                                    ]
                                    endPoint Solid {
                                      translation 0.14 0 0.09
                                      rotation 0 -0.9999999999999999 0 0.006190923615101329
                                      children [
                                        Group {
                                          children [
                                            Transform {
                                              rotation 1 0 0 -1.5707953071795862
                                              children [
                                                Shape {
                                                  appearance Appearance {
                                                    material Material {
                                                      diffuseColor 0.333333 0.333333 1
                                                    }
                                                  }
                                                  geometry Cylinder {
                                                    height 0.065
                                                    radius 0.003
                                                    subdivision 20
                                                  }
                                                }
                                              ]
                                            }
                                            Transform {
                                              translation 0 0 0.1
                                              rotation 1 0 0 -1.5707953071795862
                                              children [
                                                Shape {
                                                  appearance Appearance {
                                                    material Material {
                                                      diffuseColor 0.333333 0.333333 1
                                                    }
                                                  }
                                                  geometry Cylinder {
                                                    height 0.065
                                                    radius 0.003
                                                    subdivision 20
                                                  }
                                                }
                                              ]
                                            }
                                            Transform {
                                              translation 0 0 0.05
                                              scale 1 1 2
                                              children [
                                                Shape {
                                                  appearance Appearance {
                                                    material Material {
                                                      diffuseColor 0.333333 0.333333 1
                                                    }
                                                  }
                                                  geometry Box {
                                                    size 0.01 0.038 0.05
                                                  }
                                                }
                                              ]
                                            }
                                          ]
                                        }
                                        DEF r__finger HingeJoint {
                                          jointParameters HingeJointParameters {
                                            position 0.012231063086130417
                                            axis 0 1 0
                                            anchor 0 0 0.1
                                          }
                                          endPoint Solid {
                                            translation 0 0 0.1
                                            rotation 0.0061154934231963535 4.869932305596822e-06 0.9999813001833957 3.1400000297823176
                                            children [
                                              DEF rf_finger Group {
                                                children [
                                                  Transform {
                                                    translation -0.02 0.025 0
                                                    children [
                                                      Shape {
                                                        appearance Appearance {
                                                          material Material {
                                                            diffuseColor 0.231373 0.231373 0.231373
                                                          }
                                                        }
                                                        geometry Box {
                                                          size 0.06 0.01 0.022
                                                        }
                                                      }
                                                    ]
                                                  }
                                                  Transform {
                                                    translation -0.02 -0.025 0
                                                    children [
                                                      Shape {
                                                        appearance Appearance {
                                                          material Material {
                                                            diffuseColor 0.231373 0.231373 0.231373
                                                          }
                                                        }
                                                        geometry Box {
                                                          size 0.06 0.01 0.022
                                                        }
                                                      }
                                                    ]
                                                  }
                                                  Transform {
                                                    translation -0.01 0 0.056
                                                    children [
                                                      Shape {
                                                        appearance Appearance {
                                                          material Material {
                                                            diffuseColor 0.231373 0.231373 0.231373
                                                          }
                                                        }
                                                        geometry Box {
                                                          size 0.04 0.06 0.09
                                                        }
                                                      }
                                                    ]
                                                  }
                                                  Transform {
                                                    translation -0.04 0 0.026
                                                    children [
                                                      Shape {
                                                        appearance Appearance {
                                                          material Material {
                                                            diffuseColor 0.231373 0.231373 0.231373
                                                          }
                                                        }
                                                        geometry Box {
                                                          size 0.02 0.06 0.03
                                                        }
                                                      }
                                                    ]
                                                  }
                                                  Transform {
                                                    translation 0 0 0.111
                                                    children [
                                                      Shape {
                                                        appearance Appearance {
                                                          material Material {
                                                            diffuseColor 0.231373 0.231373 0.231373
                                                            emissiveColor 0 0.2 0.4
                                                            shininess 0
                                                          }
                                                        }
                                                        geometry Box {
                                                          size 0.02 0.06 0.2
                                                        }
                                                      }
                                                    ]
                                                  }
                                                  Transform {
                                                    translation -0.0306 0 0.0678
                                                    rotation 0 1 0 0.32
                                                    children [
                                                      Shape {
                                                        appearance Appearance {
                                                          material Material {
                                                            diffuseColor 0.231373 0.231373 0.231373
                                                          }
                                                        }
                                                        geometry Box {
                                                          size 0.02 0.056 0.0635
                                                        }
                                                      }
                                                    ]
                                                  }
                                                  Transform {
                                                    translation -0.01 0 0.101
                                                    rotation 1 0 0 -1.5707953071795862
                                                    children [
                                                      Shape {
                                                        appearance Appearance {
                                                          material Material {
                                                            diffuseColor 0.231373 0.231373 0.231373
                                                          }
                                                        }
                                                        geometry Cylinder {
                                                          height 0.058
                                                          radius 0.02
                                                          subdivision 20
                                                        }
                                                      }
                                                    ]
                                                  }
                                                ]
                                              }
                                            ]
                                            name "right_finger"
                                            boundingObject USE rf_finger
                                            physics Physics {
                                            }
                                            linearVelocity 1.604804863146848e-06 -1.0229230440111415e-07 -1.1550157842293473e-08
                                            angularVelocity 4.140750550605343e-08 5.807103846887399e-07 5.54697776735733e-07
                                          }
                                        }
                                      ]
                                      name "solid_1(1)"
                                      boundingObject DEF phalanx_1 Group {
                                        children [
                                          Transform {
                                            rotation 1 0 0 -1.5707953071795862
                                            children [
                                              Shape {
                                                appearance Appearance {
                                                  material Material {
                                                    diffuseColor 0.333333 0.333333 1
                                                  }
                                                }
                                                geometry Cylinder {
                                                  height 0.065
                                                  radius 0.003
                                                  subdivision 20
                                                }
                                              }
                                            ]
                                          }
                                          Transform {
                                            translation 0 0 0.1
                                            rotation 1 0 0 -1.5707953071795862
                                            children [
                                              Shape {
                                                appearance Appearance {
                                                  material Material {
                                                    diffuseColor 0.333333 0.333333 1
                                                  }
                                                }
                                                geometry Cylinder {
                                                  height 0.065
                                                  radius 0.003
                                                  subdivision 20
                                                }
                                              }
                                            ]
                                          }
                                          Transform {
                                            translation 0 0 0.025
                                            children [
                                              Shape {
                                                appearance Appearance {
                                                  material Material {
                                                    diffuseColor 0.333333 0.333333 1
                                                  }
                                                }
                                                geometry Box {
                                                  size 0.01 0.038 0.05
                                                }
                                              }
                                            ]
                                          }
                                        ]
                                      }
                                      physics Physics {
                                      }
                                      linearVelocity 4.2878577622611443e-07 -1.318125421470792e-08 -3.0267783870184054e-09
                                      angularVelocity -5.81149366785805e-06 -7.59501584326706e-05 1.959341517278532e-06
                                    }
                                  }
                                  DEF pitch Group {
                                    children [
                                      Transform {
                                        rotation 0 1 0 -1.5707953071795862
                                        children [
                                          Shape {
                                            appearance Appearance {
                                              material Material {
                                                diffuseColor 0.231373 0.231373 0.231373
                                              }
                                            }
                                            geometry Cylinder {
                                              height 0.095
                                              radius 0.004
                                              subdivision 20
                                            }
                                          }
                                        ]
                                      }
                                      Transform {
                                        rotation 0 1 0 -1.5707953071795862
                                        children [
                                          Shape {
                                            appearance Appearance {
                                              material Material {
                                                diffuseColor 0.231373 0.231373 0.231373
                                              }
                                            }
                                            geometry Cylinder {
                                              height 0.06
                                              radius 0.02
                                              subdivision 20
                                            }
                                          }
                                        ]
                                      }
                                      Transform {
                                        translation 0 0 0.015
                                        children [
                                          Shape {
                                            appearance Appearance {
                                              material Material {
                                                diffuseColor 0.231373 0.231373 0.231373
                                              }
                                            }
                                            geometry Box {
                                              size 0.058 0.04 0.07
                                            }
                                          }
                                        ]
                                      }
                                      Transform {
                                        translation 0 0 0.055
                                        children [
                                          Shape {
                                            appearance Appearance {
                                              material Material {
                                                diffuseColor 0.231373 0.231373 0.231373
                                              }
                                            }
                                            geometry Box {
                                              size 0.41 0.06 0.01
                                            }
                                          }
                                        ]
                                      }
                                      Transform {
                                        translation 0 0.025 0.08
                                        children [
                                          Shape {
                                            appearance Appearance {
                                              material Material {
                                                diffuseColor 0.231373 0.231373 0.231373
                                              }
                                            }
                                            geometry Box {
                                              size 0.41 0.01 0.04
                                            }
                                          }
                                        ]
                                      }
                                      Transform {
                                        translation 0 -0.025 0.08
                                        children [
                                          Shape {
                                            appearance Appearance {
                                              material Material {
                                                diffuseColor 0.231373 0.231373 0.231373
                                              }
                                            }
                                            geometry Box {
                                              size 0.42 0.01 0.04
                                            }
                                          }
                                        ]
                                      }
                                    ]
                                  }
                                  DEF left_a HingeJoint {
                                    jointParameters HingeJointParameters {
                                      position 0.3282688975081868
                                      axis 0 1 0
                                      anchor -0.14 0 0.09
                                    }
                                    device [
                                      PositionSensor {
                                        name "left_finger_sensor"
                                      }
                                      RotationalMotor {
                                        name "left_finger_motor"
                                        maxTorque 50
                                      }
                                    ]
                                    endPoint Solid {
                                      translation -0.14 0 0.09
                                      rotation 0 1 0 0.32826889750818683
                                      children [
                                        Group {
                                          children [
                                            Transform {
                                              rotation 1 0 0 -1.5707953071795862
                                              children [
                                                Shape {
                                                  appearance Appearance {
                                                    material Material {
                                                      diffuseColor 0.333333 0.333333 1
                                                    }
                                                  }
                                                  geometry Cylinder {
                                                    height 0.065
                                                    radius 0.003
                                                    subdivision 20
                                                  }
                                                }
                                              ]
                                            }
                                            Transform {
                                              translation 0 0 0.1
                                              rotation 1 0 0 -1.5707953071795862
                                              children [
                                                Shape {
                                                  appearance Appearance {
                                                    material Material {
                                                      diffuseColor 0.333333 0.333333 1
                                                    }
                                                  }
                                                  geometry Cylinder {
                                                    height 0.065
                                                    radius 0.003
                                                    subdivision 20
                                                  }
                                                }
                                              ]
                                            }
                                            Transform {
                                              translation 0 0 0.05
                                              scale 1 1 2
                                              children [
                                                Shape {
                                                  appearance Appearance {
                                                    material Material {
                                                      diffuseColor 0.333333 0.333333 1
                                                    }
                                                  }
                                                  geometry Box {
                                                    size 0.01 0.038 0.05
                                                  }
                                                }
                                              ]
                                            }
                                          ]
                                        }
                                        DEF l_finger HingeJoint {
                                          jointParameters HingeJointParameters {
                                            position -0.3442617325551726
                                            axis 0 1 0
                                            anchor 0 0 0.1
                                          }
                                          endPoint Solid {
                                            translation 0 0 0.1
                                            rotation 0 -1 0 0.344261732555172
                                            children [
                                              DEF lf_finger Group {
                                                children [
                                                  Transform {
                                                    translation -0.02 0.025 0
                                                    children [
                                                      Shape {
                                                        appearance Appearance {
                                                          material Material {
                                                            diffuseColor 0.231373 0.231373 0.231373
                                                          }
                                                        }
                                                        geometry Box {
                                                          size 0.06 0.01 0.022
                                                        }
                                                      }
                                                    ]
                                                  }
                                                  Transform {
                                                    translation -0.02 -0.025 0
                                                    children [
                                                      Shape {
                                                        appearance Appearance {
                                                          material Material {
                                                            diffuseColor 0.231373 0.231373 0.231373
                                                          }
                                                        }
                                                        geometry Box {
                                                          size 0.06 0.01 0.022
                                                        }
                                                      }
                                                    ]
                                                  }
                                                  Transform {
                                                    translation -0.01 0 0.056
                                                    children [
                                                      Shape {
                                                        appearance Appearance {
                                                          material Material {
                                                            diffuseColor 0.231373 0.231373 0.231373
                                                          }
                                                        }
                                                        geometry Box {
                                                          size 0.04 0.06 0.09
                                                        }
                                                      }
                                                    ]
                                                  }
                                                  Transform {
                                                    translation -0.04 0 0.026
                                                    children [
                                                      Shape {
                                                        appearance Appearance {
                                                          material Material {
                                                            diffuseColor 0.231373 0.231373 0.231373
                                                          }
                                                        }
                                                        geometry Box {
                                                          size 0.02 0.06 0.03
                                                        }
                                                      }
                                                    ]
                                                  }
                                                  Transform {
                                                    translation 0 0 0.111
                                                    children [
                                                      Shape {
                                                        appearance Appearance {
                                                          material Material {
                                                            ambientIntensity 0.6
                                                            diffuseColor 0 0.2 0.4
                                                            shininess 0
                                                          }
                                                        }
                                                        geometry Box {
                                                          size 0.02 0.06 0.2
                                                        }
                                                      }
                                                    ]
                                                  }
                                                  Transform {
                                                    translation -0.0306 0 0.0678
                                                    rotation 0 1 0 0.32
                                                    children [
                                                      Shape {
                                                        appearance Appearance {
                                                          material Material {
                                                            diffuseColor 0.231373 0.231373 0.231373
                                                          }
                                                        }
                                                        geometry Box {
                                                          size 0.02 0.056 0.0635
                                                        }
                                                      }
                                                    ]
                                                  }
                                                  Transform {
                                                    translation -0.01 0 0.101
                                                    rotation 1 0 0 -1.5707953071795862
                                                    children [
                                                      Shape {
                                                        appearance Appearance {
                                                          material Material {
                                                            diffuseColor 0.231373 0.231373 0.231373
                                                          }
                                                        }
                                                        geometry Cylinder {
                                                          height 0.058
                                                          radius 0.02
                                                          subdivision 20
                                                        }
                                                      }
                                                    ]
                                                  }
                                                ]
                                              }
                                            ]
                                            name "left_finger"
                                            boundingObject USE lf_finger
                                            physics Physics {
                                            }
                                            linearVelocity 1.5710266900472864e-06 -1.216083968121757e-07 5.767126160858467e-07
                                            angularVelocity 1.9465516511244334e-07 2.584424525754183e-06 5.179390400777529e-07
                                          }
                                        }
                                      ]
                                      name "solid_1"
                                      contactMaterial "friction"
                                      boundingObject DEF phalanx Group {
                                        children [
                                          Transform {
                                            rotation 1 0 0 -1.5707953071795862
                                            children [
                                              Shape {
                                                appearance Appearance {
                                                  material Material {
                                                    diffuseColor 0.333333 0.333333 1
                                                  }
                                                }
                                                geometry Cylinder {
                                                  height 0.065
                                                  radius 0.003
                                                  subdivision 20
                                                }
                                              }
                                            ]
                                          }
                                          Transform {
                                            translation 0 0 0.1
                                            rotation 1 0 0 -1.5707953071795862
                                            children [
                                              Shape {
                                                appearance Appearance {
                                                  material Material {
                                                    diffuseColor 0.333333 0.333333 1
                                                  }
                                                }
                                                geometry Cylinder {
                                                  height 0.065
                                                  radius 0.003
                                                  subdivision 20
                                                }
                                              }
                                            ]
                                          }
                                          Transform {
                                            translation 0 0 0.025
                                            children [
                                              Shape {
                                                appearance Appearance {
                                                  material Material {
                                                    diffuseColor 0.333333 0.333333 1
                                                  }
                                                }
                                                geometry Box {
                                                  size 0.01 0.038 0.05
                                                }
                                              }
                                            ]
                                          }
                                        ]
                                      }
                                      physics Physics {
                                      }
                                      linearVelocity 4.2727988171334313e-07 -4.321945318699876e-08 1.6509064260343972e-07
                                      angularVelocity -6.145772084280433e-06 -8.032115559934404e-05 2.0395626802366907e-06
                                    }
                                  }
                                  DEF left_p HingeJoint {
                                    jointParameters HingeJointParameters {
                                      position 0.338523967969293
                                      axis 0 1 0
                                      anchor -0.1800812025777988 0 0.08961334947628816
                                    }
                                    endPoint Solid {
                                      translation -0.18008011292108336 0 0.08961269048476958
                                      rotation 0 1 0 0.33852396796929274
                                      children [
                                        Group {
                                          children [
                                            Transform {
                                              rotation 1 0 0 -1.5707953071795862
                                              children [
                                                Shape {
                                                  appearance Appearance {
                                                    material Material {
                                                      diffuseColor 0.333333 0.333333 1
                                                    }
                                                  }
                                                  geometry Cylinder {
                                                    height 0.065
                                                    radius 0.003
                                                    subdivision 20
                                                  }
                                                }
                                              ]
                                            }
                                            Transform {
                                              translation 0 0 0.1
                                              rotation 1 0 0 -1.5707953071795862
                                              children [
                                                Shape {
                                                  appearance Appearance {
                                                    material Material {
                                                      diffuseColor 0.333333 0.333333 1
                                                    }
                                                  }
                                                  geometry Cylinder {
                                                    height 0.065
                                                    radius 0.003
                                                    subdivision 20
                                                  }
                                                }
                                              ]
                                            }
                                            Transform {
                                              translation 0 0 0.05
                                              scale 1 1 2
                                              children [
                                                Shape {
                                                  appearance Appearance {
                                                    material Material {
                                                      diffuseColor 0.333333 0.333333 1
                                                    }
                                                  }
                                                  geometry Box {
                                                    size 0.01 0.038 0.05
                                                  }
                                                }
                                              ]
                                            }
                                          ]
                                        }
                                        HingeJoint {
                                          jointParameters HingeJointParameters {
                                            position -9.951357352525946
                                            axis 0 1 0
                                            anchor 0 0 0.1
                                          }
                                          endPoint SolidReference {
                                            solidName "left_finger"
                                          }
                                        }
                                      ]
                                      name "solid_2"
                                      boundingObject DEF phalanx Group {
                                        children [
                                          Transform {
                                            rotation 1 0 0 -1.5707953071795862
                                            children [
                                              Shape {
                                                appearance Appearance {
                                                  material Material {
                                                    diffuseColor 0.333333 0.333333 1
                                                  }
                                                }
                                                geometry Cylinder {
                                                  height 0.065
                                                  radius 0.003
                                                  subdivision 20
                                                }
                                              }
                                            ]
                                          }
                                          Transform {
                                            translation 0 0 0.1
                                            rotation 1 0 0 -1.5707953071795862
                                            children [
                                              Shape {
                                                appearance Appearance {
                                                  material Material {
                                                    diffuseColor 0.333333 0.333333 1
                                                  }
                                                }
                                                geometry Cylinder {
                                                  height 0.065
                                                  radius 0.003
                                                  subdivision 20
                                                }
                                              }
                                            ]
                                          }
                                          Transform {
                                            translation 0 0 0.025
                                            children [
                                              Shape {
                                                appearance Appearance {
                                                  material Material {
                                                    diffuseColor 0.333333 0.333333 1
                                                  }
                                                }
                                                geometry Box {
                                                  size 0.01 0.038 0.05
                                                }
                                              }
                                            ]
                                          }
                                        ]
                                      }
                                      physics Physics {
                                      }
                                      linearVelocity 4.268172039965874e-07 -4.8018830044211176e-08 1.720967879845744e-07
                                      angularVelocity -6.172836652094059e-06 -8.06750389807449e-05 2.0460414594166167e-06
                                    }
                                  }
                                  DEF right_p HingeJoint {
                                    jointParameters HingeJointParameters {
                                      position -0.00903470948252562
                                      axis 0 1 0
                                      anchor 0.18000187121908343 0 0.09077370288145375
                                    }
                                    endPoint Solid {
                                      translation 0.17999813054177546 0 0.09077366908719331
                                      rotation 0 -1 0 0.009034709482501454
                                      children [
                                        Group {
                                          children [
                                            Transform {
                                              rotation 1 0 0 -1.5707953071795862
                                              children [
                                                Shape {
                                                  appearance Appearance {
                                                    material Material {
                                                      diffuseColor 0.333333 0.333333 1
                                                    }
                                                  }
                                                  geometry Cylinder {
                                                    height 0.065
                                                    radius 0.003
                                                    subdivision 20
                                                  }
                                                }
                                              ]
                                            }
                                            Transform {
                                              translation 0 0 0.1
                                              rotation 1 0 0 -1.5707953071795862
                                              children [
                                                Shape {
                                                  appearance Appearance {
                                                    material Material {
                                                      diffuseColor 0.333333 0.333333 1
                                                    }
                                                  }
                                                  geometry Cylinder {
                                                    height 0.065
                                                    radius 0.003
                                                    subdivision 20
                                                  }
                                                }
                                              ]
                                            }
                                            Transform {
                                              translation 0 0 0.05
                                              scale 1 1 2
                                              children [
                                                Shape {
                                                  appearance Appearance {
                                                    material Material {
                                                      diffuseColor 0.333333 0.333333 1
                                                    }
                                                  }
                                                  geometry Box {
                                                    size 0.01 0.038 0.05
                                                  }
                                                }
                                              ]
                                            }
                                          ]
                                        }
                                        HingeJoint {
                                          jointParameters HingeJointParameters {
                                            position -9.590797715227277
                                            axis 0 1 0
                                            anchor 0 0 0.1
                                          }
                                          endPoint SolidReference {
                                            solidName "right_finger"
                                          }
                                        }
                                      ]
                                      name "solid_2(1)"
                                      boundingObject DEF phalanx Group {
                                        children [
                                          Transform {
                                            rotation 1 0 0 -1.5707953071795862
                                            children [
                                              Shape {
                                                appearance Appearance {
                                                  material Material {
                                                    diffuseColor 0.333333 0.333333 1
                                                  }
                                                }
                                                geometry Cylinder {
                                                  height 0.065
                                                  radius 0.003
                                                  subdivision 20
                                                }
                                              }
                                            ]
                                          }
                                          Transform {
                                            translation 0 0 0.1
                                            rotation 1 0 0 -1.5707953071795862
                                            children [
                                              Shape {
                                                appearance Appearance {
                                                  material Material {
                                                    diffuseColor 0.333333 0.333333 1
                                                  }
                                                }
                                                geometry Cylinder {
                                                  height 0.065
                                                  radius 0.003
                                                  subdivision 20
                                                }
                                              }
                                            ]
                                          }
                                          Transform {
                                            translation 0 0 0.025
                                            children [
                                              Shape {
                                                appearance Appearance {
                                                  material Material {
                                                    diffuseColor 0.333333 0.333333 1
                                                  }
                                                }
                                                geometry Box {
                                                  size 0.01 0.038 0.05
                                                }
                                              }
                                            ]
                                          }
                                        ]
                                      }
                                      physics Physics {
                                      }
                                      linearVelocity 4.2916707336059357e-07 -8.26163571036861e-09 -4.586541028954629e-09
                                      angularVelocity -5.810738606643301e-06 -7.594028149015815e-05 1.959111449093918e-06
                                    }
                                  }
                                  Camera {
                                    translation 2.00321e-08 -0.0906935 0.0187745
                                    rotation 0.5199880554939083 -0.5199870554938015 0.6776620723211167 1.95044
                                    fieldOfView 1.4
                                    width 360
                                    height 270
                                    antiAliasing TRUE
                                  }
                                ]
                                boundingObject USE pitch
                                physics Physics {
                                }
                                linearVelocity -5.817471455361806e-08 6.961807988230798e-09 -2.394896649407733e-10
                                angularVelocity -3.130720776949108e-09 -1.7030109787316791e-09 5.653785404800782e-07
                              }
                            }
                          ]
                          boundingObject USE wrist
                          physics Physics {
                          }
                          linearVelocity -5.488344757520701e-08 6.746065654192444e-09 -2.2239940022503024e-10
                          angularVelocity -3.1852870826029274e-09 -1.6994716403722313e-09 5.653785141751006e-07
                        }
                      }
                    ]
                    boundingObject USE forearm
                    physics Physics {
                    }
                    linearVelocity -2.621760130407052e-08 4.5752449581309e-09 -6.775475687149288e-11
                    angularVelocity -3.2379993749031173e-09 -2.391574729835565e-09 5.654615070596393e-07
                  }
                }
              ]
              boundingObject USE amr
              physics Physics {
              }
              linearVelocity 1.0160021973989858e-08 1.6661578369084094e-09 1.2939109415732107e-10
              angularVelocity -3.1936183466515153e-09 -2.395631439571138e-09 5.654616379939589e-07
            }
          }
        ]
        boundingObject USE waist
        physics Physics {
        }
        linearVelocity 1.393306519747265e-08 1.2513595361494258e-09 1.4946882533739406e-10
        angularVelocity -3.1934444578230568e-09 -2.3964050851585936e-09 5.654617505784243e-07
      }
    }
    DEF d4 DistanceSensor {
      translation -0.05 0.07 0.005
      rotation 0 0 1 3.141592653589793
      name "distance sensor(4)"
    }
    DEF BoxDSensor1 DistanceSensor {
      translation 0 0.1 -0.01
      rotation 0 0 1 1.5708003061004252
      name "box_sensor_middle"
    }
    DEF d3 DistanceSensor {
      translation 0 0.07 0.005
      rotation 0 0 1 2.3561996938995744
      name "distance sensor(3)"
    }
    DEF d2 DistanceSensor {
      translation 0.05 0.07 0.005
      name "distance sensor(2)"
    }
    DEF d1 DistanceSensor {
      translation 0 0.07 0.005
      rotation 0 0 1 0.7854003061004253
      name "distance sensor(1)"
    }
    DEF d0 DistanceSensor {
      translation 0 0.07 0.005
      rotation 0 0 1 1.5707996938995747
    }
    DEF left1 HingeJoint {
      jointParameters HingeJointParameters {
        position 228.9488782182261
        anchor 0.055 0.03 0
      }
      device [
        DEF Left_motor1 RotationalMotor {
          name "Left_motor1"
        }
      ]
      endPoint Solid {
        translation -0.07200261284028012 0.029998258184684632 -7.485263258815091e-08
        rotation -0.6717176344306689 -0.29017598456031996 -0.6816108256030822 3.706158080337116
        children [
          DEF wheel Shape {
            appearance PBRAppearance {
              baseColor 0 0 1
              metalness 0
            }
            geometry Cylinder {
              height 0.01
              radius 0.03
            }
          }
        ]
        name "solid(1)"
        boundingObject USE wheel
        physics Physics {
        }
        linearVelocity 1.542351929997245e-09 5.770692633042743e-10 -2.0516664315845948e-10
        angularVelocity -2.4702211848099743e-09 3.4786435119586074e-09 -1.9532743313597492e-08
      }
    }
    DEF Body Shape {
      appearance PBRAppearance {
        baseColor 0 1 1
        metalness 0
      }
      geometry Box {
        size 0.13 0.2 0.0195
      }
    }
    DEF right1 HingeJoint {
      jointParameters HingeJointParameters {
        position -61.16222104774352
        anchor -0.055 0.03 0
      }
      device [
        RotationalMotor {
          name "Right_motor1"
        }
      ]
      endPoint Solid {
        translation 0.07199997845552394 0.029999850224935537 1.84203152749422e-05
        rotation 0.5954501440058325 0.5393283947609361 0.5954527761359627 2.1523693861666215
        children [
          DEF Wheel Shape {
            appearance PBRAppearance {
              baseColor 0 0 1
              metalness 0
            }
            geometry Cylinder {
              height 0.01
              radius 0.03
            }
          }
        ]
        name "solid_motor"
        boundingObject USE Wheel
        physics Physics {
        }
        linearVelocity 1.7804946321201368e-09 3.660435072800535e-09 3.041316298376941e-10
        angularVelocity -2.9069194886914686e-09 3.5127200364222623e-09 -1.953280081583472e-08
      }
    }
  ]
  name "Rebel_Robot"
  boundingObject USE Body
  physics Physics {
  }
  controller "my_controller"
  linearVelocity 2.3056804488435394e-09 2.07044088435353e-09 -4.6031606296317393e-11
  angularVelocity -2.6669529838581625e-09 3.4938746956294733e-09 -1.9532869856853015e-08
}
DEF supervisor Robot {
  translation -1.93 1.32 0.0015
  rotation 1 0 0 1.5708
  scale 0.001 0.001 0.001
  children [
    DEF wall_sensor TouchSensor {
      translation -0.68 0 0
      name "wall_sensor"
      boundingObject Mesh {
        url [
          "E:/DEEE/4th SEM/SLRC 23/root/SLRC Arena/solid bodies/arena/onlywalls.STL"
        ]
      }
      locked TRUE
    }
  ]
  name "robot(1)"
  controller "<none>"
  supervisor TRUE
}
