#VRML_SIM R2023a utf8

EXTERNPROTO "https://raw.githubusercontent.com/cyberbotics/webots/R2023a/projects/objects/backgrounds/protos/TexturedBackground.proto"
EXTERNPROTO "https://raw.githubusercontent.com/cyberbotics/webots/R2023a/projects/objects/backgrounds/protos/TexturedBackgroundLight.proto"
EXTERNPROTO "https://raw.githubusercontent.com/cyberbotics/webots/R2023a/projects/objects/floors/protos/RectangleArena.proto"
EXTERNPROTO "https://raw.githubusercontent.com/cyberbotics/webots/R2023a/projects/appearances/protos/Parquetry.proto"

WorldInfo {
  contactProperties [
    ContactProperties {
      material1 "friction"
    }
  ]
}
Viewpoint {
  orientation 0.5495973536442186 -0.6218407379188527 -0.5579039751891077 4.26773428641447
  position -0.7477438864175233 -0.12456946262054697 7.662361665380081
}
TexturedBackground {
}
TexturedBackgroundLight {
}
RectangleArena {
  translation -0.62 0 0
  floorSize 2.7 2.7
  floorTileSize 5 5
  floorAppearance Parquetry {
    type "dark strip"
    colorOverride 0 0 0
    textureTransform TextureTransform {
    }
  }
}
DEF box_3 Solid {
  translation 0.4923310883508391 -1.0806315826480133 0.024995095000000554
  rotation 2.4435181734897263e-11 5.070234734817685e-10 1 -0.09640721240458205
  children [
    DEF box_3_shape Shape {
      appearance PBRAppearance {
        baseColor 1 0 0
        metalness 0
      }
      geometry Box {
        size 0.05 0.05 0.05
      }
    }
  ]
  name "solid(4)"
  boundingObject USE box_3_shape
  physics Physics {
    density 100
  }
}
DEF box_2 Solid {
  translation -1.74978 -1.08 0.0699975
  rotation 0.03189682431524314 0.18595032723061086 -0.982041276322656 1.1861480867837509e-15
  children [
    DEF box_2_shape Shape {
      appearance PBRAppearance {
        baseColor 0 1 0
        metalness 0
      }
      geometry Box {
        size 0.04 0.04 0.04
      }
    }
  ]
  name "solid(3)"
  boundingObject USE box_2_shape
  physics Physics {
    density 100
  }
}
DEF box_1 Solid {
  translation 0.488212 1.13805 0.0806965
  rotation 0.9931523384312567 0.08883243027095628 0.07587642585600735 1.57271
  children [
    DEF box_1_shape Shape {
      appearance PBRAppearance {
        baseColor 0 0 1
        metalness 0
      }
      geometry Box {
        size 0.03 0.03 0.03
      }
    }
  ]
  name "solid(2)"
  boundingObject USE box_1_shape
  physics Physics {
    density 100
  }
}
DEF maze Solid {
  translation -1.93 1.32 -0.00589861
  rotation 1 0 0 1.5708
  scale 0.001 0.001 0.001
  children [
    DEF maze_shape Shape {
      appearance PBRAppearance {
        metalness 0
      }
      geometry Mesh {
        url [
          "../solid bodies/arena/webotsArena.STL"
        ]
      }
      castShadows FALSE
    }
  ]
}
DEF rebel Robot {
  translation -1.74142 1.11824 0.0418915
  rotation -0.0016355894940860585 -0.0048931884864586855 0.9999866906881526 3.03779
  scale 1.1 1.1 1.1
  children [
    Camera {
      translation 2.30255e-07 0.0613628 0.0403528
      rotation -0.1294279597735375 0.1294279597735375 0.9831056944488314 1.58784
      name "rebelEye"
      fieldOfView 1.5
      width 480
      height 320
    }
    DEF BoxDSensor5 DistanceSensor {
      translation 0.04 0.1 -0.01
      rotation 0 0 1 1.5708003061004252
      name "box_sensor_side2.2"
    }
    DEF BoxDSensor4 DistanceSensor {
      translation -0.04 0.1 -0.01
      rotation 0 0 1 1.5708003061004252
      name "box_sensor_side1.2"
    }
    DEF BoxDSensor3 DistanceSensor {
      translation -0.01 0.1 -0.01
      rotation 0 0 1 1.5708003061004252
      name "box_sensor_side1"
    }
    DEF BoxDSensor2 DistanceSensor {
      translation 0.01 0.1 -0.01
      rotation 0 0 1 1.5708003061004252
      name "box_sensor_side2"
    }
    DEF ClasterWheel BallJoint {
      jointParameters BallJointParameters {
        position 437.19236291917304
        anchor 0 -0.05 -0.017
      }
      jointParameters2 JointParameters {
        position -23.42053011436898
      }
      jointParameters3 JointParameters {
        position 112.56270882597961
        axis 0 1 0
      }
      endPoint Solid {
        translation 1.8201398236363656e-06 -0.0500048815466384 -0.01700353874949604
        rotation -0.5687458594643469 0.507290261749712 0.6474447757732471 4.99855034304501
        children [
          DEF Claster Shape {
            appearance PBRAppearance {
              baseColor 0 0 1
              metalness 0
            }
            geometry Sphere {
              radius 0.014
            }
          }
        ]
        name "solid(2)"
        boundingObject USE Claster
        physics Physics {
        }
      }
    }
    DEF waist HingeJoint {
      jointParameters HingeJointParameters {
        position -10.999999999997497
        axis 0 0 1
        anchor 0 0.04 0.012
      }
      device [
        PositionSensor {
          name "waist_sensor"
        }
        RotationalMotor {
          name "waist_motor"
          maxVelocity 4
          maxTorque 100
        }
      ]
      endPoint Solid {
        translation 4.109275438012646e-08 0.06000007984769301 0.011998186410560274
        rotation -2.0907449439199322e-09 -3.557773870237735e-08 -0.9999999999999996 3.141592521850691
        scale 0.2 0.2 0.2
        children [
          DEF waist Group {
            children [
              Transform {
                rotation 0 0 1 0.3926996938995747
                children [
                  Shape {
                    appearance Appearance {
                      material Material {
                        diffuseColor 0.231373 0.231373 0.231373
                      }
                    }
                    geometry Cylinder {
                      height 0.02
                      radius 0.15
                      subdivision 20
                    }
                  }
                ]
              }
              Transform {
                translation 0.1 0 0.11
                children [
                  Shape {
                    appearance Appearance {
                      material Material {
                        diffuseColor 0.231373 0.231373 0.231373
                      }
                    }
                    geometry Box {
                      size 0.01 0.1 0.2
                    }
                  }
                ]
              }
              Transform {
                translation -0.1 0 0.11
                children [
                  Shape {
                    appearance Appearance {
                      material Material {
                        diffuseColor 0.231373 0.231373 0.231373
                      }
                    }
                    geometry Box {
                      size 0.01 0.1 0.2
                    }
                  }
                ]
              }
              Transform {
                translation 0.1 0 0.21
                rotation 0 1 0 -1.5707953071795862
                children [
                  Shape {
                    appearance Appearance {
                      material Material {
                        diffuseColor 0.231373 0.231373 0.231373
                      }
                    }
                    geometry Cylinder {
                      height 0.02
                      radius 0.05
                      subdivision 20
                    }
                  }
                ]
              }
              Transform {
                translation -0.1 0 0.21
                rotation 0 1 0 -1.5707953071795862
                children [
                  Shape {
                    appearance Appearance {
                      material Material {
                        diffuseColor 0.231373 0.231373 0.231373
                      }
                    }
                    geometry Cylinder {
                      height 0.02
                      radius 0.05
                      subdivision 20
                    }
                  }
                ]
              }
            ]
          }
          DEF shourlder HingeJoint {
            jointParameters HingeJointParameters {
              position -0.7000000560568023
              anchor 0 0 0.21
            }
            device [
              PositionSensor {
                name "shoulder_sensor"
              }
              RotationalMotor {
                name "shoulder_motor"
                maxVelocity 4
                maxTorque 200
              }
            ]
            endPoint Solid {
              translation 0 0 0.21
              rotation -1 0 0 0.7000000560568024
              children [
                DEF amr Group {
                  children [
                    Transform {
                      rotation 0 1 0 -1.5707953071795862
                      children [
                        Shape {
                          appearance Appearance {
                            material Material {
                              diffuseColor 0.333333 0.333333 1
                            }
                          }
                          geometry Cylinder {
                            height 0.225
                            radius 0.008
                            subdivision 20
                          }
                        }
                      ]
                    }
                    Transform {
                      translation 0 0 0.03
                      children [
                        Shape {
                          appearance Appearance {
                            material Material {
                              diffuseColor 0.231373 0.231373 0.231373
                            }
                          }
                          geometry Box {
                            size 0.15 0.08 0.4
                          }
                        }
                      ]
                    }
                    Transform {
                      translation 0.07 0 0.28
                      children [
                        Shape {
                          appearance Appearance {
                            material Material {
                              diffuseColor 0.231373 0.231373 0.231373
                            }
                          }
                          geometry Box {
                            size 0.01 0.08 0.1
                          }
                        }
                      ]
                    }
                    Transform {
                      translation -0.07 0 0.28
                      children [
                        Shape {
                          appearance Appearance {
                            material Material {
                              diffuseColor 0.231373 0.231373 0.231373
                            }
                          }
                          geometry Box {
                            size 0.01 0.08 0.1
                          }
                        }
                      ]
                    }
                    Transform {
                      translation 0.07 0 0.33
                      rotation 0 1 0 -1.5707953071795862
                      children [
                        Shape {
                          appearance Appearance {
                            material Material {
                              diffuseColor 0.231373 0.231373 0.231373
                            }
                          }
                          geometry Cylinder {
                            height 0.02
                            radius 0.04
                            subdivision 20
                          }
                        }
                      ]
                    }
                    Transform {
                      translation -0.07 0 0.33
                      rotation 0 1 0 -1.5707953071795862
                      children [
                        Shape {
                          appearance Appearance {
                            material Material {
                              diffuseColor 0.231373 0.231373 0.231373
                            }
                          }
                          geometry Cylinder {
                            height 0.02
                            radius 0.04
                            subdivision 20
                          }
                        }
                      ]
                    }
                  ]
                }
                DEF elbow HingeJoint {
                  jointParameters HingeJointParameters {
                    position -1.0000000285595665
                    anchor 0 0 0.33
                  }
                  device [
                    PositionSensor {
                      name "elbow_sensor"
                    }
                    RotationalMotor {
                      name "elbow_motor"
                      maxVelocity 4
                      maxTorque 200
                    }
                  ]
                  endPoint Solid {
                    translation 0 0 0.33
                    rotation -1 0 0 1.0000000285595665
                    children [
                      DEF forearm Group {
                        children [
                          Transform {
                            rotation 0 1 0 -1.5707953071795862
                            children [
                              Shape {
                                appearance Appearance {
                                  material Material {
                                    diffuseColor 0.333333 0.333333 1
                                  }
                                }
                                geometry Cylinder {
                                  height 0.165
                                  radius 0.006
                                  subdivision 20
                                }
                              }
                            ]
                          }
                          Transform {
                            translation 0 0 0.1
                            children [
                              Shape {
                                appearance Appearance {
                                  material Material {
                                    diffuseColor 0.231373 0.231373 0.231373
                                  }
                                }
                                geometry Box {
                                  size 0.1 0.06 0.34
                                }
                              }
                            ]
                          }
                          Transform {
                            translation 0 0 0.3
                            children [
                              Shape {
                                appearance Appearance {
                                  material Material {
                                    diffuseColor 0.231373 0.231373 0.231373
                                  }
                                }
                                geometry Cylinder {
                                  height 0.06
                                  radius 0.03
                                  subdivision 20
                                }
                              }
                            ]
                          }
                        ]
                      }
                      DEF wrist HingeJoint {
                        jointParameters HingeJointParameters {
                          position 2.7503065621557226e-11
                          axis 0 0 1
                          anchor 0 0 0.34
                        }
                        device [
                          PositionSensor {
                            name "wrist_sensor"
                          }
                          RotationalMotor {
                            name "wrist_motor"
                            maxVelocity 4
                            maxTorque 50
                          }
                        ]
                        endPoint Solid {
                          translation 0 0 0.34
                          children [
                            DEF wrist Group {
                              children [
                                Transform {
                                  children [
                                    Shape {
                                      appearance Appearance {
                                        material Material {
                                          diffuseColor 0.333333 0.333333 1
                                        }
                                      }
                                      geometry Cylinder {
                                        height 0.02
                                        radius 0.05
                                        subdivision 20
                                      }
                                    }
                                  ]
                                }
                                Transform {
                                  translation 0.04 0 0.0225
                                  children [
                                    Shape {
                                      appearance Appearance {
                                        material Material {
                                          diffuseColor 0.333333 0.333333 1
                                        }
                                      }
                                      geometry Box {
                                        size 0.01 0.04 0.025
                                      }
                                    }
                                  ]
                                }
                                Transform {
                                  translation -0.04 0 0.0225
                                  children [
                                    Shape {
                                      appearance Appearance {
                                        material Material {
                                          diffuseColor 0.333333 0.333333 1
                                        }
                                      }
                                      geometry Box {
                                        size 0.01 0.04 0.025
                                      }
                                    }
                                  ]
                                }
                                Transform {
                                  translation 0.04 0 0.035
                                  rotation 0 1 0 -1.5707953071795862
                                  children [
                                    Shape {
                                      appearance Appearance {
                                        material Material {
                                          diffuseColor 0.333333 0.333333 1
                                        }
                                      }
                                      geometry Cylinder {
                                        height 0.012
                                        radius 0.02
                                        subdivision 20
                                      }
                                    }
                                  ]
                                }
                                Transform {
                                  translation -0.04 0 0.035
                                  rotation 0 1 0 -1.5707953071795862
                                  children [
                                    Shape {
                                      appearance Appearance {
                                        material Material {
                                          diffuseColor 0.333333 0.333333 1
                                        }
                                      }
                                      geometry Cylinder {
                                        height 0.012
                                        radius 0.02
                                        subdivision 20
                                      }
                                    }
                                  ]
                                }
                              ]
                            }
                            DEF pitch HingeJoint {
                              jointParameters HingeJointParameters {
                                position -1.1
                                anchor 0 0 0.035
                              }
                              device [
                                PositionSensor {
                                  name "pitch_sensor"
                                }
                                RotationalMotor {
                                  name "pitch_motor"
                                  acceleration 1
                                  maxVelocity 4
                                  maxTorque 50
                                }
                              ]
                              endPoint Solid {
                                translation 0 0 0.035
                                rotation -1 0 0 1.1000000000000003
                                children [
                                  DEF right_a HingeJoint {
                                    jointParameters HingeJointParameters {
                                      position -0.6529704012436944
                                      axis 0 1 0
                                      anchor 0.14 0 0.09
                                    }
                                    device [
                                      DEF right_finger_sensor PositionSensor {
                                      }
                                      RotationalMotor {
                                        name "right_finger_motor"
                                        maxTorque 25
                                      }
                                    ]
                                    endPoint Solid {
                                      translation 0.14 0 0.09
                                      rotation 0 -1 0 0.6529704012436947
                                      children [
                                        Group {
                                          children [
                                            Transform {
                                              rotation 1 0 0 -1.5707953071795862
                                              children [
                                                Shape {
                                                  appearance Appearance {
                                                    material Material {
                                                      diffuseColor 0.333333 0.333333 1
                                                    }
                                                  }
                                                  geometry Cylinder {
                                                    height 0.065
                                                    radius 0.003
                                                    subdivision 20
                                                  }
                                                }
                                              ]
                                            }
                                            Transform {
                                              translation 0 0 0.1
                                              rotation 1 0 0 -1.5707953071795862
                                              children [
                                                Shape {
                                                  appearance Appearance {
                                                    material Material {
                                                      diffuseColor 0.333333 0.333333 1
                                                    }
                                                  }
                                                  geometry Cylinder {
                                                    height 0.065
                                                    radius 0.003
                                                    subdivision 20
                                                  }
                                                }
                                              ]
                                            }
                                            Transform {
                                              translation 0 0 0.05
                                              scale 1 1 2
                                              children [
                                                Shape {
                                                  appearance Appearance {
                                                    material Material {
                                                      diffuseColor 0.333333 0.333333 1
                                                    }
                                                  }
                                                  geometry Box {
                                                    size 0.01 0.038 0.05
                                                  }
                                                }
                                              ]
                                            }
                                          ]
                                        }
                                        DEF r__finger HingeJoint {
                                          jointParameters HingeJointParameters {
                                            position 0.6636418059878428
                                            axis 0 1 0
                                            anchor 0 0 0.1
                                          }
                                          endPoint Solid {
                                            translation 0 0 0.1
                                            rotation 0.3257651306046018 0.00025941555717756963 0.9454506927311099 3.1400868781162643
                                            children [
                                              DEF rf_finger Group {
                                                children [
                                                  Transform {
                                                    translation -0.02 0.025 0
                                                    children [
                                                      Shape {
                                                        appearance Appearance {
                                                          material Material {
                                                            diffuseColor 0.231373 0.231373 0.231373
                                                          }
                                                        }
                                                        geometry Box {
                                                          size 0.06 0.01 0.022
                                                        }
                                                      }
                                                    ]
                                                  }
                                                  Transform {
                                                    translation -0.02 -0.025 0
                                                    children [
                                                      Shape {
                                                        appearance Appearance {
                                                          material Material {
                                                            diffuseColor 0.231373 0.231373 0.231373
                                                          }
                                                        }
                                                        geometry Box {
                                                          size 0.06 0.01 0.022
                                                        }
                                                      }
                                                    ]
                                                  }
                                                  Transform {
                                                    translation -0.01 0 0.056
                                                    children [
                                                      Shape {
                                                        appearance Appearance {
                                                          material Material {
                                                            diffuseColor 0.231373 0.231373 0.231373
                                                          }
                                                        }
                                                        geometry Box {
                                                          size 0.04 0.06 0.09
                                                        }
                                                      }
                                                    ]
                                                  }
                                                  Transform {
                                                    translation -0.04 0 0.026
                                                    children [
                                                      Shape {
                                                        appearance Appearance {
                                                          material Material {
                                                            diffuseColor 0.231373 0.231373 0.231373
                                                          }
                                                        }
                                                        geometry Box {
                                                          size 0.02 0.06 0.03
                                                        }
                                                      }
                                                    ]
                                                  }
                                                  Transform {
                                                    translation 0 0 0.111
                                                    children [
                                                      Shape {
                                                        appearance Appearance {
                                                          material Material {
                                                            diffuseColor 0.231373 0.231373 0.231373
                                                            emissiveColor 0 0.2 0.4
                                                            shininess 0
                                                          }
                                                        }
                                                        geometry Box {
                                                          size 0.02 0.06 0.2
                                                        }
                                                      }
                                                    ]
                                                  }
                                                  Transform {
                                                    translation -0.0306 0 0.0678
                                                    rotation 0 1 0 0.32
                                                    children [
                                                      Shape {
                                                        appearance Appearance {
                                                          material Material {
                                                            diffuseColor 0.231373 0.231373 0.231373
                                                          }
                                                        }
                                                        geometry Box {
                                                          size 0.02 0.056 0.0635
                                                        }
                                                      }
                                                    ]
                                                  }
                                                  Transform {
                                                    translation -0.01 0 0.101
                                                    rotation 1 0 0 -1.5707953071795862
                                                    children [
                                                      Shape {
                                                        appearance Appearance {
                                                          material Material {
                                                            diffuseColor 0.231373 0.231373 0.231373
                                                          }
                                                        }
                                                        geometry Cylinder {
                                                          height 0.058
                                                          radius 0.02
                                                          subdivision 20
                                                        }
                                                      }
                                                    ]
                                                  }
                                                ]
                                              }
                                            ]
                                            name "right_finger"
                                            boundingObject USE rf_finger
                                            physics Physics {
                                            }
                                          }
                                        }
                                      ]
                                      name "solid_1(1)"
                                      boundingObject DEF phalanx_1 Group {
                                        children [
                                          Transform {
                                            rotation 1 0 0 -1.5707953071795862
                                            children [
                                              Shape {
                                                appearance Appearance {
                                                  material Material {
                                                    diffuseColor 0.333333 0.333333 1
                                                  }
                                                }
                                                geometry Cylinder {
                                                  height 0.065
                                                  radius 0.003
                                                  subdivision 20
                                                }
                                              }
                                            ]
                                          }
                                          Transform {
                                            translation 0 0 0.1
                                            rotation 1 0 0 -1.5707953071795862
                                            children [
                                              Shape {
                                                appearance Appearance {
                                                  material Material {
                                                    diffuseColor 0.333333 0.333333 1
                                                  }
                                                }
                                                geometry Cylinder {
                                                  height 0.065
                                                  radius 0.003
                                                  subdivision 20
                                                }
                                              }
                                            ]
                                          }
                                          Transform {
                                            translation 0 0 0.025
                                            children [
                                              Shape {
                                                appearance Appearance {
                                                  material Material {
                                                    diffuseColor 0.333333 0.333333 1
                                                  }
                                                }
                                                geometry Box {
                                                  size 0.01 0.038 0.05
                                                }
                                              }
                                            ]
                                          }
                                        ]
                                      }
                                      physics Physics {
                                      }
                                    }
                                  }
                                  DEF pitch Group {
                                    children [
                                      Transform {
                                        rotation 0 1 0 -1.5707953071795862
                                        children [
                                          Shape {
                                            appearance Appearance {
                                              material Material {
                                                diffuseColor 0.231373 0.231373 0.231373
                                              }
                                            }
                                            geometry Cylinder {
                                              height 0.095
                                              radius 0.004
                                              subdivision 20
                                            }
                                          }
                                        ]
                                      }
                                      Transform {
                                        rotation 0 1 0 -1.5707953071795862
                                        children [
                                          Shape {
                                            appearance Appearance {
                                              material Material {
                                                diffuseColor 0.231373 0.231373 0.231373
                                              }
                                            }
                                            geometry Cylinder {
                                              height 0.06
                                              radius 0.02
                                              subdivision 20
                                            }
                                          }
                                        ]
                                      }
                                      Transform {
                                        translation 0 0 0.015
                                        children [
                                          Shape {
                                            appearance Appearance {
                                              material Material {
                                                diffuseColor 0.231373 0.231373 0.231373
                                              }
                                            }
                                            geometry Box {
                                              size 0.058 0.04 0.07
                                            }
                                          }
                                        ]
                                      }
                                      Transform {
                                        translation 0 0 0.055
                                        children [
                                          Shape {
                                            appearance Appearance {
                                              material Material {
                                                diffuseColor 0.231373 0.231373 0.231373
                                              }
                                            }
                                            geometry Box {
                                              size 0.41 0.06 0.01
                                            }
                                          }
                                        ]
                                      }
                                      Transform {
                                        translation 0 0.025 0.08
                                        children [
                                          Shape {
                                            appearance Appearance {
                                              material Material {
                                                diffuseColor 0.231373 0.231373 0.231373
                                              }
                                            }
                                            geometry Box {
                                              size 0.41 0.01 0.04
                                            }
                                          }
                                        ]
                                      }
                                      Transform {
                                        translation 0 -0.025 0.08
                                        children [
                                          Shape {
                                            appearance Appearance {
                                              material Material {
                                                diffuseColor 0.231373 0.231373 0.231373
                                              }
                                            }
                                            geometry Box {
                                              size 0.42 0.01 0.04
                                            }
                                          }
                                        ]
                                      }
                                    ]
                                  }
                                  DEF left_a HingeJoint {
                                    jointParameters HingeJointParameters {
                                      position 0.6815951493342737
                                      axis 0 1 0
                                      anchor -0.14 0 0.09
                                    }
                                    device [
                                      PositionSensor {
                                        name "left_finger_sensor"
                                      }
                                      RotationalMotor {
                                        name "left_finger_motor"
                                        maxTorque 25
                                      }
                                    ]
                                    endPoint Solid {
                                      translation -0.14 0 0.09
                                      rotation 0 1 0 0.6815951493342733
                                      children [
                                        Group {
                                          children [
                                            Transform {
                                              rotation 1 0 0 -1.5707953071795862
                                              children [
                                                Shape {
                                                  appearance Appearance {
                                                    material Material {
                                                      diffuseColor 0.333333 0.333333 1
                                                    }
                                                  }
                                                  geometry Cylinder {
                                                    height 0.065
                                                    radius 0.003
                                                    subdivision 20
                                                  }
                                                }
                                              ]
                                            }
                                            Transform {
                                              translation 0 0 0.1
                                              rotation 1 0 0 -1.5707953071795862
                                              children [
                                                Shape {
                                                  appearance Appearance {
                                                    material Material {
                                                      diffuseColor 0.333333 0.333333 1
                                                    }
                                                  }
                                                  geometry Cylinder {
                                                    height 0.065
                                                    radius 0.003
                                                    subdivision 20
                                                  }
                                                }
                                              ]
                                            }
                                            Transform {
                                              translation 0 0 0.05
                                              scale 1 1 2
                                              children [
                                                Shape {
                                                  appearance Appearance {
                                                    material Material {
                                                      diffuseColor 0.333333 0.333333 1
                                                    }
                                                  }
                                                  geometry Box {
                                                    size 0.01 0.038 0.05
                                                  }
                                                }
                                              ]
                                            }
                                          ]
                                        }
                                        DEF l_finger HingeJoint {
                                          jointParameters HingeJointParameters {
                                            position -0.7088169967669355
                                            axis 0 1 0
                                            anchor 0 0 0.1
                                          }
                                          endPoint Solid {
                                            translation 0 0 0.1
                                            rotation 0 -1 0 0.7088169967669353
                                            children [
                                              DEF lf_finger Group {
                                                children [
                                                  Transform {
                                                    translation -0.02 0.025 0
                                                    children [
                                                      Shape {
                                                        appearance Appearance {
                                                          material Material {
                                                            diffuseColor 0.231373 0.231373 0.231373
                                                          }
                                                        }
                                                        geometry Box {
                                                          size 0.06 0.01 0.022
                                                        }
                                                      }
                                                    ]
                                                  }
                                                  Transform {
                                                    translation -0.02 -0.025 0
                                                    children [
                                                      Shape {
                                                        appearance Appearance {
                                                          material Material {
                                                            diffuseColor 0.231373 0.231373 0.231373
                                                          }
                                                        }
                                                        geometry Box {
                                                          size 0.06 0.01 0.022
                                                        }
                                                      }
                                                    ]
                                                  }
                                                  Transform {
                                                    translation -0.01 0 0.056
                                                    children [
                                                      Shape {
                                                        appearance Appearance {
                                                          material Material {
                                                            diffuseColor 0.231373 0.231373 0.231373
                                                          }
                                                        }
                                                        geometry Box {
                                                          size 0.04 0.06 0.09
                                                        }
                                                      }
                                                    ]
                                                  }
                                                  Transform {
                                                    translation -0.04 0 0.026
                                                    children [
                                                      Shape {
                                                        appearance Appearance {
                                                          material Material {
                                                            diffuseColor 0.231373 0.231373 0.231373
                                                          }
                                                        }
                                                        geometry Box {
                                                          size 0.02 0.06 0.03
                                                        }
                                                      }
                                                    ]
                                                  }
                                                  Transform {
                                                    translation 0 0 0.111
                                                    children [
                                                      Shape {
                                                        appearance Appearance {
                                                          material Material {
                                                            ambientIntensity 0.6
                                                            diffuseColor 0 0.2 0.4
                                                            shininess 0
                                                          }
                                                        }
                                                        geometry Box {
                                                          size 0.02 0.06 0.2
                                                        }
                                                      }
                                                    ]
                                                  }
                                                  Transform {
                                                    translation -0.0306 0 0.0678
                                                    rotation 0 1 0 0.32
                                                    children [
                                                      Shape {
                                                        appearance Appearance {
                                                          material Material {
                                                            diffuseColor 0.231373 0.231373 0.231373
                                                          }
                                                        }
                                                        geometry Box {
                                                          size 0.02 0.056 0.0635
                                                        }
                                                      }
                                                    ]
                                                  }
                                                  Transform {
                                                    translation -0.01 0 0.101
                                                    rotation 1 0 0 -1.5707953071795862
                                                    children [
                                                      Shape {
                                                        appearance Appearance {
                                                          material Material {
                                                            diffuseColor 0.231373 0.231373 0.231373
                                                          }
                                                        }
                                                        geometry Cylinder {
                                                          height 0.058
                                                          radius 0.02
                                                          subdivision 20
                                                        }
                                                      }
                                                    ]
                                                  }
                                                ]
                                              }
                                            ]
                                            name "left_finger"
                                            boundingObject USE lf_finger
                                            physics Physics {
                                            }
                                          }
                                        }
                                      ]
                                      name "solid_1"
                                      contactMaterial "friction"
                                      boundingObject DEF phalanx Group {
                                        children [
                                          Transform {
                                            rotation 1 0 0 -1.5707953071795862
                                            children [
                                              Shape {
                                                appearance Appearance {
                                                  material Material {
                                                    diffuseColor 0.333333 0.333333 1
                                                  }
                                                }
                                                geometry Cylinder {
                                                  height 0.065
                                                  radius 0.003
                                                  subdivision 20
                                                }
                                              }
                                            ]
                                          }
                                          Transform {
                                            translation 0 0 0.1
                                            rotation 1 0 0 -1.5707953071795862
                                            children [
                                              Shape {
                                                appearance Appearance {
                                                  material Material {
                                                    diffuseColor 0.333333 0.333333 1
                                                  }
                                                }
                                                geometry Cylinder {
                                                  height 0.065
                                                  radius 0.003
                                                  subdivision 20
                                                }
                                              }
                                            ]
                                          }
                                          Transform {
                                            translation 0 0 0.025
                                            children [
                                              Shape {
                                                appearance Appearance {
                                                  material Material {
                                                    diffuseColor 0.333333 0.333333 1
                                                  }
                                                }
                                                geometry Box {
                                                  size 0.01 0.038 0.05
                                                }
                                              }
                                            ]
                                          }
                                        ]
                                      }
                                      physics Physics {
                                      }
                                    }
                                  }
                                  DEF left_p HingeJoint {
                                    jointParameters HingeJointParameters {
                                      position 0.6939278127500479
                                      axis 0 1 0
                                      anchor -0.1800812025777988 0 0.08961334947628816
                                    }
                                    endPoint Solid {
                                      translation -0.18008041032666683 0 0.08961235250100112
                                      rotation 0 0.9999999999999999 0 0.6939278127500477
                                      children [
                                        Group {
                                          children [
                                            Transform {
                                              rotation 1 0 0 -1.5707953071795862
                                              children [
                                                Shape {
                                                  appearance Appearance {
                                                    material Material {
                                                      diffuseColor 0.333333 0.333333 1
                                                    }
                                                  }
                                                  geometry Cylinder {
                                                    height 0.065
                                                    radius 0.003
                                                    subdivision 20
                                                  }
                                                }
                                              ]
                                            }
                                            Transform {
                                              translation 0 0 0.1
                                              rotation 1 0 0 -1.5707953071795862
                                              children [
                                                Shape {
                                                  appearance Appearance {
                                                    material Material {
                                                      diffuseColor 0.333333 0.333333 1
                                                    }
                                                  }
                                                  geometry Cylinder {
                                                    height 0.065
                                                    radius 0.003
                                                    subdivision 20
                                                  }
                                                }
                                              ]
                                            }
                                            Transform {
                                              translation 0 0 0.05
                                              scale 1 1 2
                                              children [
                                                Shape {
                                                  appearance Appearance {
                                                    material Material {
                                                      diffuseColor 0.333333 0.333333 1
                                                    }
                                                  }
                                                  geometry Box {
                                                    size 0.01 0.038 0.05
                                                  }
                                                }
                                              ]
                                            }
                                          ]
                                        }
                                        HingeJoint {
                                          jointParameters HingeJointParameters {
                                            position -10.317974841126993
                                            axis 0 1 0
                                            anchor 0 0 0.1
                                          }
                                          endPoint SolidReference {
                                            solidName "left_finger"
                                          }
                                        }
                                      ]
                                      name "solid_2"
                                      boundingObject DEF phalanx Group {
                                        children [
                                          Transform {
                                            rotation 1 0 0 -1.5707953071795862
                                            children [
                                              Shape {
                                                appearance Appearance {
                                                  material Material {
                                                    diffuseColor 0.333333 0.333333 1
                                                  }
                                                }
                                                geometry Cylinder {
                                                  height 0.065
                                                  radius 0.003
                                                  subdivision 20
                                                }
                                              }
                                            ]
                                          }
                                          Transform {
                                            translation 0 0 0.1
                                            rotation 1 0 0 -1.5707953071795862
                                            children [
                                              Shape {
                                                appearance Appearance {
                                                  material Material {
                                                    diffuseColor 0.333333 0.333333 1
                                                  }
                                                }
                                                geometry Cylinder {
                                                  height 0.065
                                                  radius 0.003
                                                  subdivision 20
                                                }
                                              }
                                            ]
                                          }
                                          Transform {
                                            translation 0 0 0.025
                                            children [
                                              Shape {
                                                appearance Appearance {
                                                  material Material {
                                                    diffuseColor 0.333333 0.333333 1
                                                  }
                                                }
                                                geometry Box {
                                                  size 0.01 0.038 0.05
                                                }
                                              }
                                            ]
                                          }
                                        ]
                                      }
                                      physics Physics {
                                      }
                                    }
                                  }
                                  DEF right_p HingeJoint {
                                    jointParameters HingeJointParameters {
                                      position -0.6561779656870496
                                      axis 0 1 0
                                      anchor 0.18000187121908343 0 0.09077370288145375
                                    }
                                    endPoint Solid {
                                      translation 0.17999890724641476 0 0.09077142062932181
                                      rotation 0 -0.9999999999999999 0 0.6561779656870498
                                      children [
                                        Group {
                                          children [
                                            Transform {
                                              rotation 1 0 0 -1.5707953071795862
                                              children [
                                                Shape {
                                                  appearance Appearance {
                                                    material Material {
                                                      diffuseColor 0.333333 0.333333 1
                                                    }
                                                  }
                                                  geometry Cylinder {
                                                    height 0.065
                                                    radius 0.003
                                                    subdivision 20
                                                  }
                                                }
                                              ]
                                            }
                                            Transform {
                                              translation 0 0 0.1
                                              rotation 1 0 0 -1.5707953071795862
                                              children [
                                                Shape {
                                                  appearance Appearance {
                                                    material Material {
                                                      diffuseColor 0.333333 0.333333 1
                                                    }
                                                  }
                                                  geometry Cylinder {
                                                    height 0.065
                                                    radius 0.003
                                                    subdivision 20
                                                  }
                                                }
                                              ]
                                            }
                                            Transform {
                                              translation 0 0 0.05
                                              scale 1 1 2
                                              children [
                                                Shape {
                                                  appearance Appearance {
                                                    material Material {
                                                      diffuseColor 0.333333 0.333333 1
                                                    }
                                                  }
                                                  geometry Box {
                                                    size 0.01 0.038 0.05
                                                  }
                                                }
                                              ]
                                            }
                                          ]
                                        }
                                        HingeJoint {
                                          jointParameters HingeJointParameters {
                                            position -8.939051050411576
                                            axis 0 1 0
                                            anchor 0 0 0.1
                                          }
                                          endPoint SolidReference {
                                            solidName "right_finger"
                                          }
                                        }
                                      ]
                                      name "solid_2(1)"
                                      boundingObject DEF phalanx Group {
                                        children [
                                          Transform {
                                            rotation 1 0 0 -1.5707953071795862
                                            children [
                                              Shape {
                                                appearance Appearance {
                                                  material Material {
                                                    diffuseColor 0.333333 0.333333 1
                                                  }
                                                }
                                                geometry Cylinder {
                                                  height 0.065
                                                  radius 0.003
                                                  subdivision 20
                                                }
                                              }
                                            ]
                                          }
                                          Transform {
                                            translation 0 0 0.1
                                            rotation 1 0 0 -1.5707953071795862
                                            children [
                                              Shape {
                                                appearance Appearance {
                                                  material Material {
                                                    diffuseColor 0.333333 0.333333 1
                                                  }
                                                }
                                                geometry Cylinder {
                                                  height 0.065
                                                  radius 0.003
                                                  subdivision 20
                                                }
                                              }
                                            ]
                                          }
                                          Transform {
                                            translation 0 0 0.025
                                            children [
                                              Shape {
                                                appearance Appearance {
                                                  material Material {
                                                    diffuseColor 0.333333 0.333333 1
                                                  }
                                                }
                                                geometry Box {
                                                  size 0.01 0.038 0.05
                                                }
                                              }
                                            ]
                                          }
                                        ]
                                      }
                                      physics Physics {
                                      }
                                    }
                                  }
                                  Camera {
                                    translation 2.00321e-08 -0.0906935 0.0187745
                                    rotation 0.5199880554939083 -0.5199870554938015 0.6776620723211167 1.95044
                                    fieldOfView 1.4
                                    width 360
                                    height 270
                                    antiAliasing TRUE
                                  }
                                ]
                                boundingObject USE pitch
                                physics Physics {
                                }
                              }
                            }
                          ]
                          boundingObject USE wrist
                          physics Physics {
                          }
                        }
                      }
                    ]
                    boundingObject USE forearm
                    physics Physics {
                    }
                  }
                }
              ]
              boundingObject USE amr
              physics Physics {
              }
            }
          }
        ]
        boundingObject USE waist
        physics Physics {
        }
      }
    }
    DEF d4 DistanceSensor {
      translation -0.05 0.07 0.005
      rotation 0 0 1 3.141592653589793
      name "distance sensor(4)"
    }
    DEF BoxDSensor1 DistanceSensor {
      translation 0 0.1 -0.01
      rotation 0 0 1 1.5708003061004252
      name "box_sensor_middle"
    }
    DEF d3 DistanceSensor {
      translation 0 0.07 0.005
      rotation 0 0 1 2.3561996938995744
      name "distance sensor(3)"
    }
    DEF d2 DistanceSensor {
      translation 0.05 0.07 0.005
      name "distance sensor(2)"
    }
    DEF d1 DistanceSensor {
      translation 0 0.07 0.005
      rotation 0 0 1 0.7854003061004253
      name "distance sensor(1)"
    }
    DEF d0 DistanceSensor {
      translation 0 0.07 0.005
      rotation 0 0 1 1.5707996938995747
    }
    DEF left1 HingeJoint {
      jointParameters HingeJointParameters {
        position 234.51156874397546
        anchor 0.055 0.03 0
      }
      device [
        DEF Left_motor1 RotationalMotor {
          name "Left_motor1"
        }
      ]
      endPoint Solid {
        translation -0.07200261284028076 0.029998641677180374 1.092923888996898e-06
        rotation 0.5792074562311698 0.563205208757056 0.5893374377002858 2.121812057743486
        children [
          DEF wheel Shape {
            appearance PBRAppearance {
              baseColor 0 0 1
              metalness 0
            }
            geometry Cylinder {
              height 0.01
              radius 0.03
            }
          }
        ]
        name "solid(1)"
        boundingObject USE wheel
        physics Physics {
        }
      }
    }
    DEF Body Shape {
      appearance PBRAppearance {
        baseColor 0 1 1
        metalness 0
      }
      geometry Box {
        size 0.13 0.2 0.0195
      }
    }
    DEF right1 HingeJoint {
      jointParameters HingeJointParameters {
        position -54.1169115935253
        anchor -0.055 0.03 0
      }
      device [
        RotationalMotor {
          name "Right_motor1"
        }
      ]
      endPoint Solid {
        translation 0.07199997845552142 0.029987173174501947 1.3221308370986545e-05
        rotation -0.6840075306065911 -0.2535023944407253 -0.6840104049546998 3.6381358641311796
        children [
          DEF Wheel Shape {
            appearance PBRAppearance {
              baseColor 0 0 1
              metalness 0
            }
            geometry Cylinder {
              height 0.01
              radius 0.03
            }
          }
        ]
        name "solid_motor"
        boundingObject USE Wheel
        physics Physics {
        }
      }
    }
  ]
  name "Rebel_Robot"
  boundingObject USE Body
  physics Physics {
  }
  controller "my_controller"
}
DEF supervisor Robot {
  translation -1.93 1.32 0.0015
  rotation 1 0 0 1.5708
  scale 0.001 0.001 0.001
  children [
    DEF wall_sensor TouchSensor {
      translation -0.68 0 0
      name "wall_sensor"
      boundingObject Mesh {
        url [
          "E:/DEEE/4th SEM/SLRC 23/root/SLRC Arena/solid bodies/arena/onlywalls.STL"
        ]
      }
      locked TRUE
    }
  ]
  name "robot(1)"
  controller "<none>"
  supervisor TRUE
}
