#VRML_SIM R2023a utf8
PROTO armrobot[

]
{
    Robot {
    translation -0.9269030843142055 -1.09454398183154 0.030145131628058014
    rotation -0.005839393172616949 0.005477518568413535 -0.9999679486252089 1.501773734099077
    children [
        DEF ClasterWheel BallJoint {
        jointParameters BallJointParameters {
            position 2.5452117072627387
            anchor 0 -0.05 -0.017
        }
        jointParameters2 JointParameters {
            position 0.5239476696495642
        }
        jointParameters3 JointParameters {
            position -0.968970873665036
            axis 0 1 0
        }
        endPoint Solid {
            translation -8.037859267062686e-11 -0.05000003132157138 -0.016997133248554112
            rotation 0.24123508329435045 -0.3202616925661899 0.9160993848172844 1.8773510962422164
            children [
            DEF Claster Shape {
                appearance PBRAppearance {
                baseColor 0 0 1
                metalness 0
                }
                geometry Sphere {
                radius 0.014
                }
            }
            ]
            name "solid(2)"
            boundingObject USE Claster
            physics Physics {
            }
            linearVelocity -1.663794160786589e-06 2.403859323705736e-06 -1.1952755861773644e-06
            angularVelocity -0.00017170423564531542 -0.00011884243810496403 0.7425149252802302
        }
        }
        DEF waist robotArm {
        translation 0 0.04 0.012
        rotation 0 0 1 1.5999692659236002
        scale 0.2 0.2 0.2
        }
        DEF d4 DistanceSensor {
        translation -0.05 0.07 0.005
        rotation 0 0 1 3.141592653589793
        name "distance sensor(4)"
        }
        DEF d3 DistanceSensor {
        translation 0 0.07 0.005
        rotation 0 0 1 2.3561996938995744
        name "distance sensor(3)"
        }
        DEF d2 DistanceSensor {
        translation 0.05 0.07 0.005
        name "distance sensor(2)"
        }
        DEF d1 DistanceSensor {
        translation 0 0.07 0.005
        rotation 0 0 1 0.7854003061004253
        name "distance sensor(1)"
        }
        DEF d0 DistanceSensor {
        translation 0 0.07 0.005
        rotation 0 0 1 1.5707996938995747
        }
        DEF left1 HingeJoint {
        jointParameters HingeJointParameters {
            position 270.1828187972517
            anchor 0.055 0.03 0
        }
        device [
            DEF Left_motor1 RotationalMotor {
            name "Left_motor1"
            }
        ]
        endPoint Solid {
            translation -0.07200259129342837 0.03000171848803132 -4.125143140353599e-06
            rotation -0.20253771300653664 0.9585969862422912 -0.2001756548066682 1.6265620384920991
            children [
            DEF wheel Shape {
                appearance PBRAppearance {
                baseColor 0 0 1
                metalness 0
                }
                geometry Cylinder {
                height 0.01
                radius 0.03
                }
            }
            ]
            name "solid(1)"
            boundingObject USE wheel
            physics Physics {
            }
            linearVelocity 7.171676980365828e-07 -6.676594852301202e-08 -7.36633125244663e-07
            angularVelocity -2.4986589714279996e-05 -3.1733679672198374e-05 -3.824832228431634e-05
        }
        }
        DEF Body Shape {
        appearance PBRAppearance {
            metalness 0
        }
        geometry Box {
            size 0.13 0.2 0.0195
        }
        }
        DEF right1 HingeJoint {
        jointParameters HingeJointParameters {
            position -22.716158522022646
            anchor -0.055 0.03 0
        }
        device [
            RotationalMotor {
            name "Right_motor1"
            }
        ]
        endPoint Solid {
            translation 0.07199999999999929 0.029987413188806197 8.53290718170826e-06
            rotation 0.6829717692960027 0.2590285082482078 0.6829742266435799 2.634678668020583
            children [
            DEF Wheel Shape {
                appearance PBRAppearance {
                baseColor 0 0 1
                metalness 0
                }
                geometry Cylinder {
                height 0.01
                radius 0.03
                }
            }
            ]
            name "solid_motor"
            boundingObject USE Wheel
            physics Physics {
            }
            linearVelocity -4.648123382369378e-06 -4.38376069211886e-07 3.0900939764239692e-06
            angularVelocity -2.4958430482919186e-05 -3.205519514372778e-05 -3.8248328980797455e-05
        }
        }
    ]
    boundingObject USE Body
    physics Physics {
    }
    controller "my_controller"
    linearVelocity -2.0550502246349222e-06 8.996332181616306e-07 2.99841590301294e-07
    angularVelocity -2.4981817504927536e-05 -3.183100016956327e-05 -3.82565520608897e-05
    }
}