#VRML_SIM R2023a utf8

EXTERNPROTO "https://raw.githubusercontent.com/cyberbotics/webots/R2023a/projects/objects/backgrounds/protos/TexturedBackground.proto"
EXTERNPROTO "https://raw.githubusercontent.com/cyberbotics/webots/R2023a/projects/objects/backgrounds/protos/TexturedBackgroundLight.proto"
EXTERNPROTO "https://raw.githubusercontent.com/cyberbotics/webots/R2023a/projects/objects/floors/protos/RectangleArena.proto"
EXTERNPROTO "https://raw.githubusercontent.com/cyberbotics/webots/R2023a/projects/appearances/protos/Parquetry.proto"

WorldInfo {
  contactProperties [
    ContactProperties {
    }
  ]
}
Viewpoint {
  orientation 0.1440616380687634 0.05371126603021934 -0.9881099859521588 2.4356252789277617
  position 1.004558765303564 0.8830320099639267 0.5102470838891334
}
TexturedBackground {
}
TexturedBackgroundLight {
}
RectangleArena {
  translation -0.62 0 0
  floorSize 2.7 2.7
  floorTileSize 5 5
  floorAppearance Parquetry {
    type "dark strip"
    colorOverride 0 0 0
    textureTransform TextureTransform {
    }
  }
}
Robot {
  translation -0.0013815112231036436 0.0013562887725742537 0.03003738419134047
  rotation -0.9857589640255463 0.0016421068365729244 0.16815638057599577 0.010813521160902126
  children [
    DEF ClasterWheel BallJoint {
      jointParameters BallJointParameters {
        position 3.1370716991102827
        anchor 0 -0.05 -0.017
      }
      jointParameters2 JointParameters {
        position 4.345739049533962
      }
      jointParameters3 JointParameters {
        position 1.6855997590651017
        axis 0 1 0
      }
      endPoint Solid {
        translation -1.1595123141493006e-06 -0.04999744310572549 -0.017000580575371554
        rotation 0.7258163817187183 0.6878876202553609 -0.0010963248441961616 3.927600452421005
        children [
          DEF Claster Shape {
            appearance PBRAppearance {
              baseColor 0 0 1
              metalness 0
            }
            geometry Sphere {
              radius 0.014
            }
          }
        ]
        name "solid(2)"
        boundingObject USE Claster
        physics Physics {
        }
      }
    }
    DEF waist HingeJoint {
      jointParameters HingeJointParameters {
        position -10.999999999643716
        axis 0 0 1
        anchor 0 0.04 0.012
      }
      device [
        PositionSensor {
          name "waist_sensor"
        }
        RotationalMotor {
          name "waist_motor"
          maxVelocity 4
          maxTorque 100
        }
      ]
      endPoint Solid {
        translation -1.4716118896255159e-09 0.05999999999999994 0.012
        rotation 0 0 1 3.141592727170387
        scale 0.2 0.2 0.2
        children [
          DEF waist Group {
            children [
              Transform {
                rotation 0 0 1 0.3926996938995747
                children [
                  Shape {
                    appearance Appearance {
                      material Material {
                        diffuseColor 0.231373 0.231373 0.231373
                      }
                    }
                    geometry Cylinder {
                      height 0.02
                      radius 0.15
                      subdivision 20
                    }
                  }
                ]
              }
              Transform {
                translation 0.1 0 0.11
                children [
                  Shape {
                    appearance Appearance {
                      material Material {
                        diffuseColor 0.231373 0.231373 0.231373
                      }
                    }
                    geometry Box {
                      size 0.01 0.1 0.2
                    }
                  }
                ]
              }
              Transform {
                translation -0.1 0 0.11
                children [
                  Shape {
                    appearance Appearance {
                      material Material {
                        diffuseColor 0.231373 0.231373 0.231373
                      }
                    }
                    geometry Box {
                      size 0.01 0.1 0.2
                    }
                  }
                ]
              }
              Transform {
                translation 0.1 0 0.21
                rotation 0 1 0 -1.5707953071795862
                children [
                  Shape {
                    appearance Appearance {
                      material Material {
                        diffuseColor 0.231373 0.231373 0.231373
                      }
                    }
                    geometry Cylinder {
                      height 0.02
                      radius 0.05
                      subdivision 20
                    }
                  }
                ]
              }
              Transform {
                translation -0.1 0 0.21
                rotation 0 1 0 -1.5707953071795862
                children [
                  Shape {
                    appearance Appearance {
                      material Material {
                        diffuseColor 0.231373 0.231373 0.231373
                      }
                    }
                    geometry Cylinder {
                      height 0.02
                      radius 0.05
                      subdivision 20
                    }
                  }
                ]
              }
            ]
          }
          DEF shourlder HingeJoint {
            jointParameters HingeJointParameters {
              position -1.0146896459950483e-05
              anchor 0 0 0.21
            }
            device [
              PositionSensor {
                name "shoulder_sensor"
              }
              RotationalMotor {
                name "shoulder_motor"
                maxVelocity 4
                maxTorque 100
              }
            ]
            endPoint Solid {
              translation 0 0 0.21
              rotation -1 0 0 1.0146892074359456e-05
              children [
                DEF amr Group {
                  children [
                    Transform {
                      rotation 0 1 0 -1.5707953071795862
                      children [
                        Shape {
                          appearance Appearance {
                            material Material {
                              diffuseColor 0.333333 0.333333 1
                            }
                          }
                          geometry Cylinder {
                            height 0.225
                            radius 0.008
                            subdivision 20
                          }
                        }
                      ]
                    }
                    Transform {
                      translation 0 0 0.03
                      children [
                        Shape {
                          appearance Appearance {
                            material Material {
                              diffuseColor 0.231373 0.231373 0.231373
                            }
                          }
                          geometry Box {
                            size 0.15 0.08 0.4
                          }
                        }
                      ]
                    }
                    Transform {
                      translation 0.07 0 0.28
                      children [
                        Shape {
                          appearance Appearance {
                            material Material {
                              diffuseColor 0.231373 0.231373 0.231373
                            }
                          }
                          geometry Box {
                            size 0.01 0.08 0.1
                          }
                        }
                      ]
                    }
                    Transform {
                      translation -0.07 0 0.28
                      children [
                        Shape {
                          appearance Appearance {
                            material Material {
                              diffuseColor 0.231373 0.231373 0.231373
                            }
                          }
                          geometry Box {
                            size 0.01 0.08 0.1
                          }
                        }
                      ]
                    }
                    Transform {
                      translation 0.07 0 0.33
                      rotation 0 1 0 -1.5707953071795862
                      children [
                        Shape {
                          appearance Appearance {
                            material Material {
                              diffuseColor 0.231373 0.231373 0.231373
                            }
                          }
                          geometry Cylinder {
                            height 0.02
                            radius 0.04
                            subdivision 20
                          }
                        }
                      ]
                    }
                    Transform {
                      translation -0.07 0 0.33
                      rotation 0 1 0 -1.5707953071795862
                      children [
                        Shape {
                          appearance Appearance {
                            material Material {
                              diffuseColor 0.231373 0.231373 0.231373
                            }
                          }
                          geometry Cylinder {
                            height 0.02
                            radius 0.04
                            subdivision 20
                          }
                        }
                      ]
                    }
                  ]
                }
                DEF elbow HingeJoint {
                  jointParameters HingeJointParameters {
                    position 5.208260253699422e-10
                    anchor 0 0 0.33
                  }
                  device [
                    PositionSensor {
                      name "elbow_sensor"
                    }
                    RotationalMotor {
                      name "elbow_motor"
                      maxVelocity 4
                      maxTorque 100
                    }
                  ]
                  endPoint Solid {
                    translation 0 0 0.33
                    rotation 1 0 0 0
                    children [
                      DEF forearm Group {
                        children [
                          Transform {
                            rotation 0 1 0 -1.5707953071795862
                            children [
                              Shape {
                                appearance Appearance {
                                  material Material {
                                    diffuseColor 0.333333 0.333333 1
                                  }
                                }
                                geometry Cylinder {
                                  height 0.165
                                  radius 0.006
                                  subdivision 20
                                }
                              }
                            ]
                          }
                          Transform {
                            translation 0 0 0.1
                            children [
                              Shape {
                                appearance Appearance {
                                  material Material {
                                    diffuseColor 0.231373 0.231373 0.231373
                                  }
                                }
                                geometry Box {
                                  size 0.1 0.06 0.34
                                }
                              }
                            ]
                          }
                          Transform {
                            translation 0 0 0.3
                            children [
                              Shape {
                                appearance Appearance {
                                  material Material {
                                    diffuseColor 0.231373 0.231373 0.231373
                                  }
                                }
                                geometry Cylinder {
                                  height 0.06
                                  radius 0.03
                                  subdivision 20
                                }
                              }
                            ]
                          }
                        ]
                      }
                      DEF wrist HingeJoint {
                        jointParameters HingeJointParameters {
                          position 4.932994246403255e-10
                          axis 0 0 1
                          anchor 0 0 0.34
                        }
                        device [
                          PositionSensor {
                            name "wrist_sensor"
                          }
                          RotationalMotor {
                            name "wrist_motor"
                            maxVelocity 4
                            maxTorque 50
                          }
                        ]
                        endPoint Solid {
                          translation 0 0 0.34
                          children [
                            DEF wrist Group {
                              children [
                                Transform {
                                  children [
                                    Shape {
                                      appearance Appearance {
                                        material Material {
                                          diffuseColor 0.333333 0.333333 1
                                        }
                                      }
                                      geometry Cylinder {
                                        height 0.02
                                        radius 0.05
                                        subdivision 20
                                      }
                                    }
                                  ]
                                }
                                Transform {
                                  translation 0.04 0 0.0225
                                  children [
                                    Shape {
                                      appearance Appearance {
                                        material Material {
                                          diffuseColor 0.333333 0.333333 1
                                        }
                                      }
                                      geometry Box {
                                        size 0.01 0.04 0.025
                                      }
                                    }
                                  ]
                                }
                                Transform {
                                  translation -0.04 0 0.0225
                                  children [
                                    Shape {
                                      appearance Appearance {
                                        material Material {
                                          diffuseColor 0.333333 0.333333 1
                                        }
                                      }
                                      geometry Box {
                                        size 0.01 0.04 0.025
                                      }
                                    }
                                  ]
                                }
                                Transform {
                                  translation 0.04 0 0.035
                                  rotation 0 1 0 -1.5707953071795862
                                  children [
                                    Shape {
                                      appearance Appearance {
                                        material Material {
                                          diffuseColor 0.333333 0.333333 1
                                        }
                                      }
                                      geometry Cylinder {
                                        height 0.012
                                        radius 0.02
                                        subdivision 20
                                      }
                                    }
                                  ]
                                }
                                Transform {
                                  translation -0.04 0 0.035
                                  rotation 0 1 0 -1.5707953071795862
                                  children [
                                    Shape {
                                      appearance Appearance {
                                        material Material {
                                          diffuseColor 0.333333 0.333333 1
                                        }
                                      }
                                      geometry Cylinder {
                                        height 0.012
                                        radius 0.02
                                        subdivision 20
                                      }
                                    }
                                  ]
                                }
                              ]
                            }
                            DEF pitch HingeJoint {
                              jointParameters HingeJointParameters {
                                position -4.881839272936993e-10
                                anchor 0 0 0.035
                              }
                              device [
                                PositionSensor {
                                  name "pitch_sensor"
                                }
                                RotationalMotor {
                                  name "pitch_motor"
                                  acceleration 1
                                  maxVelocity 4
                                  maxTorque 50
                                }
                              ]
                              endPoint Solid {
                                translation 0 0 0.035
                                rotation 1 0 0 0
                                children [
                                  DEF pitch Group {
                                    children [
                                      Transform {
                                        rotation 0 1 0 -1.5707953071795862
                                        children [
                                          Shape {
                                            appearance Appearance {
                                              material Material {
                                                diffuseColor 0.231373 0.231373 0.231373
                                              }
                                            }
                                            geometry Cylinder {
                                              height 0.095
                                              radius 0.004
                                              subdivision 20
                                            }
                                          }
                                        ]
                                      }
                                      Transform {
                                        rotation 0 1 0 -1.5707953071795862
                                        children [
                                          Shape {
                                            appearance Appearance {
                                              material Material {
                                                diffuseColor 0.231373 0.231373 0.231373
                                              }
                                            }
                                            geometry Cylinder {
                                              height 0.06
                                              radius 0.02
                                              subdivision 20
                                            }
                                          }
                                        ]
                                      }
                                      Transform {
                                        translation 0 0 0.015
                                        children [
                                          Shape {
                                            appearance Appearance {
                                              material Material {
                                                diffuseColor 0.231373 0.231373 0.231373
                                              }
                                            }
                                            geometry Box {
                                              size 0.058 0.04 0.07
                                            }
                                          }
                                        ]
                                      }
                                      Transform {
                                        translation 0 0 0.055
                                        children [
                                          Shape {
                                            appearance Appearance {
                                              material Material {
                                                diffuseColor 0.231373 0.231373 0.231373
                                              }
                                            }
                                            geometry Box {
                                              size 0.41 0.06 0.01
                                            }
                                          }
                                        ]
                                      }
                                      Transform {
                                        translation 0 0.025 0.08
                                        children [
                                          Shape {
                                            appearance Appearance {
                                              material Material {
                                                diffuseColor 0.231373 0.231373 0.231373
                                              }
                                            }
                                            geometry Box {
                                              size 0.41 0.01 0.04
                                            }
                                          }
                                        ]
                                      }
                                      Transform {
                                        translation 0 -0.025 0.08
                                        children [
                                          Shape {
                                            appearance Appearance {
                                              material Material {
                                                diffuseColor 0.231373 0.231373 0.231373
                                              }
                                            }
                                            geometry Box {
                                              size 0.42 0.01 0.04
                                            }
                                          }
                                        ]
                                      }
                                    ]
                                  }
                                  DEF right_a HingeJoint {
                                    jointParameters HingeJointParameters {
                                      position -1.5277140355808097e-11
                                      axis 0 1 0
                                      anchor 0.16 0 0.065
                                    }
                                    device [
                                      PositionSensor {
                                        name "phalanx_sensor"
                                      }
                                      RotationalMotor {
                                        name "phalanx_motor::right"
                                        maxVelocity 4
                                        maxTorque 50
                                      }
                                    ]
                                    endPoint Solid {
                                      translation 0.16 0 0.065
                                      rotation 0 1 0 0
                                      children [
                                        DEF phalanx Group {
                                          children [
                                            Transform {
                                              rotation 1 0 0 -1.5707953071795862
                                              children [
                                                Shape {
                                                  appearance Appearance {
                                                    material Material {
                                                      diffuseColor 0.333333 0.333333 1
                                                    }
                                                  }
                                                  geometry Cylinder {
                                                    height 0.065
                                                    radius 0.003
                                                    subdivision 20
                                                  }
                                                }
                                              ]
                                            }
                                            Transform {
                                              translation 0 0 0.05
                                              rotation 1 0 0 -1.5707953071795862
                                              children [
                                                Shape {
                                                  appearance Appearance {
                                                    material Material {
                                                      diffuseColor 0.333333 0.333333 1
                                                    }
                                                  }
                                                  geometry Cylinder {
                                                    height 0.065
                                                    radius 0.003
                                                    subdivision 20
                                                  }
                                                }
                                              ]
                                            }
                                            Transform {
                                              translation 0 0 0.025
                                              children [
                                                Shape {
                                                  appearance Appearance {
                                                    material Material {
                                                      diffuseColor 0.333333 0.333333 1
                                                    }
                                                  }
                                                  geometry Box {
                                                    size 0.01 0.038 0.05
                                                  }
                                                }
                                              ]
                                            }
                                          ]
                                        }
                                        DEF r_finger HingeJoint {
                                          jointParameters HingeJointParameters {
                                            position -3.501378749264187e-05
                                            axis 0 1 0
                                            anchor 0 0 0.05
                                          }
                                          endPoint Solid {
                                            translation 0 0 0.05
                                            rotation 0 -1 0 3.50137845318279e-05
                                            children [
                                              DEF rg_finger Group {
                                                children [
                                                  Transform {
                                                    translation 0.02 0.025 0
                                                    children [
                                                      Shape {
                                                        appearance Appearance {
                                                          material Material {
                                                            diffuseColor 0.231373 0.231373 0.231373
                                                          }
                                                        }
                                                        geometry Box {
                                                          size 0.06 0.01 0.022
                                                        }
                                                      }
                                                    ]
                                                  }
                                                  Transform {
                                                    translation 0.02 -0.025 0
                                                    children [
                                                      Shape {
                                                        appearance Appearance {
                                                          material Material {
                                                            diffuseColor 0.231373 0.231373 0.231373
                                                          }
                                                        }
                                                        geometry Box {
                                                          size 0.06 0.01 0.022
                                                        }
                                                      }
                                                    ]
                                                  }
                                                  Transform {
                                                    translation 0.01 0 0.056
                                                    children [
                                                      Shape {
                                                        appearance Appearance {
                                                          material Material {
                                                            diffuseColor 0.231373 0.231373 0.231373
                                                          }
                                                        }
                                                        geometry Box {
                                                          size 0.04 0.06 0.09
                                                        }
                                                      }
                                                    ]
                                                  }
                                                  Transform {
                                                    translation 0.0306 0 0.0678
                                                    rotation 0 1 0 -0.32
                                                    children [
                                                      Shape {
                                                        appearance Appearance {
                                                          material Material {
                                                            diffuseColor 0.231373 0.231373 0.231373
                                                          }
                                                        }
                                                        geometry Box {
                                                          size 0.02 0.056 0.0635
                                                        }
                                                      }
                                                    ]
                                                  }
                                                  Transform {
                                                    translation 0.04 0 0.026
                                                    children [
                                                      Shape {
                                                        appearance Appearance {
                                                          material Material {
                                                            diffuseColor 0.231373 0.231373 0.231373
                                                          }
                                                        }
                                                        geometry Box {
                                                          size 0.02 0.06 0.03
                                                        }
                                                      }
                                                    ]
                                                  }
                                                  Transform {
                                                    translation 0 0 0.111
                                                    children [
                                                      Shape {
                                                        appearance Appearance {
                                                          material Material {
                                                            diffuseColor 0.231373 0.231373 0.231373
                                                          }
                                                        }
                                                        geometry Box {
                                                          size 0.02 0.06 0.2
                                                        }
                                                      }
                                                    ]
                                                  }
                                                  Transform {
                                                    translation 0.01 0 0.101
                                                    rotation 1 0 0 -1.5707953071795862
                                                    children [
                                                      Shape {
                                                        appearance Appearance {
                                                          material Material {
                                                            diffuseColor 0.231373 0.231373 0.231373
                                                          }
                                                        }
                                                        geometry Cylinder {
                                                          height 0.056
                                                          radius 0.02
                                                          subdivision 20
                                                        }
                                                      }
                                                    ]
                                                  }
                                                ]
                                              }
                                              TouchSensor {
                                                translation 0.0019996594079179936 7.448946410647944e-07 0.06899223079883006
                                                rotation -2.6604661128241078e-15 -1.434456781603295e-13 -1 -3.141590000000001
                                                name "finger_sensor"
                                                boundingObject Shape {
                                                  geometry Box {
                                                    size 0.02 0.06 0.1
                                                  }
                                                }
                                                physics Physics {
                                                }
                                                lookupTable [
                                                  0 0 0
                                                  0.01 1 0
                                                ]
                                              }
                                            ]
                                            name "right_finger"
                                            boundingObject USE rg_finger
                                            physics Physics {
                                            }
                                          }
                                        }
                                      ]
                                      boundingObject USE phalanx
                                      physics Physics {
                                      }
                                    }
                                  }
                                  DEF left_a HingeJoint {
                                    jointParameters HingeJointParameters {
                                      position -1.3031123430115641e-11
                                      axis 0 1 0
                                      anchor -0.16 0 0.065
                                    }
                                    device [
                                      RotationalMotor {
                                        name "phalanx_motor::left"
                                        maxVelocity 4
                                        maxTorque 50
                                        multiplier -1
                                      }
                                    ]
                                    endPoint Solid {
                                      translation -0.15999999594615708 2.899945214518418e-08 0.06500064095957808
                                      rotation 0 1 0 0
                                      children [
                                        Group {
                                          children [
                                            Transform {
                                              rotation 1 0 0 -1.5707953071795862
                                              children [
                                                Shape {
                                                  appearance Appearance {
                                                    material Material {
                                                      diffuseColor 0.333333 0.333333 1
                                                    }
                                                  }
                                                  geometry Cylinder {
                                                    height 0.065
                                                    radius 0.003
                                                    subdivision 20
                                                  }
                                                }
                                              ]
                                            }
                                            Transform {
                                              translation 0 0 0.05
                                              rotation 1 0 0 -1.5707953071795862
                                              children [
                                                Shape {
                                                  appearance Appearance {
                                                    material Material {
                                                      diffuseColor 0.333333 0.333333 1
                                                    }
                                                  }
                                                  geometry Cylinder {
                                                    height 0.065
                                                    radius 0.003
                                                    subdivision 20
                                                  }
                                                }
                                              ]
                                            }
                                            Transform {
                                              translation 0 0 0.025
                                              children [
                                                Shape {
                                                  appearance Appearance {
                                                    material Material {
                                                      diffuseColor 0.333333 0.333333 1
                                                    }
                                                  }
                                                  geometry Box {
                                                    size 0.01 0.038 0.05
                                                  }
                                                }
                                              ]
                                            }
                                          ]
                                        }
                                        DEF l_finger HingeJoint {
                                          jointParameters HingeJointParameters {
                                            position -0.0033123849819295995
                                            axis 0 1 0
                                            anchor 0 0 0.05
                                          }
                                          endPoint Solid {
                                            translation 0 0 0.05
                                            rotation 0 -1 0 0.0033123849819182098
                                            children [
                                              DEF lf_finger Group {
                                                children [
                                                  Transform {
                                                    translation -0.02 0.025 0
                                                    children [
                                                      Shape {
                                                        appearance Appearance {
                                                          material Material {
                                                            diffuseColor 0.231373 0.231373 0.231373
                                                          }
                                                        }
                                                        geometry Box {
                                                          size 0.06 0.01 0.022
                                                        }
                                                      }
                                                    ]
                                                  }
                                                  Transform {
                                                    translation -0.02 -0.025 0
                                                    children [
                                                      Shape {
                                                        appearance Appearance {
                                                          material Material {
                                                            diffuseColor 0.231373 0.231373 0.231373
                                                          }
                                                        }
                                                        geometry Box {
                                                          size 0.06 0.01 0.022
                                                        }
                                                      }
                                                    ]
                                                  }
                                                  Transform {
                                                    translation -0.01 0 0.056
                                                    children [
                                                      Shape {
                                                        appearance Appearance {
                                                          material Material {
                                                            diffuseColor 0.231373 0.231373 0.231373
                                                          }
                                                        }
                                                        geometry Box {
                                                          size 0.04 0.06 0.09
                                                        }
                                                      }
                                                    ]
                                                  }
                                                  Transform {
                                                    translation -0.04 0 0.026
                                                    children [
                                                      Shape {
                                                        appearance Appearance {
                                                          material Material {
                                                            diffuseColor 0.231373 0.231373 0.231373
                                                          }
                                                        }
                                                        geometry Box {
                                                          size 0.02 0.06 0.03
                                                        }
                                                      }
                                                    ]
                                                  }
                                                  Transform {
                                                    translation 0 0 0.111
                                                    children [
                                                      Shape {
                                                        appearance Appearance {
                                                          material Material {
                                                            diffuseColor 0.231373 0.231373 0.231373
                                                          }
                                                        }
                                                        geometry Box {
                                                          size 0.02 0.06 0.2
                                                        }
                                                      }
                                                    ]
                                                  }
                                                  Transform {
                                                    translation -0.0306 0 0.0678
                                                    rotation 0 1 0 0.32
                                                    children [
                                                      Shape {
                                                        appearance Appearance {
                                                          material Material {
                                                            diffuseColor 0.231373 0.231373 0.231373
                                                          }
                                                        }
                                                        geometry Box {
                                                          size 0.02 0.056 0.0635
                                                        }
                                                      }
                                                    ]
                                                  }
                                                  Transform {
                                                    translation -0.01 0 0.101
                                                    rotation 1 0 0 -1.5707953071795862
                                                    children [
                                                      Shape {
                                                        appearance Appearance {
                                                          material Material {
                                                            diffuseColor 0.231373 0.231373 0.231373
                                                          }
                                                        }
                                                        geometry Cylinder {
                                                          height 0.058
                                                          radius 0.02
                                                          subdivision 20
                                                        }
                                                      }
                                                    ]
                                                  }
                                                ]
                                              }
                                            ]
                                            name "left_finger"
                                            boundingObject USE lf_finger
                                            physics Physics {
                                            }
                                          }
                                        }
                                      ]
                                      name "solid_1"
                                      boundingObject USE phalanx
                                      physics Physics {
                                      }
                                    }
                                  }
                                  DEF right_p HingeJoint {
                                    jointParameters HingeJointParameters {
                                      position -4.452414943693745e-06
                                      axis 0 1 0
                                      anchor 0.06 0 0.065
                                    }
                                    endPoint Solid {
                                      translation 0.06 0 0.065
                                      rotation 0 -1 0 4.452431058165301e-06
                                      children [
                                        DEF phalanx Group {
                                          children [
                                            Transform {
                                              rotation 1 0 0 -1.5707953071795862
                                              children [
                                                Shape {
                                                  appearance Appearance {
                                                    material Material {
                                                      diffuseColor 0.333333 0.333333 1
                                                    }
                                                  }
                                                  geometry Cylinder {
                                                    height 0.065
                                                    radius 0.003
                                                    subdivision 20
                                                  }
                                                }
                                              ]
                                            }
                                            Transform {
                                              translation 0 0 0.05
                                              rotation 1 0 0 -1.5707953071795862
                                              children [
                                                Shape {
                                                  appearance Appearance {
                                                    material Material {
                                                      diffuseColor 0.333333 0.333333 1
                                                    }
                                                  }
                                                  geometry Cylinder {
                                                    height 0.065
                                                    radius 0.003
                                                    subdivision 20
                                                  }
                                                }
                                              ]
                                            }
                                            Transform {
                                              translation 0 0 0.025
                                              children [
                                                Shape {
                                                  appearance Appearance {
                                                    material Material {
                                                      diffuseColor 0.333333 0.333333 1
                                                    }
                                                  }
                                                  geometry Box {
                                                    size 0.01 0.038 0.05
                                                  }
                                                }
                                              ]
                                            }
                                          ]
                                        }
                                        HingeJoint {
                                          jointParameters HingeJointParameters {
                                            position -9.60004620538273
                                            axis 0 1 0
                                            anchor 0 0 0.05
                                          }
                                          endPoint SolidReference {
                                            solidName "right_finger"
                                          }
                                        }
                                      ]
                                      name "solid_3"
                                      boundingObject USE phalanx
                                      physics Physics {
                                      }
                                    }
                                  }
                                  DEF left_p HingeJoint {
                                    jointParameters HingeJointParameters {
                                      position 0.0032231754504269882
                                      axis 0 1 0
                                      anchor -0.06 0 0.065
                                    }
                                    endPoint Solid {
                                      translation -0.06 0 0.065
                                      rotation 0 1 0 0.0032231754504468127
                                      children [
                                        Group {
                                          children [
                                            Transform {
                                              rotation 1 0 0 -1.5707953071795862
                                              children [
                                                Shape {
                                                  appearance Appearance {
                                                    material Material {
                                                      diffuseColor 0.333333 0.333333 1
                                                    }
                                                  }
                                                  geometry Cylinder {
                                                    height 0.065
                                                    radius 0.003
                                                    subdivision 20
                                                  }
                                                }
                                              ]
                                            }
                                            Transform {
                                              translation 0 0 0.05
                                              rotation 1 0 0 -1.5707953071795862
                                              children [
                                                Shape {
                                                  appearance Appearance {
                                                    material Material {
                                                      diffuseColor 0.333333 0.333333 1
                                                    }
                                                  }
                                                  geometry Cylinder {
                                                    height 0.065
                                                    radius 0.003
                                                    subdivision 20
                                                  }
                                                }
                                              ]
                                            }
                                            Transform {
                                              translation 0 0 0.025
                                              children [
                                                Shape {
                                                  appearance Appearance {
                                                    material Material {
                                                      diffuseColor 0.333333 0.333333 1
                                                    }
                                                  }
                                                  geometry Box {
                                                    size 0.01 0.038 0.05
                                                  }
                                                }
                                              ]
                                            }
                                          ]
                                        }
                                        HingeJoint {
                                          jointParameters HingeJointParameters {
                                            position -9.603299307106559
                                            axis 0 1 0
                                            anchor 0 0 0.05
                                          }
                                          endPoint SolidReference {
                                            solidName "left_finger"
                                          }
                                        }
                                      ]
                                      name "solid_2"
                                      boundingObject USE phalanx
                                      physics Physics {
                                      }
                                    }
                                  }
                                  Camera {
                                    translation 2.00321e-08 -0.0906935 0.0187745
                                    rotation 0.5199880554939083 -0.5199870554938015 0.6776620723211167 1.95044
                                    fieldOfView 1.4
                                    width 360
                                    height 270
                                    antiAliasing TRUE
                                  }
                                ]
                                boundingObject USE pitch
                                physics Physics {
                                }
                              }
                            }
                          ]
                          boundingObject USE wrist
                          physics Physics {
                          }
                        }
                      }
                    ]
                    boundingObject USE forearm
                    physics Physics {
                    }
                  }
                }
              ]
              boundingObject USE amr
              physics Physics {
              }
            }
          }
        ]
        boundingObject USE waist
        physics Physics {
        }
      }
    }
    DEF d4 DistanceSensor {
      translation -0.05 0.07 0.005
      rotation 0 0 1 3.141592653589793
      name "distance sensor(4)"
    }
    DEF d3 DistanceSensor {
      translation 0 0.07 0.005
      rotation 0 0 1 2.3561996938995744
      name "distance sensor(3)"
    }
    DEF d2 DistanceSensor {
      translation 0.05 0.07 0.005
      name "distance sensor(2)"
    }
    DEF d1 DistanceSensor {
      translation 0 0.07 0.005
      rotation 0 0 1 0.7854003061004253
      name "distance sensor(1)"
    }
    DEF d0 DistanceSensor {
      translation 0 0.07 0.005
      rotation 0 0 1 1.5707996938995747
    }
    DEF left1 HingeJoint {
      jointParameters HingeJointParameters {
        position 270.1828163537862
        anchor 0.055 0.03 0
      }
      device [
        DEF Left_motor1 RotationalMotor {
          name "Left_motor1"
        }
      ]
      endPoint Solid {
        translation -0.07200259129342254 0.03000171847795167 -4.125147339406889e-06
        rotation -0.20253882104173515 0.9585965173502042 -0.20017677911057366 1.6265625333873572
        children [
          DEF wheel Shape {
            appearance PBRAppearance {
              baseColor 0 0 1
              metalness 0
            }
            geometry Cylinder {
              height 0.01
              radius 0.03
            }
          }
        ]
        name "solid(1)"
        boundingObject USE wheel
        physics Physics {
        }
      }
    }
    DEF Body Shape {
      appearance PBRAppearance {
        baseColor 0 1 1
        metalness 0
      }
      geometry Box {
        size 0.13 0.2 0.0195
      }
    }
    DEF right1 HingeJoint {
      jointParameters HingeJointParameters {
        position -22.716158925777602
        anchor -0.055 0.03 0
      }
      device [
        RotationalMotor {
          name "Right_motor1"
        }
      ]
      endPoint Solid {
        translation 0.07199999999999274 0.029987413192251396 8.532912263687339e-06
        rotation 0.6829717413957106 0.2590286553762275 0.6829741987431839 2.634678392267351
        children [
          DEF Wheel Shape {
            appearance PBRAppearance {
              baseColor 0 0 1
              metalness 0
            }
            geometry Cylinder {
              height 0.01
              radius 0.03
            }
          }
        ]
        name "solid_motor"
        boundingObject USE Wheel
        physics Physics {
        }
      }
    }
  ]
  boundingObject USE Body
  physics Physics {
  }
  controller "my_controller"
}
DEF box_3 Solid {
  translation -1.7299995204922196 -1.090000614758106 0.025089990768604846
  rotation 0.7668202324346809 0.641861042341572 -0.001064637502916408 2.939780769215368e-05
  children [
    DEF box_3_shape Shape {
      appearance PBRAppearance {
        baseColor 1 0 0
        metalness 0
      }
      geometry Box {
        size 0.05 0.05 0.05
      }
    }
  ]
  name "solid(4)"
  boundingObject USE box_3_shape
  physics Physics {
    density 100
  }
}
DEF box_2 Solid {
  translation 0.49897701413408013 -1.0929100766062243 0.020090981908437843
  rotation 0.7514490759312616 0.6597805920943682 0.003722442431812063 4.007413790858935e-05
  children [
    DEF box_2_shape Shape {
      appearance PBRAppearance {
        baseColor 0 1 0
        metalness 0
      }
      geometry Box {
        size 0.04 0.04 0.04
      }
    }
  ]
  name "solid(3)"
  boundingObject USE box_2_shape
  physics Physics {
    density 100
  }
}
DEF box_1 Solid {
  translation 0.4700000000016863 1.1199999274091412 0.01509994909100842
  rotation 0.9999999995315432 3.0607238466922065e-05 -3.3272870405426506e-07 3.673445318120104e-06
  children [
    DEF box_1_shape Shape {
      appearance PBRAppearance {
        baseColor 0 0 1
        metalness 0
      }
      geometry Box {
        size 0.03 0.03 0.03
      }
    }
  ]
  name "solid(2)"
  boundingObject USE box_1_shape
  physics Physics {
    density 100
  }
}
DEF maze Solid {
  translation -1.93 1.32 -0.00589861
  rotation 1 0 0 1.5708
  scale 0.001 0.001 0.001
  children [
    DEF maze_shape Shape {
      appearance PBRAppearance {
        metalness 0
      }
      geometry Mesh {
        url [
          "../solid bodies/arena/webotsArena.STL"
        ]
      }
      castShadows FALSE
    }
  ]
  boundingObject USE maze_shape
}
