#VRML_SIM R2023a utf8

EXTERNPROTO "https://raw.githubusercontent.com/cyberbotics/webots/R2023a/projects/objects/backgrounds/protos/TexturedBackground.proto"
EXTERNPROTO "https://raw.githubusercontent.com/cyberbotics/webots/R2023a/projects/objects/backgrounds/protos/TexturedBackgroundLight.proto"
EXTERNPROTO "https://raw.githubusercontent.com/cyberbotics/webots/R2023a/projects/objects/floors/protos/RectangleArena.proto"
EXTERNPROTO "https://raw.githubusercontent.com/cyberbotics/webots/R2023a/projects/appearances/protos/Parquetry.proto"

WorldInfo {
  contactProperties [
    ContactProperties {
    }
  ]
}
Viewpoint {
  orientation 0.0039178799184916855 0.9999600774042595 -0.008030804107423802 0.9070805909682027
  position -0.43612678067658367 -0.9955667115862579 0.7937517668787334
}
TexturedBackground {
}
TexturedBackgroundLight {
}
RectangleArena {
  translation -0.62 0 0
  floorSize 2.7 2.7
  floorTileSize 5 5
  floorAppearance Parquetry {
    type "dark strip"
    colorOverride 0 0 0
    textureTransform TextureTransform {
    }
  }
}
Robot {
  translation -0.9269030843142055 -1.09454398183154 0.030145131628058014
  rotation -0.005839393172616949 0.005477518568413535 -0.9999679486252089 1.501773734099077
  children [
    DEF ClasterWheel BallJoint {
      jointParameters BallJointParameters {
        position 2.5452117072627387
        anchor 0 -0.05 -0.017
      }
      jointParameters2 JointParameters {
        position 0.5239476696495642
      }
      jointParameters3 JointParameters {
        position -0.968970873665036
        axis 0 1 0
      }
      endPoint Solid {
        translation -8.037859064537108e-11 -0.05000003132157138 -0.016997133248554112
        rotation 0.24123508329435087 -0.32026169256618964 0.9160993848172844 1.8773510962422169
        children [
          DEF Claster Shape {
            appearance PBRAppearance {
              baseColor 0 0 1
              metalness 0
            }
            geometry Sphere {
              radius 0.014
            }
          }
        ]
        name "solid(2)"
        boundingObject USE Claster
        physics Physics {
        }
      }
    }
    DEF waist HingeJoint {
      jointParameters HingeJointParameters {
        axis 0 0 1
        anchor 0 0.04 0.012
      }
      device [
        PositionSensor {
          name "waist_sensor"
        }
        RotationalMotor {
          name "waist_motor"
          maxVelocity 4
          maxTorque 100
        }
      ]
      endPoint Solid {
        translation 0 0.04 0.012
        rotation 0 0 1 1.5999692659236002
        scale 0.2 0.2 0.2
        children [
          DEF waist Group {
            children [
              Transform {
                rotation 0 0 1 0.3926996938995747
                children [
                  Shape {
                    appearance Appearance {
                      material Material {
                        diffuseColor 0.231373 0.231373 0.231373
                      }
                    }
                    geometry Cylinder {
                      height 0.02
                      radius 0.15
                      subdivision 20
                    }
                  }
                ]
              }
              Transform {
                translation 0.1 0 0.11
                children [
                  Shape {
                    appearance Appearance {
                      material Material {
                        diffuseColor 0.231373 0.231373 0.231373
                      }
                    }
                    geometry Box {
                      size 0.01 0.1 0.2
                    }
                  }
                ]
              }
              Transform {
                translation -0.1 0 0.11
                children [
                  Shape {
                    appearance Appearance {
                      material Material {
                        diffuseColor 0.231373 0.231373 0.231373
                      }
                    }
                    geometry Box {
                      size 0.01 0.1 0.2
                    }
                  }
                ]
              }
              Transform {
                translation 0.1 0 0.21
                rotation 0 1 0 -1.5707953071795862
                children [
                  Shape {
                    appearance Appearance {
                      material Material {
                        diffuseColor 0.231373 0.231373 0.231373
                      }
                    }
                    geometry Cylinder {
                      height 0.02
                      radius 0.05
                      subdivision 20
                    }
                  }
                ]
              }
              Transform {
                translation -0.1 0 0.21
                rotation 0 1 0 -1.5707953071795862
                children [
                  Shape {
                    appearance Appearance {
                      material Material {
                        diffuseColor 0.231373 0.231373 0.231373
                      }
                    }
                    geometry Cylinder {
                      height 0.02
                      radius 0.05
                      subdivision 20
                    }
                  }
                ]
              }
            ]
          }
          DEF shourlder HingeJoint {
            jointParameters HingeJointParameters {
              anchor 0 0 0.21
            }
            device [
              PositionSensor {
                name "shoulder_sensor"
              }
              RotationalMotor {
                name "shoulder_motor"
                maxVelocity 4
                maxTorque 100
              }
            ]
            endPoint Solid {
              translation 0 0 0.21
              rotation 1 0 0 0
              children [
                DEF amr Group {
                  children [
                    Transform {
                      rotation 0 1 0 -1.5707953071795862
                      children [
                        Shape {
                          appearance Appearance {
                            material Material {
                              diffuseColor 0.333333 0.333333 1
                            }
                          }
                          geometry Cylinder {
                            height 0.225
                            radius 0.008
                            subdivision 20
                          }
                        }
                      ]
                    }
                    Transform {
                      translation 0 0 0.03
                      children [
                        Shape {
                          appearance Appearance {
                            material Material {
                              diffuseColor 0.231373 0.231373 0.231373
                            }
                          }
                          geometry Box {
                            size 0.15 0.08 0.4
                          }
                        }
                      ]
                    }
                    Transform {
                      translation 0.07 0 0.28
                      children [
                        Shape {
                          appearance Appearance {
                            material Material {
                              diffuseColor 0.231373 0.231373 0.231373
                            }
                          }
                          geometry Box {
                            size 0.01 0.08 0.1
                          }
                        }
                      ]
                    }
                    Transform {
                      translation -0.07 0 0.28
                      children [
                        Shape {
                          appearance Appearance {
                            material Material {
                              diffuseColor 0.231373 0.231373 0.231373
                            }
                          }
                          geometry Box {
                            size 0.01 0.08 0.1
                          }
                        }
                      ]
                    }
                    Transform {
                      translation 0.07 0 0.33
                      rotation 0 1 0 -1.5707953071795862
                      children [
                        Shape {
                          appearance Appearance {
                            material Material {
                              diffuseColor 0.231373 0.231373 0.231373
                            }
                          }
                          geometry Cylinder {
                            height 0.02
                            radius 0.04
                            subdivision 20
                          }
                        }
                      ]
                    }
                    Transform {
                      translation -0.07 0 0.33
                      rotation 0 1 0 -1.5707953071795862
                      children [
                        Shape {
                          appearance Appearance {
                            material Material {
                              diffuseColor 0.231373 0.231373 0.231373
                            }
                          }
                          geometry Cylinder {
                            height 0.02
                            radius 0.04
                            subdivision 20
                          }
                        }
                      ]
                    }
                  ]
                }
                DEF elbow HingeJoint {
                  jointParameters HingeJointParameters {
                    anchor 0 0 0.33
                  }
                  device [
                    PositionSensor {
                      name "elbow_sensor"
                    }
                    RotationalMotor {
                      name "elbow_motor"
                      maxVelocity 4
                      maxTorque 100
                    }
                  ]
                  endPoint Solid {
                    translation 0 0 0.33
                    rotation 1 0 0 0
                    children [
                      DEF forearm Group {
                        children [
                          Transform {
                            rotation 0 1 0 -1.5707953071795862
                            children [
                              Shape {
                                appearance Appearance {
                                  material Material {
                                    diffuseColor 0.333333 0.333333 1
                                  }
                                }
                                geometry Cylinder {
                                  height 0.165
                                  radius 0.006
                                  subdivision 20
                                }
                              }
                            ]
                          }
                          Transform {
                            translation 0 0 0.1
                            children [
                              Shape {
                                appearance Appearance {
                                  material Material {
                                    diffuseColor 0.231373 0.231373 0.231373
                                  }
                                }
                                geometry Box {
                                  size 0.1 0.06 0.34
                                }
                              }
                            ]
                          }
                          Transform {
                            translation 0 0 0.3
                            children [
                              Shape {
                                appearance Appearance {
                                  material Material {
                                    diffuseColor 0.231373 0.231373 0.231373
                                  }
                                }
                                geometry Cylinder {
                                  height 0.06
                                  radius 0.03
                                  subdivision 20
                                }
                              }
                            ]
                          }
                        ]
                      }
                      DEF wrist HingeJoint {
                        jointParameters HingeJointParameters {
                          axis 0 0 1
                          anchor 0 0 0.34
                        }
                        device [
                          PositionSensor {
                            name "wrist_sensor"
                          }
                          RotationalMotor {
                            name "wrist_motor"
                            maxVelocity 4
                            maxTorque 50
                          }
                        ]
                        endPoint Solid {
                          translation 0 0 0.34
                          children [
                            DEF wrist Group {
                              children [
                                Transform {
                                  children [
                                    Shape {
                                      appearance Appearance {
                                        material Material {
                                          diffuseColor 0.333333 0.333333 1
                                        }
                                      }
                                      geometry Cylinder {
                                        height 0.02
                                        radius 0.05
                                        subdivision 20
                                      }
                                    }
                                  ]
                                }
                                Transform {
                                  translation 0.04 0 0.0225
                                  children [
                                    Shape {
                                      appearance Appearance {
                                        material Material {
                                          diffuseColor 0.333333 0.333333 1
                                        }
                                      }
                                      geometry Box {
                                        size 0.01 0.04 0.025
                                      }
                                    }
                                  ]
                                }
                                Transform {
                                  translation -0.04 0 0.0225
                                  children [
                                    Shape {
                                      appearance Appearance {
                                        material Material {
                                          diffuseColor 0.333333 0.333333 1
                                        }
                                      }
                                      geometry Box {
                                        size 0.01 0.04 0.025
                                      }
                                    }
                                  ]
                                }
                                Transform {
                                  translation 0.04 0 0.035
                                  rotation 0 1 0 -1.5707953071795862
                                  children [
                                    Shape {
                                      appearance Appearance {
                                        material Material {
                                          diffuseColor 0.333333 0.333333 1
                                        }
                                      }
                                      geometry Cylinder {
                                        height 0.012
                                        radius 0.02
                                        subdivision 20
                                      }
                                    }
                                  ]
                                }
                                Transform {
                                  translation -0.04 0 0.035
                                  rotation 0 1 0 -1.5707953071795862
                                  children [
                                    Shape {
                                      appearance Appearance {
                                        material Material {
                                          diffuseColor 0.333333 0.333333 1
                                        }
                                      }
                                      geometry Cylinder {
                                        height 0.012
                                        radius 0.02
                                        subdivision 20
                                      }
                                    }
                                  ]
                                }
                              ]
                            }
                            DEF pitch HingeJoint {
                              jointParameters HingeJointParameters {
                                anchor 0 0 0.035
                              }
                              device [
                                PositionSensor {
                                  name "pitch_sensor"
                                }
                                RotationalMotor {
                                  name "pitch_motor"
                                  maxVelocity 4
                                  maxTorque 50
                                }
                              ]
                              endPoint Solid {
                                translation 0 0 0.035
                                rotation 1 0 0 0
                                children [
                                  DEF pitch Group {
                                    children [
                                      Transform {
                                        rotation 0 1 0 -1.5707953071795862
                                        children [
                                          Shape {
                                            appearance Appearance {
                                              material Material {
                                                diffuseColor 0.231373 0.231373 0.231373
                                              }
                                            }
                                            geometry Cylinder {
                                              height 0.095
                                              radius 0.004
                                              subdivision 20
                                            }
                                          }
                                        ]
                                      }
                                      Transform {
                                        rotation 0 1 0 -1.5707953071795862
                                        children [
                                          Shape {
                                            appearance Appearance {
                                              material Material {
                                                diffuseColor 0.231373 0.231373 0.231373
                                              }
                                            }
                                            geometry Cylinder {
                                              height 0.06
                                              radius 0.02
                                              subdivision 20
                                            }
                                          }
                                        ]
                                      }
                                      Transform {
                                        translation 0 0 0.015
                                        children [
                                          Shape {
                                            appearance Appearance {
                                              material Material {
                                                diffuseColor 0.231373 0.231373 0.231373
                                              }
                                            }
                                            geometry Box {
                                              size 0.058 0.04 0.03
                                            }
                                          }
                                        ]
                                      }
                                      Transform {
                                        translation 0 0 0.035
                                        children [
                                          Shape {
                                            appearance Appearance {
                                              material Material {
                                                diffuseColor 0.231373 0.231373 0.231373
                                              }
                                            }
                                            geometry Box {
                                              size 0.14 0.06 0.01
                                            }
                                          }
                                        ]
                                      }
                                      Transform {
                                        translation 0 0.025 0.06
                                        children [
                                          Shape {
                                            appearance Appearance {
                                              material Material {
                                                diffuseColor 0.231373 0.231373 0.231373
                                              }
                                            }
                                            geometry Box {
                                              size 0.14 0.01 0.04
                                            }
                                          }
                                        ]
                                      }
                                      Transform {
                                        translation 0 -0.025 0.06
                                        children [
                                          Shape {
                                            appearance Appearance {
                                              material Material {
                                                diffuseColor 0.231373 0.231373 0.231373
                                              }
                                            }
                                            geometry Box {
                                              size 0.14 0.01 0.04
                                            }
                                          }
                                        ]
                                      }
                                    ]
                                  }
                                  DEF right_a HingeJoint {
                                    jointParameters HingeJointParameters {
                                      axis 0 1 0
                                      anchor 0.02 0 0.065
                                    }
                                    device [
                                      PositionSensor {
                                        name "phalanx_sensor"
                                      }
                                      RotationalMotor {
                                        name "phalanx_motor::right"
                                        maxVelocity 4
                                        maxTorque 50
                                      }
                                    ]
                                    endPoint Solid {
                                      translation 0.02 0 0.065
                                      rotation 0 1 0 0
                                      children [
                                        DEF phalanx Group {
                                          children [
                                            Transform {
                                              rotation 1 0 0 -1.5707953071795862
                                              children [
                                                Shape {
                                                  appearance Appearance {
                                                    material Material {
                                                      diffuseColor 0.333333 0.333333 1
                                                    }
                                                  }
                                                  geometry Cylinder {
                                                    height 0.065
                                                    radius 0.003
                                                    subdivision 20
                                                  }
                                                }
                                              ]
                                            }
                                            Transform {
                                              translation 0 0 0.05
                                              rotation 1 0 0 -1.5707953071795862
                                              children [
                                                Shape {
                                                  appearance Appearance {
                                                    material Material {
                                                      diffuseColor 0.333333 0.333333 1
                                                    }
                                                  }
                                                  geometry Cylinder {
                                                    height 0.065
                                                    radius 0.003
                                                    subdivision 20
                                                  }
                                                }
                                              ]
                                            }
                                            Transform {
                                              translation 0 0 0.025
                                              children [
                                                Shape {
                                                  appearance Appearance {
                                                    material Material {
                                                      diffuseColor 0.333333 0.333333 1
                                                    }
                                                  }
                                                  geometry Box {
                                                    size 0.01 0.038 0.05
                                                  }
                                                }
                                              ]
                                            }
                                          ]
                                        }
                                        DEF r_finger HingeJoint {
                                          jointParameters HingeJointParameters {
                                            axis 0 1 0
                                            anchor 0 0 0.05
                                          }
                                          endPoint Solid {
                                            translation 0 0 0.05
                                            rotation 0 1 0 0
                                            children [
                                              DEF rg_finger Group {
                                                children [
                                                  Transform {
                                                    translation 0.02 0.025 0
                                                    children [
                                                      Shape {
                                                        appearance Appearance {
                                                          material Material {
                                                            diffuseColor 0.231373 0.231373 0.231373
                                                          }
                                                        }
                                                        geometry Box {
                                                          size 0.06 0.01 0.022
                                                        }
                                                      }
                                                    ]
                                                  }
                                                  Transform {
                                                    translation 0.02 -0.025 0
                                                    children [
                                                      Shape {
                                                        appearance Appearance {
                                                          material Material {
                                                            diffuseColor 0.231373 0.231373 0.231373
                                                          }
                                                        }
                                                        geometry Box {
                                                          size 0.06 0.01 0.022
                                                        }
                                                      }
                                                    ]
                                                  }
                                                  Transform {
                                                    translation 0.01 0 0.056
                                                    children [
                                                      Shape {
                                                        appearance Appearance {
                                                          material Material {
                                                            diffuseColor 0.231373 0.231373 0.231373
                                                          }
                                                        }
                                                        geometry Box {
                                                          size 0.04 0.06 0.09
                                                        }
                                                      }
                                                    ]
                                                  }
                                                  Transform {
                                                    translation 0.0306 0 0.0678
                                                    rotation 0 1 0 -0.32
                                                    children [
                                                      Shape {
                                                        appearance Appearance {
                                                          material Material {
                                                            diffuseColor 0.231373 0.231373 0.231373
                                                          }
                                                        }
                                                        geometry Box {
                                                          size 0.02 0.056 0.0635
                                                        }
                                                      }
                                                    ]
                                                  }
                                                  Transform {
                                                    translation 0.04 0 0.026
                                                    children [
                                                      Shape {
                                                        appearance Appearance {
                                                          material Material {
                                                            diffuseColor 0.231373 0.231373 0.231373
                                                          }
                                                        }
                                                        geometry Box {
                                                          size 0.02 0.06 0.03
                                                        }
                                                      }
                                                    ]
                                                  }
                                                  Transform {
                                                    translation 0 0 0.111
                                                    children [
                                                      Shape {
                                                        appearance Appearance {
                                                          material Material {
                                                            diffuseColor 0.231373 0.231373 0.231373
                                                          }
                                                        }
                                                        geometry Box {
                                                          size 0.02 0.06 0.02
                                                        }
                                                      }
                                                    ]
                                                  }
                                                  Transform {
                                                    translation 0.01 0 0.101
                                                    rotation 1 0 0 -1.5707953071795862
                                                    children [
                                                      Shape {
                                                        appearance Appearance {
                                                          material Material {
                                                            diffuseColor 0.231373 0.231373 0.231373
                                                          }
                                                        }
                                                        geometry Cylinder {
                                                          height 0.056
                                                          radius 0.02
                                                          subdivision 20
                                                        }
                                                      }
                                                    ]
                                                  }
                                                ]
                                              }
                                              TouchSensor {
                                                translation 0.002 0 0.069
                                                rotation 0 0 1 3.14159
                                                name "finger_sensor"
                                                boundingObject Shape {
                                                  geometry Box {
                                                    size 0.02 0.06 0.1
                                                  }
                                                }
                                                physics Physics {
                                                }
                                                lookupTable [
                                                  0 0 0
                                                  0.01 1 0
                                                ]
                                              }
                                            ]
                                            name "right_finger"
                                            boundingObject USE rg_finger
                                            physics Physics {
                                            }
                                          }
                                        }
                                      ]
                                      boundingObject USE phalanx
                                      physics Physics {
                                      }
                                    }
                                  }
                                  DEF left_a HingeJoint {
                                    jointParameters HingeJointParameters {
                                      axis 0 1 0
                                      anchor -0.02 0 0.065
                                    }
                                    device [
                                      RotationalMotor {
                                        name "phalanx_motor::left"
                                        maxVelocity 4
                                        maxTorque 50
                                        multiplier -1
                                      }
                                    ]
                                    endPoint Solid {
                                      translation -0.02 0 0.065
                                      rotation 0 1 0 0
                                      children [
                                        Group {
                                          children [
                                            Transform {
                                              rotation 1 0 0 -1.5707953071795862
                                              children [
                                                Shape {
                                                  appearance Appearance {
                                                    material Material {
                                                      diffuseColor 0.333333 0.333333 1
                                                    }
                                                  }
                                                  geometry Cylinder {
                                                    height 0.065
                                                    radius 0.003
                                                    subdivision 20
                                                  }
                                                }
                                              ]
                                            }
                                            Transform {
                                              translation 0 0 0.05
                                              rotation 1 0 0 -1.5707953071795862
                                              children [
                                                Shape {
                                                  appearance Appearance {
                                                    material Material {
                                                      diffuseColor 0.333333 0.333333 1
                                                    }
                                                  }
                                                  geometry Cylinder {
                                                    height 0.065
                                                    radius 0.003
                                                    subdivision 20
                                                  }
                                                }
                                              ]
                                            }
                                            Transform {
                                              translation 0 0 0.025
                                              children [
                                                Shape {
                                                  appearance Appearance {
                                                    material Material {
                                                      diffuseColor 0.333333 0.333333 1
                                                    }
                                                  }
                                                  geometry Box {
                                                    size 0.01 0.038 0.05
                                                  }
                                                }
                                              ]
                                            }
                                          ]
                                        }
                                        DEF l_finger HingeJoint {
                                          jointParameters HingeJointParameters {
                                            axis 0 1 0
                                            anchor 0 0 0.05
                                          }
                                          endPoint Solid {
                                            translation 0 0 0.05
                                            rotation 0 1 0 0
                                            children [
                                              DEF lf_finger Group {
                                                children [
                                                  Transform {
                                                    translation -0.02 0.025 0
                                                    children [
                                                      Shape {
                                                        appearance Appearance {
                                                          material Material {
                                                            diffuseColor 0.231373 0.231373 0.231373
                                                          }
                                                        }
                                                        geometry Box {
                                                          size 0.06 0.01 0.022
                                                        }
                                                      }
                                                    ]
                                                  }
                                                  Transform {
                                                    translation -0.02 -0.025 0
                                                    children [
                                                      Shape {
                                                        appearance Appearance {
                                                          material Material {
                                                            diffuseColor 0.231373 0.231373 0.231373
                                                          }
                                                        }
                                                        geometry Box {
                                                          size 0.06 0.01 0.022
                                                        }
                                                      }
                                                    ]
                                                  }
                                                  Transform {
                                                    translation -0.01 0 0.056
                                                    children [
                                                      Shape {
                                                        appearance Appearance {
                                                          material Material {
                                                            diffuseColor 0.231373 0.231373 0.231373
                                                          }
                                                        }
                                                        geometry Box {
                                                          size 0.04 0.06 0.09
                                                        }
                                                      }
                                                    ]
                                                  }
                                                  Transform {
                                                    translation -0.04 0 0.026
                                                    children [
                                                      Shape {
                                                        appearance Appearance {
                                                          material Material {
                                                            diffuseColor 0.231373 0.231373 0.231373
                                                          }
                                                        }
                                                        geometry Box {
                                                          size 0.02 0.06 0.03
                                                        }
                                                      }
                                                    ]
                                                  }
                                                  Transform {
                                                    translation 0 0 0.111
                                                    children [
                                                      Shape {
                                                        appearance Appearance {
                                                          material Material {
                                                            diffuseColor 0.231373 0.231373 0.231373
                                                          }
                                                        }
                                                        geometry Box {
                                                          size 0.02 0.06 0.02
                                                        }
                                                      }
                                                    ]
                                                  }
                                                  Transform {
                                                    translation -0.0306 0 0.0678
                                                    rotation 0 1 0 0.32
                                                    children [
                                                      Shape {
                                                        appearance Appearance {
                                                          material Material {
                                                            diffuseColor 0.231373 0.231373 0.231373
                                                          }
                                                        }
                                                        geometry Box {
                                                          size 0.02 0.056 0.0635
                                                        }
                                                      }
                                                    ]
                                                  }
                                                  Transform {
                                                    translation -0.01 0 0.101
                                                    rotation 1 0 0 -1.5707953071795862
                                                    children [
                                                      Shape {
                                                        appearance Appearance {
                                                          material Material {
                                                            diffuseColor 0.231373 0.231373 0.231373
                                                          }
                                                        }
                                                        geometry Cylinder {
                                                          height 0.056
                                                          radius 0.02
                                                          subdivision 20
                                                        }
                                                      }
                                                    ]
                                                  }
                                                ]
                                              }
                                            ]
                                            name "left_finger"
                                            boundingObject USE lf_finger
                                            physics Physics {
                                            }
                                          }
                                        }
                                      ]
                                      name "solid_1"
                                      boundingObject USE phalanx
                                      physics Physics {
                                      }
                                    }
                                  }
                                  DEF right_p HingeJoint {
                                    jointParameters HingeJointParameters {
                                      axis 0 1 0
                                      anchor 0.06 0 0.065
                                    }
                                    endPoint Solid {
                                      translation 0.06 0 0.065
                                      rotation 0 1 0 0
                                      children [
                                        DEF phalanx Group {
                                          children [
                                            Transform {
                                              rotation 1 0 0 -1.5707953071795862
                                              children [
                                                Shape {
                                                  appearance Appearance {
                                                    material Material {
                                                      diffuseColor 0.333333 0.333333 1
                                                    }
                                                  }
                                                  geometry Cylinder {
                                                    height 0.065
                                                    radius 0.003
                                                    subdivision 20
                                                  }
                                                }
                                              ]
                                            }
                                            Transform {
                                              translation 0 0 0.05
                                              rotation 1 0 0 -1.5707953071795862
                                              children [
                                                Shape {
                                                  appearance Appearance {
                                                    material Material {
                                                      diffuseColor 0.333333 0.333333 1
                                                    }
                                                  }
                                                  geometry Cylinder {
                                                    height 0.065
                                                    radius 0.003
                                                    subdivision 20
                                                  }
                                                }
                                              ]
                                            }
                                            Transform {
                                              translation 0 0 0.025
                                              children [
                                                Shape {
                                                  appearance Appearance {
                                                    material Material {
                                                      diffuseColor 0.333333 0.333333 1
                                                    }
                                                  }
                                                  geometry Box {
                                                    size 0.01 0.038 0.05
                                                  }
                                                }
                                              ]
                                            }
                                          ]
                                        }
                                        HingeJoint {
                                          jointParameters HingeJointParameters {
                                            axis 0 1 0
                                            anchor 0 0 0.05
                                          }
                                          endPoint SolidReference {
                                            solidName "right_finger"
                                          }
                                        }
                                      ]
                                      name "solid_3"
                                      boundingObject USE phalanx
                                      physics Physics {
                                      }
                                    }
                                  }
                                  DEF left_p HingeJoint {
                                    jointParameters HingeJointParameters {
                                      axis 0 1 0
                                      anchor -0.06 0 0.065
                                    }
                                    endPoint Solid {
                                      translation -0.06 0 0.065
                                      rotation 0 1 0 0
                                      children [
                                        Group {
                                          children [
                                            Transform {
                                              rotation 1 0 0 -1.5707953071795862
                                              children [
                                                Shape {
                                                  appearance Appearance {
                                                    material Material {
                                                      diffuseColor 0.333333 0.333333 1
                                                    }
                                                  }
                                                  geometry Cylinder {
                                                    height 0.065
                                                    radius 0.003
                                                    subdivision 20
                                                  }
                                                }
                                              ]
                                            }
                                            Transform {
                                              translation 0 0 0.05
                                              rotation 1 0 0 -1.5707953071795862
                                              children [
                                                Shape {
                                                  appearance Appearance {
                                                    material Material {
                                                      diffuseColor 0.333333 0.333333 1
                                                    }
                                                  }
                                                  geometry Cylinder {
                                                    height 0.065
                                                    radius 0.003
                                                    subdivision 20
                                                  }
                                                }
                                              ]
                                            }
                                            Transform {
                                              translation 0 0 0.025
                                              children [
                                                Shape {
                                                  appearance Appearance {
                                                    material Material {
                                                      diffuseColor 0.333333 0.333333 1
                                                    }
                                                  }
                                                  geometry Box {
                                                    size 0.01 0.038 0.05
                                                  }
                                                }
                                              ]
                                            }
                                          ]
                                        }
                                        HingeJoint {
                                          jointParameters HingeJointParameters {
                                            axis 0 1 0
                                            anchor 0 0 0.05
                                          }
                                          endPoint SolidReference {
                                            solidName "left_finger"
                                          }
                                        }
                                      ]
                                      name "solid_2"
                                      boundingObject USE phalanx
                                      physics Physics {
                                      }
                                    }
                                  }
                                  Camera {
                                    translation 2.00321e-08 -0.0906935 0.0187745
                                    rotation 0.5199880554939083 -0.5199870554938015 0.6776620723211167 1.95044
                                    fieldOfView 1.4
                                    width 360
                                    height 270
                                    antiAliasing TRUE
                                  }
                                ]
                                boundingObject USE pitch
                                physics Physics {
                                }
                              }
                            }
                          ]
                          boundingObject USE wrist
                          physics Physics {
                          }
                        }
                      }
                    ]
                    boundingObject USE forearm
                    physics Physics {
                    }
                  }
                }
              ]
              boundingObject USE amr
              physics Physics {
              }
            }
          }
        ]
        boundingObject USE waist
        physics Physics {
        }
      }
    }
    DEF d4 DistanceSensor {
      translation -0.05 0.07 0.005
      rotation 0 0 1 3.141592653589793
      name "distance sensor(4)"
    }
    DEF d3 DistanceSensor {
      translation 0 0.07 0.005
      rotation 0 0 1 2.3561996938995744
      name "distance sensor(3)"
    }
    DEF d2 DistanceSensor {
      translation 0.05 0.07 0.005
      name "distance sensor(2)"
    }
    DEF d1 DistanceSensor {
      translation 0 0.07 0.005
      rotation 0 0 1 0.7854003061004253
      name "distance sensor(1)"
    }
    DEF d0 DistanceSensor {
      translation 0 0.07 0.005
      rotation 0 0 1 1.5707996938995747
    }
    DEF left1 HingeJoint {
      jointParameters HingeJointParameters {
        position 270.1828187972517
        anchor 0.055 0.03 0
      }
      device [
        DEF Left_motor1 RotationalMotor {
          name "Left_motor1"
        }
      ]
      endPoint Solid {
        translation -0.07200259129342837 0.03000171848803132 -4.1251431403535786e-06
        rotation -0.20253771300653664 0.9585969862422912 -0.2001756548066682 1.6265620384920991
        children [
          DEF wheel Shape {
            appearance PBRAppearance {
              baseColor 0 0 1
              metalness 0
            }
            geometry Cylinder {
              height 0.01
              radius 0.03
            }
          }
        ]
        name "solid(1)"
        boundingObject USE wheel
        physics Physics {
        }
      }
    }
    DEF Body Shape {
      appearance PBRAppearance {
        baseColor 0 1 1
        metalness 0
      }
      geometry Box {
        size 0.13 0.2 0.0195
      }
    }
    DEF right1 HingeJoint {
      jointParameters HingeJointParameters {
        position -22.716158522022646
        anchor -0.055 0.03 0
      }
      device [
        RotationalMotor {
          name "Right_motor1"
        }
      ]
      endPoint Solid {
        translation 0.07199999999999929 0.029987413188806197 8.532907181707083e-06
        rotation 0.6829717692960027 0.2590285082482078 0.6829742266435799 2.634678668020583
        children [
          DEF Wheel Shape {
            appearance PBRAppearance {
              baseColor 0 0 1
              metalness 0
            }
            geometry Cylinder {
              height 0.01
              radius 0.03
            }
          }
        ]
        name "solid_motor"
        boundingObject USE Wheel
        physics Physics {
        }
      }
    }
  ]
  boundingObject USE Body
  physics Physics {
  }
  controller "my_controller"
}
DEF box_3 Solid {
  translation -1.73 -1.09 0.04
  children [
    DEF box_3_shape Shape {
      appearance PBRAppearance {
        baseColor 1 0 0
        metalness 0
      }
      geometry Box {
        size 0.05 0.05 0.05
      }
    }
  ]
  name "solid(4)"
  boundingObject USE box_3_shape
  physics Physics {
    density 100
  }
}
DEF box_2 Solid {
  translation 0.5 -1.1 0.03
  children [
    DEF box_2_shape Shape {
      appearance PBRAppearance {
        baseColor 0 1 0
        metalness 0
      }
      geometry Box {
        size 0.04 0.04 0.04
      }
    }
  ]
  name "solid(3)"
  boundingObject USE box_2_shape
  physics Physics {
    density 100
  }
}
DEF box_1 Solid {
  translation 0.47 1.12 0.02
  children [
    DEF box_1_shape Shape {
      appearance PBRAppearance {
        baseColor 0 0 1
        metalness 0
      }
      geometry Box {
        size 0.03 0.03 0.03
      }
    }
  ]
  name "solid(2)"
  boundingObject USE box_1_shape
  physics Physics {
    density 100
  }
}
DEF maze Solid {
  translation -1.93 1.32 -0.00589861
  rotation 1 0 0 1.5708
  scale 0.001 0.001 0.001
  children [
    DEF maze_shape Shape {
      appearance PBRAppearance {
        metalness 0
      }
      geometry Mesh {
        url [
          "../solid bodies/arena/webotsArena.STL"
        ]
      }
      castShadows FALSE
    }
  ]
  boundingObject USE maze_shape
}
