#VRML_SIM R2023a utf8

EXTERNPROTO "https://raw.githubusercontent.com/cyberbotics/webots/R2023a/projects/objects/backgrounds/protos/TexturedBackground.proto"
EXTERNPROTO "https://raw.githubusercontent.com/cyberbotics/webots/R2023a/projects/objects/backgrounds/protos/TexturedBackgroundLight.proto"
EXTERNPROTO "https://raw.githubusercontent.com/cyberbotics/webots/R2023a/projects/objects/floors/protos/RectangleArena.proto"
EXTERNPROTO "https://raw.githubusercontent.com/cyberbotics/webots/R2023a/projects/appearances/protos/BrushedAluminium.proto"

WorldInfo {
}
Viewpoint {
  orientation -0.6040330435880484 -0.5845822863696243 0.5416711481301374 4.107280604914538
  position -1.0155684952329451 -0.3138021702834506 1.452498512936399
}
TexturedBackground {
}
TexturedBackgroundLight {
  texture "empty_office"
}
RectangleArena {
  floorSize 2.52 2.52
  floorTileSize 0.72 0.72
  floorAppearance PBRAppearance {
    baseColorMap ImageTexture {
      url [
        "../../../SLRC_simulations/WhatsApp Image 2023-03-13 at 22.56.15.jpg"
      ]
    }
    metalness 0
  }
  wallHeight 0.15
  wallAppearance BrushedAluminium {
    IBLStrength 8
  }
}
Robot {
  translation -0.9269030843142055 -1.09454398183154 0.030145131628058014
  rotation -0.005839393172616949 0.005477518568413535 -0.9999679486252089 1.501773734099077
  children [
    DEF LineSensor-3 DistanceSensor {
      translation -0.035 0.101 0
      rotation 0 1 0 1.5707996938995747
      name "linesensor(1)"
    }
    DEF LineSensor-2 DistanceSensor {
      translation -0.025 0.101 0
      rotation 0 1 0 1.5707996938995747
      name "linesensor(2)"
    }
    DEF LineSensor-1 DistanceSensor {
      translation -0.015 0.101 0
      rotation 0 1 0 1.5707996938995747
      name "linesensor(3)"
    }
    DEF LineSensor5 DistanceSensor {
      translation 0.035 0.101 0
      rotation 0 1 0 1.5707996938995747
      name "linesensor(8)"
    }
    DEF LineSensor4 DistanceSensor {
      translation 0.025 0.101 0
      rotation 0 1 0 1.5707996938995747
      name "linesensor(7)"
    }
    DEF LineSensor3 DistanceSensor {
      translation 0.015 0.101 0
      rotation 0 1 0 1.5707996938995747
      name "linesensor(6)"
    }
    DEF LineSensor2 DistanceSensor {
      translation 0.005 0.101 0
      rotation 0 1 0 1.5707996938995747
      name "linesensor(5)"
    }
    DEF LineSensor1 DistanceSensor {
      translation -0.005 0.101 0
      rotation 0 1 0 1.5707996938995747
      name "linesensor(4)"
    }
    DEF ClasterWheel BallJoint {
      jointParameters BallJointParameters {
        position 2.5452117072627387
        anchor 0 -0.05 -0.017
      }
      jointParameters2 JointParameters {
        position 0.5239476696495642
      }
      jointParameters3 JointParameters {
        position -0.968970873665036
        axis 0 1 0
      }
      endPoint Solid {
        translation -8.03785906457946e-11 -0.05000003132157138 -0.016997133248554112
        rotation 0.24123508329435084 -0.32026169256618964 0.9160993848172845 1.8773510962422169
        children [
          DEF Claster Shape {
            appearance PBRAppearance {
              baseColor 0 0 1
              metalness 0
            }
            geometry Sphere {
              radius 0.014
            }
          }
        ]
        name "solid(2)"
        boundingObject USE Claster
        physics Physics {
        }
      }
    }
    DEF d4 DistanceSensor {
      translation -0.05 0.07 0.005
      rotation 0 0 1 3.141592653589793
      name "distance sensor(4)"
    }
    DEF d3 DistanceSensor {
      translation 0 0.07 0.005
      rotation 0 0 1 2.3561996938995744
      name "distance sensor(3)"
    }
    DEF d2 DistanceSensor {
      translation 0.05 0.07 0.005
      name "distance sensor(2)"
    }
    DEF d1 DistanceSensor {
      translation 0 0.07 0.005
      rotation 0 0 1 0.7854003061004253
      name "distance sensor(1)"
    }
    DEF d0 DistanceSensor {
      translation 0 0.07 0.005
      rotation 0 0 1 1.5707996938995747
    }
    DEF left1 HingeJoint {
      jointParameters HingeJointParameters {
        position 270.1828187972517
        anchor 0.055 0.03 0
      }
      device [
        DEF Left_motor1 RotationalMotor {
          name "Left_motor1"
        }
      ]
      endPoint Solid {
        translation -0.07200259129342837 0.03000171848803132 -4.125143140353584e-06
        rotation -0.20253771300653664 0.9585969862422912 -0.2001756548066682 1.6265620384920991
        children [
          DEF wheel Shape {
            appearance PBRAppearance {
              baseColor 0 0 1
              metalness 0
            }
            geometry Cylinder {
              height 0.01
              radius 0.03
            }
          }
        ]
        name "solid(1)"
        boundingObject USE wheel
        physics Physics {
        }
      }
    }
    DEF Body Shape {
      appearance PBRAppearance {
        metalness 0
      }
      geometry Box {
        size 0.13 0.2 0.0195
      }
    }
    DEF right1 HingeJoint {
      jointParameters HingeJointParameters {
        position -22.716158522022646
        anchor -0.055 0.03 0
      }
      device [
        RotationalMotor {
          name "Right_motor1"
        }
      ]
      endPoint Solid {
        translation 0.07199999999999929 0.029987413188806197 8.532907181707185e-06
        rotation 0.6829717692960027 0.2590285082482078 0.6829742266435799 2.634678668020583
        children [
          DEF Wheel Shape {
            appearance PBRAppearance {
              baseColor 0 0 1
              metalness 0
            }
            geometry Cylinder {
              height 0.01
              radius 0.03
            }
          }
        ]
        name "solid_motor"
        boundingObject USE Wheel
        physics Physics {
        }
      }
    }
  ]
  boundingObject USE Body
  physics Physics {
  }
  controller "my_controller"
}
