#VRML_SIM R2023a utf8

EXTERNPROTO "https://raw.githubusercontent.com/cyberbotics/webots/R2023a/projects/objects/backgrounds/protos/TexturedBackground.proto"
EXTERNPROTO "https://raw.githubusercontent.com/cyberbotics/webots/R2023a/projects/objects/backgrounds/protos/TexturedBackgroundLight.proto"
EXTERNPROTO "https://raw.githubusercontent.com/cyberbotics/webots/R2023a/projects/objects/floors/protos/RectangleArena.proto"
EXTERNPROTO "https://raw.githubusercontent.com/cyberbotics/webots/R2023a/projects/appearances/protos/Parquetry.proto"
EXTERNPROTO "https://raw.githubusercontent.com/cyberbotics/webots/R2023a/projects/appearances/protos/BrushedAluminium.proto"
EXTERNPROTO "../protos/robotArm.proto"

WorldInfo {
}
Viewpoint {
  orientation 0.0008506951371150352 -9.096174366273501e-05 0.9999996340218055 2.9257950336167413
  position -0.006845463162802989 -1.0696717407888459 0.06396266185211792
}
TexturedBackground {
}
TexturedBackgroundLight {
}
RectangleArena {
  floorSize 2.52 2.52
  floorTileSize 0.72 0.72
  floorAppearance Parquetry {
    type "dark strip"
    colorOverride 0 0 0
  }
  wallHeight 0.15
  wallAppearance BrushedAluminium {
    IBLStrength 8
  }
}
Solid {
  translation -0.54 0 0.075
  children [
    DEF wall_13 Shape {
      appearance PBRAppearance {
        metalness 0
      }
      geometry Box {
        size 0.01 1.08 0.15
      }
    }
  ]
  boundingObject USE wall_13
}
Solid {
  translation -6.74634e-14 -0.9 0.075
  rotation 0 0 1 1.5708
  children [
    DEF wall_8 Shape {
      appearance PBRAppearance {
        metalness 0
      }
      geometry Box {
        size 0.01 1.08 0.15
      }
    }
  ]
  name "solid(3)"
  boundingObject USE wall_8
}
Solid {
  translation -5.28942e-06 0.54 0.075
  rotation 0 0 1 1.5708
  children [
    DEF wall_14 Shape {
      appearance PBRAppearance {
        metalness 0
      }
      geometry Box {
        size 0.01 1.08 0.15
      }
    }
  ]
  name "solid(7)"
  boundingObject USE wall_14
}
Solid {
  translation -0.180002 0.9 0.075
  rotation 0 0 1 1.5708
  children [
    DEF wall_5 Shape {
      appearance PBRAppearance {
        metalness 0
      }
      geometry Box {
        size 0.01 0.72 0.15
      }
    }
  ]
  name "solid(8)"
  boundingObject USE wall_5
}
Solid {
  translation -0.360001 -0.54 0.075
  rotation 0 0 1 1.5708
  children [
    DEF wall_12 Shape {
      appearance PBRAppearance {
        metalness 0
      }
      geometry Box {
        size 0.01 0.36 0.15
      }
    }
  ]
  name "solid(4)"
  boundingObject USE wall_12
}
Solid {
  translation -0.720001 0.18 0.075
  rotation 0 0 1 1.5708
  children [
    DEF wall_3 Shape {
      appearance PBRAppearance {
        metalness 0
      }
      geometry Box {
        size 0.01 0.36 0.15
      }
    }
  ]
  name "solid(14)"
  boundingObject USE wall_3
}
DEF wall Solid {
  translation -1.08 -0.91 0.075
  rotation 0 0 1 1.5708
  children [
    DEF wall_1 Shape {
      appearance PBRAppearance {
        metalness 0
      }
      geometry Box {
        size 0.01 0.36 0.15
      }
    }
  ]
  name "wall"
  boundingObject USE wall_1
}
Solid {
  translation -0.180001 -0.72 0.075
  rotation 0 0 1 -3.1415853071795863
  children [
    DEF wall_11 Shape {
      appearance PBRAppearance {
        metalness 0
      }
      geometry Box {
        size 0.01 0.36 0.15
      }
    }
  ]
  name "solid(6)"
  boundingObject USE wall_11
}
Solid {
  translation 0.539996 1.08 0.075
  rotation 0 0 1 -3.1415853071795863
  children [
    DEF wall_7 Shape {
      appearance PBRAppearance {
        metalness 0
      }
      geometry Box {
        size 0.01 0.36 0.15
      }
    }
  ]
  name "solid(12)"
  boundingObject USE wall_7
}
Solid {
  translation 0.9 -1.07999 0.075
  rotation 0 0 1 -3.1415853071795863
  children [
    DEF wall_10 Shape {
      appearance PBRAppearance {
        metalness 0
      }
      geometry Box {
        size 0.01 0.36 0.15
      }
    }
  ]
  name "solid(11)"
  boundingObject USE wall_10
}
Solid {
  translation 0.9 -0.35999 0.075
  rotation 0 0 1 -3.1415853071795863
  children [
    DEF wall_9 Shape {
      appearance PBRAppearance {
        metalness 0
      }
      geometry Box {
        size 0.01 0.36 0.15
      }
    }
  ]
  name "solid(17)"
  boundingObject USE wall_9
}
Solid {
  translation 0.179991 1.08 0.075
  rotation 0 0 1 -3.1415853071795863
  children [
    DEF wall_6 Shape {
      appearance PBRAppearance {
        metalness 0
      }
      geometry Box {
        size 0.01 0.36 0.15
      }
    }
  ]
  name "solid(9)"
  boundingObject USE wall_6
}
Solid {
  translation 0.359999 -0.54 0.075
  rotation 0 0 1 1.5708
  children [
    DEF wall_16 Shape {
      appearance PBRAppearance {
        metalness 0
      }
      geometry Box {
        size 0.01 0.36 0.15
      }
    }
  ]
  name "solid(5)"
  boundingObject USE wall_16
}
Solid {
  translation 1.08 0.9 0.075
  rotation 0 0 1 1.5708
  children [
    DEF wall_8 Shape {
      appearance PBRAppearance {
        metalness 0
      }
      geometry Box {
        size 0.01 0.36 0.15
      }
    }
  ]
  name "solid(13)"
  boundingObject USE wall_8
}
Solid {
  translation 1.08 -0.18 0.075
  rotation 0 0 1 1.5708
  children [
    DEF wall_8 Shape {
      appearance PBRAppearance {
        metalness 0
      }
      geometry Box {
        size 0.01 0.36 0.15
      }
    }
  ]
  name "solid(10)"
  boundingObject USE wall_8
}
Solid {
  translation 0.54 0 0.075
  children [
    DEF wall_15 Shape {
      appearance PBRAppearance {
        metalness 0
      }
      geometry Box {
        size 0.01 1.08 0.15
      }
    }
  ]
  name "solid(1)"
  boundingObject USE wall_15
}
Solid {
  translation -0.9 0.9 0.075
  children [
    DEF wall_4 Shape {
      appearance PBRAppearance {
        metalness 0
      }
      geometry Box {
        size 0.01 0.72 0.15
      }
    }
  ]
  name "solid(2)"
  boundingObject USE wall_4
}
Solid {
  translation -0.9 -0.54 0.075
  children [
    DEF wall_2 Shape {
      appearance PBRAppearance {
        metalness 0
      }
      geometry Box {
        size 0.01 0.72 0.15
      }
    }
  ]
  name "solid(15)"
  boundingObject USE wall_2
}
Robot {
  translation -0.6781561926752532 -1.0739904598485812 0.021592333423814166
  rotation -0.12014352995455611 -0.07249492339619137 0.9901060641627435 0.8282120735733204
  children [
    DEF ClasterWheel BallJoint {
      jointParameters BallJointParameters {
        position -0.1556584420455847
        anchor 0 -0.06 -0.019
      }
      jointParameters2 JointParameters {
        position 0.0453376897616631
      }
      jointParameters3 JointParameters {
        position 0.09741058260918906
        axis 0 1 0
      }
      endPoint Solid {
        translation -2.7836820206683655e-05 -0.06017305111801896 -0.019014616571372947
        rotation -0.7747225598436 -0.6320255356878668 0.018672908392768306 -1.0056021105993755
        children [
          DEF Claster Shape {
            appearance PBRAppearance {
              baseColor 0 0 1
              metalness 0
            }
            geometry Sphere {
              radius 0.01
            }
          }
        ]
        name "solid(2)"
        boundingObject USE Claster
        physics Physics {
        }
        linearVelocity 0.14900647361592018 0.020996182218604102 0.0027761831852881396
        angularVelocity -2.099617842129417 14.900646882851994 -2.703448929174507e-15
      }
    }
    DEF waist robotArm {
      translation 0 0.03 0.012
      rotation 0 0 1 0.09278536397599607
      scale 0.2 0.2 0.2
    }
    DEF d4 DistanceSensor {
      translation -0.05 0.07 0.005
      rotation 0 0 1 3.141592653589793
      name "distance sensor(4)"
    }
    DEF d3 DistanceSensor {
      translation 0 0.07 0.005
      rotation 0 0 1 2.3561996938995744
      name "distance sensor(3)"
    }
    DEF d2 DistanceSensor {
      translation 0.05 0.07 0.005
      name "distance sensor(2)"
    }
    DEF d1 DistanceSensor {
      translation 0 0.07 0.005
      rotation 0 0 1 0.7854003061004253
      name "distance sensor(1)"
    }
    DEF d0 DistanceSensor {
      translation 0 0.07 0.005
      rotation 0 0 1 1.5707996938995747
    }
    DEF left1 HingeJoint {
      jointParameters HingeJointParameters {
        position 71.16746530970676
        anchor 0.055 0.03 0
      }
      device [
        DEF Left_motor1 RotationalMotor {
          name "Left_motor1"
        }
      ]
      endPoint Solid {
        translation -0.07199999999999993 0.03 0
        rotation -0.6256229374642337 -0.4521081778141151 -0.6357626409850017 3.9868450395166066
        children [
          DEF wheel Shape {
            appearance PBRAppearance {
              baseColor 0 0 1
              metalness 0
            }
            geometry Cylinder {
              height 0.01
              radius 0.0195
            }
          }
        ]
        name "solid(1)"
        boundingObject USE wheel
        physics Physics {
        }
        linearVelocity 0.1346321486699147 -0.13384859269641886 0.00021694597298245133
        angularVelocity 7.078951572378303 7.1214642788434155 1.509112438595803
      }
    }
    DEF Body Shape {
      appearance PBRAppearance {
        metalness 0
      }
      geometry Box {
        size 0.13 0.182 0.0195
      }
    }
    DEF right1 HingeJoint {
      jointParameters HingeJointParameters {
        position -23.356159689108967
        anchor -0.055 0.03 0
      }
      device [
        RotationalMotor {
          name "Right_motor1"
        }
      ]
      endPoint Solid {
        translation 0.07199999999999976 0.02999500000216717 1.4361000754534448e-05
        rotation 0.6130611868584269 0.4983063894235885 0.6130633926661778 2.2170119203611476
        children [
          DEF Wheel Shape {
            appearance PBRAppearance {
              baseColor 0 0 1
              metalness 0
            }
            geometry Cylinder {
              height 0.01
              radius 0.0195
            }
          }
        ]
        name "solid_motor"
        boundingObject USE Wheel
        physics Physics {
        }
        linearVelocity -0.002421325990952629 0.0020329841017143143 -0.00011446733318330526
        angularVelocity -0.03467244619138317 0.09581798572618101 1.3173314437996213
      }
    }
  ]
  boundingObject USE Body
  physics Physics {
  }
  controller "my_controller"
  linearVelocity 0.09303611877668325 -0.036779190313463064 0.0054217621034783215
  angularVelocity -0.03467529586276859 0.09581583503883884 1.3173310231344089
}
