#VRML_SIM R2023a utf8

EXTERNPROTO "https://raw.githubusercontent.com/cyberbotics/webots/R2023a/projects/objects/backgrounds/protos/TexturedBackground.proto"
EXTERNPROTO "https://raw.githubusercontent.com/cyberbotics/webots/R2023a/projects/objects/backgrounds/protos/TexturedBackgroundLight.proto"
EXTERNPROTO "https://raw.githubusercontent.com/cyberbotics/webots/R2023a/projects/objects/floors/protos/RectangleArena.proto"
EXTERNPROTO "https://raw.githubusercontent.com/cyberbotics/webots/R2023a/projects/appearances/protos/Parquetry.proto"
EXTERNPROTO "https://raw.githubusercontent.com/cyberbotics/webots/R2023a/projects/appearances/protos/BrushedAluminium.proto"

WorldInfo {
}
Viewpoint {
  orientation -0.39170933296730837 0.445692949855996 0.8049357694344108 1.658573238517443
  position -0.18735721547696046 -2.991091895573835 3.114442573319414
}
TexturedBackground {
}
TexturedBackgroundLight {
}
RectangleArena {
  floorSize 2.52 2.52
  floorTileSize 0.72 0.72
  floorAppearance Parquetry {
    type "dark strip"
    colorOverride 0 0 0
  }
  wallHeight 0.15
  wallAppearance BrushedAluminium {
    IBLStrength 8
  }
}
Solid {
  translation -0.54 0 0.075
  children [
    DEF wall_13 Shape {
      appearance PBRAppearance {
        metalness 0
      }
      geometry Box {
        size 0.01 1.08 0.15
      }
    }
  ]
  boundingObject USE wall_13
}
Solid {
  translation -6.74634e-14 -0.9 0.075
  rotation 0 0 1 1.5708
  children [
    DEF wall_8 Shape {
      appearance PBRAppearance {
        metalness 0
      }
      geometry Box {
        size 0.01 1.08 0.15
      }
    }
  ]
  name "solid(3)"
  boundingObject USE wall_8
}
Solid {
  translation -5.28942e-06 0.54 0.075
  rotation 0 0 1 1.5708
  children [
    DEF wall_14 Shape {
      appearance PBRAppearance {
        metalness 0
      }
      geometry Box {
        size 0.01 1.08 0.15
      }
    }
  ]
  name "solid(7)"
  boundingObject USE wall_14
}
Solid {
  translation -0.180002 0.9 0.075
  rotation 0 0 1 1.5708
  children [
    DEF wall_5 Shape {
      appearance PBRAppearance {
        metalness 0
      }
      geometry Box {
        size 0.01 0.72 0.15
      }
    }
  ]
  name "solid(8)"
  boundingObject USE wall_5
}
Solid {
  translation -0.360001 -0.54 0.075
  rotation 0 0 1 1.5708
  children [
    DEF wall_12 Shape {
      appearance PBRAppearance {
        metalness 0
      }
      geometry Box {
        size 0.01 0.36 0.15
      }
    }
  ]
  name "solid(4)"
  boundingObject USE wall_12
}
Solid {
  translation -0.720001 0.18 0.075
  rotation 0 0 1 1.5708
  children [
    DEF wall_3 Shape {
      appearance PBRAppearance {
        metalness 0
      }
      geometry Box {
        size 0.01 0.36 0.15
      }
    }
  ]
  name "solid(14)"
  boundingObject USE wall_3
}
DEF wall Solid {
  translation -1.08 -0.91 0.075
  rotation 0 0 1 1.5708
  children [
    DEF wall_1 Shape {
      appearance PBRAppearance {
        metalness 0
      }
      geometry Box {
        size 0.01 0.36 0.15
      }
    }
  ]
  name "wall"
  boundingObject USE wall_1
}
Solid {
  translation -0.180001 -0.72 0.075
  rotation 0 0 1 -3.1415853071795863
  children [
    DEF wall_11 Shape {
      appearance PBRAppearance {
        metalness 0
      }
      geometry Box {
        size 0.01 0.36 0.15
      }
    }
  ]
  name "solid(6)"
  boundingObject USE wall_11
}
Solid {
  translation 0.539996 1.08 0.075
  rotation 0 0 1 -3.1415853071795863
  children [
    DEF wall_7 Shape {
      appearance PBRAppearance {
        metalness 0
      }
      geometry Box {
        size 0.01 0.36 0.15
      }
    }
  ]
  name "solid(12)"
  boundingObject USE wall_7
}
Solid {
  translation 0.9 -1.07999 0.075
  rotation 0 0 1 -3.1415853071795863
  children [
    DEF wall_10 Shape {
      appearance PBRAppearance {
        metalness 0
      }
      geometry Box {
        size 0.01 0.36 0.15
      }
    }
  ]
  name "solid(11)"
  boundingObject USE wall_10
}
Solid {
  translation 0.9 -0.35999 0.075
  rotation 0 0 1 -3.1415853071795863
  children [
    DEF wall_9 Shape {
      appearance PBRAppearance {
        metalness 0
      }
      geometry Box {
        size 0.01 0.36 0.15
      }
    }
  ]
  name "solid(17)"
  boundingObject USE wall_9
}
Solid {
  translation 0.179991 1.08 0.075
  rotation 0 0 1 -3.1415853071795863
  children [
    DEF wall_6 Shape {
      appearance PBRAppearance {
        metalness 0
      }
      geometry Box {
        size 0.01 0.36 0.15
      }
    }
  ]
  name "solid(9)"
  boundingObject USE wall_6
}
Solid {
  translation 0.359999 -0.54 0.075
  rotation 0 0 1 1.5708
  children [
    DEF wall_16 Shape {
      appearance PBRAppearance {
        metalness 0
      }
      geometry Box {
        size 0.01 0.36 0.15
      }
    }
  ]
  name "solid(5)"
  boundingObject USE wall_16
}
Solid {
  translation 1.08 0.9 0.075
  rotation 0 0 1 1.5708
  children [
    DEF wall_8 Shape {
      appearance PBRAppearance {
        metalness 0
      }
      geometry Box {
        size 0.01 0.36 0.15
      }
    }
  ]
  name "solid(13)"
  boundingObject USE wall_8
}
Solid {
  translation 1.08 -0.18 0.075
  rotation 0 0 1 1.5708
  children [
    DEF wall_8 Shape {
      appearance PBRAppearance {
        metalness 0
      }
      geometry Box {
        size 0.01 0.36 0.15
      }
    }
  ]
  name "solid(10)"
  boundingObject USE wall_8
}
Solid {
  translation 0.54 0 0.075
  children [
    DEF wall_15 Shape {
      appearance PBRAppearance {
        metalness 0
      }
      geometry Box {
        size 0.01 1.08 0.15
      }
    }
  ]
  name "solid(1)"
  boundingObject USE wall_15
}
Solid {
  translation -0.9 0.9 0.075
  children [
    DEF wall_4 Shape {
      appearance PBRAppearance {
        metalness 0
      }
      geometry Box {
        size 0.01 0.72 0.15
      }
    }
  ]
  name "solid(2)"
  boundingObject USE wall_4
}
Solid {
  translation -0.9 -0.54 0.075
  children [
    DEF wall_2 Shape {
      appearance PBRAppearance {
        metalness 0
      }
      geometry Box {
        size 0.01 0.72 0.15
      }
    }
  ]
  name "solid(15)"
  boundingObject USE wall_2
}
Robot {
  translation -0.7199294571919925 -0.23010327420281657 0.014879441775854655
  rotation -0.49401872875485714 -0.004331464689406664 0.8694404718283358 0.001148545912718611
  children [
    DEF d4 DistanceSensor {
      translation 0 0.07 0.005
      rotation 0 0 1 3.141592653589793
      name "distance sensor(4)"
    }
    DEF d3 DistanceSensor {
      translation 0 0.07 0.005
      rotation 0 0 1 2.3561996938995744
      name "distance sensor(3)"
    }
    DEF d2 DistanceSensor {
      translation 0 0.07 0.005
      name "distance sensor(2)"
    }
    DEF d1 DistanceSensor {
      translation 0 0.07 0.005
      rotation 0 0 1 0.7854003061004253
      name "distance sensor(1)"
    }
    DEF d0 DistanceSensor {
      translation 0 0.07 0.005
      rotation 0 0 1 1.5707996938995747
    }
    DEF right2 HingeJoint {
      jointParameters HingeJointParameters {
        position -1.506940222581305e-07
        anchor 0.055 -0.04 0
      }
      device [
        RotationalMotor {
          name "Right_motor2"
        }
      ]
      endPoint Solid {
        translation 0.055048342441120605 -0.040023518599145526 -1.2541791334960659e-05
        rotation -6.763416192372756e-08 0.9999999999999948 -7.561477512512336e-08 1.570800311854295
        children [
          DEF Wheel Shape {
            appearance PBRAppearance {
              baseColor 0 0 1
              metalness 0
            }
            geometry Cylinder {
              height 0.01
              radius 0.015
            }
          }
        ]
        name "solid(3)"
        boundingObject USE Wheel
        physics Physics {
        }
      }
    }
    DEF left2 HingeJoint {
      jointParameters HingeJointParameters {
        anchor 0.055 -0.04 0
      }
      device [
        RotationalMotor {
          name "Left_motor2"
        }
      ]
      endPoint Solid {
        translation -0.05499999999999986 -0.04 0
        rotation 1.6763259002921578e-07 0.9999999999999688 1.8493665049696337e-07 1.5708000580488213
        children [
          DEF wheel Shape {
            appearance PBRAppearance {
              baseColor 0 0 1
              metalness 0
            }
            geometry Cylinder {
              height 0.01
              radius 0.015
            }
          }
        ]
        name "solid(2)"
        boundingObject USE wheel
        physics Physics {
        }
      }
    }
    DEF left1 HingeJoint {
      jointParameters HingeJointParameters {
        position 85.24799454799299
        anchor 0.055 0.03 0
      }
      device [
        DEF Left_motor1 RotationalMotor {
          name "Left_motor1"
        }
      ]
      endPoint Solid {
        translation -0.05500000000000108 0.03 0
        rotation -0.6994987752291932 0.09896097666169008 -0.7077486761209963 2.9538111260731004
        children [
          DEF wheel Shape {
            appearance PBRAppearance {
              baseColor 0 0 1
              metalness 0
            }
            geometry Cylinder {
              height 0.01
              radius 0.015
            }
          }
        ]
        name "solid(1)"
        boundingObject USE wheel
        physics Physics {
        }
      }
    }
    DEF Body Shape {
      appearance PBRAppearance {
        metalness 0
      }
      geometry Box {
        size 0.1 0.15 0.01
      }
    }
    DEF right1 HingeJoint {
      jointParameters HingeJointParameters {
        anchor -0.055 0.03 0
      }
      device [
        RotationalMotor {
          name "Right_motor1"
        }
      ]
      endPoint Solid {
        translation 0.05506087867990909 0.030015695285869858 4.9450665115697055e-06
        rotation 9.263322982710945e-09 1 9.26335642562015e-09 1.5707999248106108
        children [
          DEF Wheel Shape {
            appearance PBRAppearance {
              baseColor 0 0 1
              metalness 0
            }
            geometry Cylinder {
              height 0.01
              radius 0.015
            }
          }
        ]
        boundingObject USE Wheel
        physics Physics {
        }
      }
    }
  ]
  boundingObject USE Body
  physics Physics {
  }
  controller "my_controller"
}
