#VRML_SIM R2023a utf8

EXTERNPROTO "https://raw.githubusercontent.com/cyberbotics/webots/R2023a/projects/objects/backgrounds/protos/TexturedBackground.proto"
EXTERNPROTO "https://raw.githubusercontent.com/cyberbotics/webots/R2023a/projects/objects/backgrounds/protos/TexturedBackgroundLight.proto"
EXTERNPROTO "https://raw.githubusercontent.com/cyberbotics/webots/R2023a/projects/objects/floors/protos/RectangleArena.proto"
EXTERNPROTO "https://raw.githubusercontent.com/cyberbotics/webots/R2023a/projects/appearances/protos/Parquetry.proto"
EXTERNPROTO "https://raw.githubusercontent.com/cyberbotics/webots/R2023a/projects/appearances/protos/BrushedAluminium.proto"
EXTERNPROTO "../protos/robotArm.proto"

WorldInfo {
}
Viewpoint {
  orientation -0.6815396975788678 -0.2620728723764494 0.683243331609217 3.6554392796543747
  position -0.6499399370880068 -0.7579739945490871 1.6805910898645386
}
TexturedBackground {
}
TexturedBackgroundLight {
}
RectangleArena {
  floorSize 2.52 2.52
  floorTileSize 0.72 0.72
  floorAppearance Parquetry {
    type "dark strip"
    colorOverride 1 0 1
  }
  wallHeight 0.15
  wallAppearance BrushedAluminium {
    IBLStrength 8
  }
}
Solid {
  translation -0.54 0 0.075
  children [
    DEF wall_13 Shape {
      appearance PBRAppearance {
        metalness 0
      }
      geometry Box {
        size 0.01 1.08 0.15
      }
    }
  ]
  boundingObject USE wall_13
}
Solid {
  translation -6.74634e-14 -0.9 0.075
  rotation 0 0 1 1.5708
  children [
    DEF wall_8 Shape {
      appearance PBRAppearance {
        metalness 0
      }
      geometry Box {
        size 0.01 1.08 0.15
      }
    }
  ]
  name "solid(3)"
  boundingObject USE wall_8
}
Solid {
  translation -5.28942e-06 0.54 0.075
  rotation 0 0 1 1.5708
  children [
    DEF wall_14 Shape {
      appearance PBRAppearance {
        metalness 0
      }
      geometry Box {
        size 0.01 1.08 0.15
      }
    }
  ]
  name "solid(7)"
  boundingObject USE wall_14
}
Solid {
  translation -0.180002 0.9 0.075
  rotation 0 0 1 1.5708
  children [
    DEF wall_5 Shape {
      appearance PBRAppearance {
        metalness 0
      }
      geometry Box {
        size 0.01 0.72 0.15
      }
    }
  ]
  name "solid(8)"
  boundingObject USE wall_5
}
Solid {
  translation -0.360001 -0.54 0.075
  rotation 0 0 1 1.5708
  children [
    DEF wall_12 Shape {
      appearance PBRAppearance {
        metalness 0
      }
      geometry Box {
        size 0.01 0.36 0.15
      }
    }
  ]
  name "solid(4)"
  boundingObject USE wall_12
}
Solid {
  translation -0.720001 0.18 0.075
  rotation 0 0 1 1.5708
  children [
    DEF wall_3 Shape {
      appearance PBRAppearance {
        metalness 0
      }
      geometry Box {
        size 0.01 0.36 0.15
      }
    }
  ]
  name "solid(14)"
  boundingObject USE wall_3
}
DEF wall Solid {
  translation -1.08 -0.91 0.075
  rotation 0 0 1 1.5708
  children [
    DEF wall_1 Shape {
      appearance PBRAppearance {
        metalness 0
      }
      geometry Box {
        size 0.01 0.36 0.15
      }
    }
  ]
  name "wall"
  boundingObject USE wall_1
}
Solid {
  translation -0.180001 -0.72 0.075
  rotation 0 0 1 -3.1415853071795863
  children [
    DEF wall_11 Shape {
      appearance PBRAppearance {
        metalness 0
      }
      geometry Box {
        size 0.01 0.36 0.15
      }
    }
  ]
  name "solid(6)"
  boundingObject USE wall_11
}
Solid {
  translation 0.539996 1.08 0.075
  rotation 0 0 1 -3.1415853071795863
  children [
    DEF wall_7 Shape {
      appearance PBRAppearance {
        metalness 0
      }
      geometry Box {
        size 0.01 0.36 0.15
      }
    }
  ]
  name "solid(12)"
  boundingObject USE wall_7
}
Solid {
  translation 0.9 -1.07999 0.075
  rotation 0 0 1 -3.1415853071795863
  children [
    DEF wall_10 Shape {
      appearance PBRAppearance {
        metalness 0
      }
      geometry Box {
        size 0.01 0.36 0.15
      }
    }
  ]
  name "solid(11)"
  boundingObject USE wall_10
}
Solid {
  translation 0.9 -0.35999 0.075
  rotation 0 0 1 -3.1415853071795863
  children [
    DEF wall_9 Shape {
      appearance PBRAppearance {
        metalness 0
      }
      geometry Box {
        size 0.01 0.36 0.15
      }
    }
  ]
  name "solid(17)"
  boundingObject USE wall_9
}
Solid {
  translation 0.179991 1.08 0.075
  rotation 0 0 1 -3.1415853071795863
  children [
    DEF wall_6 Shape {
      appearance PBRAppearance {
        metalness 0
      }
      geometry Box {
        size 0.01 0.36 0.15
      }
    }
  ]
  name "solid(9)"
  boundingObject USE wall_6
}
Solid {
  translation 0.359999 -0.54 0.075
  rotation 0 0 1 1.5708
  children [
    DEF wall_16 Shape {
      appearance PBRAppearance {
        metalness 0
      }
      geometry Box {
        size 0.01 0.36 0.15
      }
    }
  ]
  name "solid(5)"
  boundingObject USE wall_16
}
Solid {
  translation 1.08 0.9 0.075
  rotation 0 0 1 1.5708
  children [
    DEF wall_8 Shape {
      appearance PBRAppearance {
        metalness 0
      }
      geometry Box {
        size 0.01 0.36 0.15
      }
    }
  ]
  name "solid(13)"
  boundingObject USE wall_8
}
Solid {
  translation 1.08 -0.18 0.075
  rotation 0 0 1 1.5708
  children [
    DEF wall_8 Shape {
      appearance PBRAppearance {
        metalness 0
      }
      geometry Box {
        size 0.01 0.36 0.15
      }
    }
  ]
  name "solid(10)"
  boundingObject USE wall_8
}
Solid {
  translation 0.54 0 0.075
  children [
    DEF wall_15 Shape {
      appearance PBRAppearance {
        metalness 0
      }
      geometry Box {
        size 0.01 1.08 0.15
      }
    }
  ]
  name "solid(1)"
  boundingObject USE wall_15
}
Solid {
  translation -0.9 0.9 0.075
  children [
    DEF wall_4 Shape {
      appearance PBRAppearance {
        metalness 0
      }
      geometry Box {
        size 0.01 0.72 0.15
      }
    }
  ]
  name "solid(2)"
  boundingObject USE wall_4
}
Solid {
  translation -0.9 -0.54 0.075
  children [
    DEF wall_2 Shape {
      appearance PBRAppearance {
        metalness 0
      }
      geometry Box {
        size 0.01 0.72 0.15
      }
    }
  ]
  name "solid(15)"
  boundingObject USE wall_2
}
Robot {
  translation -0.71039 -0.810649 0.0276741
  rotation 0.020361036267001444 -9.557472818531279e-05 0.9997926880446791 -2.2770556164766447
  children [
    DEF ClasterWheel BallJoint {
      jointParameters BallJointParameters {
        position 13.323597644122186
        anchor 0 -0.06 -0.019
      }
      jointParameters2 JointParameters {
        position -16.823905046152746
      }
      jointParameters3 JointParameters {
        position -19.111954826155063
        axis 0 1 0
      }
      endPoint Solid {
        translation 1.7076184216646695e-18 -0.06 -0.02
        rotation 0.9508812563614727 0.29043790850983564 0.10710115592681495 2.0273091359463837
        children [
          DEF Claster Shape {
            appearance PBRAppearance {
              baseColor 0 0 1
              metalness 0
            }
            geometry Sphere {
              radius 0.01
            }
          }
        ]
        name "solid(2)"
        boundingObject USE Claster
        physics Physics {
        }
      }
    }
    DEF waist robotArm {
      translation 0 0.03 0.012
      rotation 0 0 1 2.076773136935329
      scale 0.2 0.2 0.2
    }
    DEF d4 DistanceSensor {
      translation -0.05 0.07 0.005
      rotation 0 0 1 3.141592653589793
      name "distance sensor(4)"
    }
    DEF d3 DistanceSensor {
      translation 0 0.07 0.005
      rotation 0 0 1 2.3561996938995744
      name "distance sensor(3)"
    }
    DEF d2 DistanceSensor {
      translation 0.05 0.07 0.005
      name "distance sensor(2)"
    }
    DEF d1 DistanceSensor {
      translation 0 0.07 0.005
      rotation 0 0 1 0.7854003061004253
      name "distance sensor(1)"
    }
    DEF d0 DistanceSensor {
      translation 0 0.07 0.005
      rotation 0 0 1 1.5707996938995747
    }
    DEF left1 HingeJoint {
      jointParameters HingeJointParameters {
        position 269.54281952003026
        anchor 0.055 0.03 0
      }
      device [
        DEF Left_motor1 RotationalMotor {
          name "Left_motor1"
        }
      ]
      endPoint Solid {
        translation -0.07200259129342854 0.02999891487841478 -4.3350338161887976e-06
        rotation -0.4472972674938941 0.7735459781295353 -0.44894517951762924 1.8396790885434322
        children [
          DEF wheel Shape {
            appearance PBRAppearance {
              baseColor 0 0 1
              metalness 0
            }
            geometry Cylinder {
              height 0.01
              radius 0.03
            }
          }
        ]
        name "solid(1)"
        boundingObject USE wheel
        physics Physics {
        }
      }
    }
    DEF Body Shape {
      appearance PBRAppearance {
        metalness 0
      }
      geometry Box {
        size 0.13 0.182 0.0195
      }
    }
    DEF right1 HingeJoint {
      jointParameters HingeJointParameters {
        position -23.356160005921243
        anchor -0.055 0.03 0
      }
      device [
        RotationalMotor {
          name "Right_motor1"
        }
      ]
      endPoint Solid {
        translation 0.0719999999999997 0.029995000006716913 1.4361002338594421e-05
        rotation 0.6130611375909739 0.4983065106504784 0.6130633433985477 2.217011726135845
        children [
          DEF Wheel Shape {
            appearance PBRAppearance {
              baseColor 0 0 1
              metalness 0
            }
            geometry Cylinder {
              height 0.01
              radius 0.03
            }
          }
        ]
        name "solid_motor"
        boundingObject USE Wheel
        physics Physics {
        }
      }
    }
  ]
  boundingObject USE Body
  physics Physics {
  }
  controller "my_controller"
}
