#VRML_SIM R2023a utf8

EXTERNPROTO "https://raw.githubusercontent.com/cyberbotics/webots/R2023a/projects/objects/backgrounds/protos/TexturedBackground.proto"
EXTERNPROTO "https://raw.githubusercontent.com/cyberbotics/webots/R2023a/projects/objects/backgrounds/protos/TexturedBackgroundLight.proto"
EXTERNPROTO "https://raw.githubusercontent.com/cyberbotics/webots/R2023a/projects/objects/floors/protos/RectangleArena.proto"
EXTERNPROTO "https://raw.githubusercontent.com/cyberbotics/webots/R2023a/projects/appearances/protos/Parquetry.proto"
EXTERNPROTO "https://raw.githubusercontent.com/cyberbotics/webots/R2023a/projects/appearances/protos/BrushedAluminium.proto"

WorldInfo {
}
Viewpoint {
  orientation -0.3143907228591373 0.6097993571840463 0.7275322792550396 1.2330217192540738
  position -2.3973866372508614 -2.9016310021797596 3.494070268572254
}
TexturedBackground {
}
TexturedBackgroundLight {
}
RectangleArena {
  floorSize 2.52 2.52
  floorTileSize 0.72 0.72
  floorAppearance Parquetry {
    type "dark strip"
    colorOverride 0 0 0
  }
  wallHeight 0.15
  wallAppearance BrushedAluminium {
    IBLStrength 8
  }
}
Solid {
  translation -0.54 0 0.075
  children [
    Shape {
      appearance PBRAppearance {
        metalness 0
      }
      geometry Box {
        size 0.01 1.08 0.15
      }
    }
  ]
}
Solid {
  translation -6.74634e-14 -0.9 0.075
  rotation 0 0 1 1.5708
  children [
    Shape {
      appearance PBRAppearance {
        metalness 0
      }
      geometry Box {
        size 0.01 1.08 0.15
      }
    }
  ]
  name "solid(3)"
}
Solid {
  translation -5.28942e-06 0.54 0.075
  rotation 0 0 1 1.5708
  children [
    Shape {
      appearance PBRAppearance {
        metalness 0
      }
      geometry Box {
        size 0.01 1.08 0.15
      }
    }
  ]
  name "solid(7)"
}
Solid {
  translation -0.180002 0.9 0.075
  rotation 0 0 1 1.5708
  children [
    Shape {
      appearance PBRAppearance {
        metalness 0
      }
      geometry Box {
        size 0.01 0.72 0.15
      }
    }
  ]
  name "solid(8)"
}
Solid {
  translation -0.360001 -0.54 0.075
  rotation 0 0 1 1.5708
  children [
    Shape {
      appearance PBRAppearance {
        metalness 0
      }
      geometry Box {
        size 0.01 0.36 0.15
      }
    }
  ]
  name "solid(4)"
}
Solid {
  translation -0.720001 0.18 0.075
  rotation 0 0 1 1.5708
  children [
    Shape {
      appearance PBRAppearance {
        metalness 0
      }
      geometry Box {
        size 0.01 0.36 0.15
      }
    }
  ]
  name "solid(14)"
}
Solid {
  translation -1.08 -0.91 0.075
  rotation 0 0 1 1.5708
  children [
    Shape {
      appearance PBRAppearance {
        metalness 0
      }
      geometry Box {
        size 0.01 0.36 0.15
      }
    }
  ]
  name "solid(16)"
}
Solid {
  translation -0.180001 -0.72 0.075
  rotation 0 0 1 -3.1415853071795863
  children [
    Shape {
      appearance PBRAppearance {
        metalness 0
      }
      geometry Box {
        size 0.01 0.36 0.15
      }
    }
  ]
  name "solid(6)"
}
Solid {
  translation 0.539996 1.08 0.075
  rotation 0 0 1 -3.1415853071795863
  children [
    Shape {
      appearance PBRAppearance {
        metalness 0
      }
      geometry Box {
        size 0.01 0.36 0.15
      }
    }
  ]
  name "solid(12)"
}
Solid {
  translation 0.9 -1.07999 0.075
  rotation 0 0 1 -3.1415853071795863
  children [
    Shape {
      appearance PBRAppearance {
        metalness 0
      }
      geometry Box {
        size 0.01 0.36 0.15
      }
    }
  ]
  name "solid(11)"
}
Solid {
  translation 0.9 -0.35999 0.075
  rotation 0 0 1 -3.1415853071795863
  children [
    Shape {
      appearance PBRAppearance {
        metalness 0
      }
      geometry Box {
        size 0.01 0.36 0.15
      }
    }
  ]
  name "solid(17)"
}
Solid {
  translation 0.179991 1.08 0.075
  rotation 0 0 1 -3.1415853071795863
  children [
    Shape {
      appearance PBRAppearance {
        metalness 0
      }
      geometry Box {
        size 0.01 0.36 0.15
      }
    }
  ]
  name "solid(9)"
}
Solid {
  translation 0.359999 -0.54 0.075
  rotation 0 0 1 1.5708
  children [
    Shape {
      appearance PBRAppearance {
        metalness 0
      }
      geometry Box {
        size 0.01 0.36 0.15
      }
    }
  ]
  name "solid(5)"
}
Solid {
  translation 1.08 0.9 0.075
  rotation 0 0 1 1.5708
  children [
    Shape {
      appearance PBRAppearance {
        metalness 0
      }
      geometry Box {
        size 0.01 0.36 0.15
      }
    }
  ]
  name "solid(13)"
}
Solid {
  translation 1.08 -0.18 0.075
  rotation 0 0 1 1.5708
  children [
    Shape {
      appearance PBRAppearance {
        metalness 0
      }
      geometry Box {
        size 0.01 0.36 0.15
      }
    }
  ]
  name "solid(10)"
}
Solid {
  translation 0.54 0 0.075
  children [
    Shape {
      appearance PBRAppearance {
        metalness 0
      }
      geometry Box {
        size 0.01 1.08 0.15
      }
    }
  ]
  name "solid(1)"
}
Solid {
  translation -0.9 0.9 0.075
  children [
    Shape {
      appearance PBRAppearance {
        metalness 0
      }
      geometry Box {
        size 0.01 0.72 0.15
      }
    }
  ]
  name "solid(2)"
}
Solid {
  translation -0.9 -0.54 0.075
  children [
    Shape {
      appearance PBRAppearance {
        metalness 0
      }
      geometry Box {
        size 0.01 0.72 0.15
      }
    }
  ]
  name "solid(15)"
}
Robot {
  translation -0.72 -0.230003 0.0299774
  rotation -0.9999998774655164 -0.0004950440207052201 6.077039561306071e-07 6.128354263936896e-05
  scale 1.5 1.5 1.5
  children [
    DEF d4 DistanceSensor {
      translation 0 0.07 0.005
      rotation 0 0 1 3.141592653589793
      name "distance sensor(4)"
    }
    DEF d3 DistanceSensor {
      translation 0 0.07 0.005
      rotation 0 0 1 2.3561996938995744
      name "distance sensor(3)"
    }
    DEF d2 DistanceSensor {
      translation 0 0.07 0.005
      name "distance sensor(2)"
    }
    DEF d1 DistanceSensor {
      translation 0 0.07 0.005
      rotation 0 0 1 0.7854003061004253
      name "distance sensor(1)"
    }
    DEF d0 DistanceSensor {
      translation 0 0.07 0.005
      rotation 0 0 1 1.5707996938995747
    }
    HingeJoint {
      jointParameters HingeJointParameters {
        position -6.551885933540673e-08
      }
      device [
        RotationalMotor {
        }
      ]
      endPoint Solid {
        translation 0.05499999999999999 -0.04000000000003657 -4.3546720967084687e-07
        rotation -2.5230692149464645e-08 0.9999999999999992 -2.5060034692345635e-08 1.5708003024263841
        children [
          DEF Wheel Shape {
            appearance PBRAppearance {
              baseColor 0 0 1
              metalness 0
            }
            geometry Cylinder {
              height 0.01
              radius 0.015
            }
          }
        ]
        name "solid(3)"
        boundingObject USE Wheel
        physics Physics {
        }
      }
    }
    HingeJoint {
      jointParameters HingeJointParameters {
        position -6.552169406857647e-08
      }
      device [
        RotationalMotor {
        }
      ]
      endPoint Solid {
        translation -0.05499999999999999 -0.040000000000036576 -4.354670964458621e-07
        rotation -3.8477692277429935e-08 0.9999999999999984 -3.847782061623649e-08 1.5707996698267248
        children [
          DEF wheel Shape {
            appearance PBRAppearance {
              baseColor 0 0 1
              metalness 0
            }
            geometry Cylinder {
              height 0.01
              radius 0.015
            }
          }
        ]
        name "solid(2)"
        boundingObject USE wheel
        physics Physics {
        }
      }
    }
    HingeJoint {
      jointParameters HingeJointParameters {
        position -1.8520463989322606e-08
      }
      device [
        RotationalMotor {
        }
      ]
      endPoint Solid {
        translation -0.05499999999999801 0.02999999999998488 -4.3991072827695396e-07
        rotation -1.4977155800975738e-08 0.9999999999999999 -1.4977205576609597e-08 1.5707996698267235
        children [
          DEF wheel Shape {
            appearance PBRAppearance {
              baseColor 0 0 1
              metalness 0
            }
            geometry Cylinder {
              height 0.01
              radius 0.015
            }
          }
        ]
        name "solid(1)"
        boundingObject USE wheel
        physics Physics {
        }
      }
    }
    DEF Body Shape {
      appearance PBRAppearance {
        metalness 0
      }
      geometry Box {
        size 0.1 0.15 0.01
      }
    }
    HingeJoint {
      jointParameters HingeJointParameters {
        position -1.8526714086980635e-08
      }
      device [
        RotationalMotor {
        }
      ]
      endPoint Solid {
        translation 0.054999999999998 0.02999999999998488 -4.399109163888629e-07
        rotation -1.498027488876314e-08 0.9999999999999997 -1.4980335154159682e-08 1.570800330173281
        children [
          DEF Wheel Shape {
            appearance PBRAppearance {
              baseColor 0 0 1
              metalness 0
            }
            geometry Cylinder {
              height 0.01
              radius 0.015
            }
          }
        ]
        boundingObject USE Wheel
        physics Physics {
        }
      }
    }
  ]
  boundingObject USE Body
  physics Physics {
  }
}
