#VRML_SIM R2023a utf8

EXTERNPROTO "https://raw.githubusercontent.com/cyberbotics/webots/R2023a/projects/objects/backgrounds/protos/TexturedBackground.proto"
EXTERNPROTO "https://raw.githubusercontent.com/cyberbotics/webots/R2023a/projects/objects/backgrounds/protos/TexturedBackgroundLight.proto"
EXTERNPROTO "https://raw.githubusercontent.com/cyberbotics/webots/R2023a/projects/objects/floors/protos/RectangleArena.proto"
EXTERNPROTO "https://raw.githubusercontent.com/cyberbotics/webots/R2023a/projects/appearances/protos/Parquetry.proto"
EXTERNPROTO "https://raw.githubusercontent.com/cyberbotics/webots/R2023a/projects/appearances/protos/BrushedAluminium.proto"
EXTERNPROTO "../protos/robotArm.proto"

WorldInfo {
}
Viewpoint {
  orientation -0.08389591790685856 0.1693040144939897 -0.9819865710053192 5.3485330790788606
  position -1.0438235221942074 -1.2587549340723698 0.008307139063869685
}
TexturedBackground {
}
TexturedBackgroundLight {
}
RectangleArena {
  floorSize 2.52 2.52
  floorTileSize 0.72 0.72
  floorAppearance Parquetry {
    type "dark strip"
    colorOverride 1 0 1
  }
  wallHeight 0.15
  wallAppearance BrushedAluminium {
    IBLStrength 8
  }
}
Solid {
  translation -0.54 0 0.075
  children [
    DEF wall_13 Shape {
      appearance PBRAppearance {
        metalness 0
      }
      geometry Box {
        size 0.01 1.08 0.15
      }
    }
  ]
  boundingObject USE wall_13
}
Solid {
  translation -6.74634e-14 -0.9 0.075
  rotation 0 0 1 1.5708
  children [
    DEF wall_8 Shape {
      appearance PBRAppearance {
        metalness 0
      }
      geometry Box {
        size 0.01 1.08 0.15
      }
    }
  ]
  name "solid(3)"
  boundingObject USE wall_8
}
Solid {
  translation -5.28942e-06 0.54 0.075
  rotation 0 0 1 1.5708
  children [
    DEF wall_14 Shape {
      appearance PBRAppearance {
        metalness 0
      }
      geometry Box {
        size 0.01 1.08 0.15
      }
    }
  ]
  name "solid(7)"
  boundingObject USE wall_14
}
Solid {
  translation -0.180002 0.9 0.075
  rotation 0 0 1 1.5708
  children [
    DEF wall_5 Shape {
      appearance PBRAppearance {
        metalness 0
      }
      geometry Box {
        size 0.01 0.72 0.15
      }
    }
  ]
  name "solid(8)"
  boundingObject USE wall_5
}
Solid {
  translation -0.360001 -0.54 0.075
  rotation 0 0 1 1.5708
  children [
    DEF wall_12 Shape {
      appearance PBRAppearance {
        metalness 0
      }
      geometry Box {
        size 0.01 0.36 0.15
      }
    }
  ]
  name "solid(4)"
  boundingObject USE wall_12
}
Solid {
  translation -0.720001 0.18 0.075
  rotation 0 0 1 1.5708
  children [
    DEF wall_3 Shape {
      appearance PBRAppearance {
        metalness 0
      }
      geometry Box {
        size 0.01 0.36 0.15
      }
    }
  ]
  name "solid(14)"
  boundingObject USE wall_3
}
DEF wall Solid {
  translation -1.08 -0.91 0.075
  rotation 0 0 1 1.5708
  children [
    DEF wall_1 Shape {
      appearance PBRAppearance {
        metalness 0
      }
      geometry Box {
        size 0.01 0.36 0.15
      }
    }
  ]
  name "wall"
  boundingObject USE wall_1
}
Solid {
  translation -0.180001 -0.72 0.075
  rotation 0 0 1 -3.1415853071795863
  children [
    DEF wall_11 Shape {
      appearance PBRAppearance {
        metalness 0
      }
      geometry Box {
        size 0.01 0.36 0.15
      }
    }
  ]
  name "solid(6)"
  boundingObject USE wall_11
}
Solid {
  translation 0.539996 1.08 0.075
  rotation 0 0 1 -3.1415853071795863
  children [
    DEF wall_7 Shape {
      appearance PBRAppearance {
        metalness 0
      }
      geometry Box {
        size 0.01 0.36 0.15
      }
    }
  ]
  name "solid(12)"
  boundingObject USE wall_7
}
Solid {
  translation 0.9 -1.07999 0.075
  rotation 0 0 1 -3.1415853071795863
  children [
    DEF wall_10 Shape {
      appearance PBRAppearance {
        metalness 0
      }
      geometry Box {
        size 0.01 0.36 0.15
      }
    }
  ]
  name "solid(11)"
  boundingObject USE wall_10
}
Solid {
  translation 0.9 -0.35999 0.075
  rotation 0 0 1 -3.1415853071795863
  children [
    DEF wall_9 Shape {
      appearance PBRAppearance {
        metalness 0
      }
      geometry Box {
        size 0.01 0.36 0.15
      }
    }
  ]
  name "solid(17)"
  boundingObject USE wall_9
}
Solid {
  translation 0.179991 1.08 0.075
  rotation 0 0 1 -3.1415853071795863
  children [
    DEF wall_6 Shape {
      appearance PBRAppearance {
        metalness 0
      }
      geometry Box {
        size 0.01 0.36 0.15
      }
    }
  ]
  name "solid(9)"
  boundingObject USE wall_6
}
Solid {
  translation 0.359999 -0.54 0.075
  rotation 0 0 1 1.5708
  children [
    DEF wall_16 Shape {
      appearance PBRAppearance {
        metalness 0
      }
      geometry Box {
        size 0.01 0.36 0.15
      }
    }
  ]
  name "solid(5)"
  boundingObject USE wall_16
}
Solid {
  translation 1.08 0.9 0.075
  rotation 0 0 1 1.5708
  children [
    DEF wall_8 Shape {
      appearance PBRAppearance {
        metalness 0
      }
      geometry Box {
        size 0.01 0.36 0.15
      }
    }
  ]
  name "solid(13)"
  boundingObject USE wall_8
}
Solid {
  translation 1.08 -0.18 0.075
  rotation 0 0 1 1.5708
  children [
    DEF wall_8 Shape {
      appearance PBRAppearance {
        metalness 0
      }
      geometry Box {
        size 0.01 0.36 0.15
      }
    }
  ]
  name "solid(10)"
  boundingObject USE wall_8
}
Solid {
  translation 0.54 0 0.075
  children [
    DEF wall_15 Shape {
      appearance PBRAppearance {
        metalness 0
      }
      geometry Box {
        size 0.01 1.08 0.15
      }
    }
  ]
  name "solid(1)"
  boundingObject USE wall_15
}
Solid {
  translation -0.9 0.9 0.075
  children [
    DEF wall_4 Shape {
      appearance PBRAppearance {
        metalness 0
      }
      geometry Box {
        size 0.01 0.72 0.15
      }
    }
  ]
  name "solid(2)"
  boundingObject USE wall_4
}
Solid {
  translation -0.9 -0.54 0.075
  children [
    DEF wall_2 Shape {
      appearance PBRAppearance {
        metalness 0
      }
      geometry Box {
        size 0.01 0.72 0.15
      }
    }
  ]
  name "solid(15)"
  boundingObject USE wall_2
}
Robot {
  translation -0.9269030843142055 -1.09454398183154 0.030145131628058014
  rotation -0.005839393172616949 0.005477518568413535 -0.9999679486252089 1.501773734099077
  children [
    DEF ClasterWheel BallJoint {
      jointParameters BallJointParameters {
        position 2.5452117072627387
        anchor 0 -0.05 -0.017
      }
      jointParameters2 JointParameters {
        position 0.5239476696495642
      }
      jointParameters3 JointParameters {
        position -0.968970873665036
        axis 0 1 0
      }
      endPoint Solid {
        translation -8.037859267062686e-11 -0.05000003132157138 -0.016997133248554112
        rotation 0.24123508329435045 -0.3202616925661899 0.9160993848172844 1.8773510962422164
        children [
          DEF Claster Shape {
            appearance PBRAppearance {
              baseColor 0 0 1
              metalness 0
            }
            geometry Sphere {
              radius 0.014
            }
          }
        ]
        name "solid(2)"
        boundingObject USE Claster
        physics Physics {
        }
        linearVelocity -1.663794160786589e-06 2.403859323705736e-06 -1.1952755861773644e-06
        angularVelocity -0.00017170423564531542 -0.00011884243810496403 0.7425149252802302
      }
    }
    DEF waist robotArm {
      translation 0 0.04 0.012
      rotation 0 0 1 1.5999692659236002
      scale 0.2 0.2 0.2
    }
    DEF d4 DistanceSensor {
      translation -0.05 0.07 0.005
      rotation 0 0 1 3.141592653589793
      name "distance sensor(4)"
    }
    DEF d3 DistanceSensor {
      translation 0 0.07 0.005
      rotation 0 0 1 2.3561996938995744
      name "distance sensor(3)"
    }
    DEF d2 DistanceSensor {
      translation 0.05 0.07 0.005
      name "distance sensor(2)"
    }
    DEF d1 DistanceSensor {
      translation 0 0.07 0.005
      rotation 0 0 1 0.7854003061004253
      name "distance sensor(1)"
    }
    DEF d0 DistanceSensor {
      translation 0 0.07 0.005
      rotation 0 0 1 1.5707996938995747
    }
    DEF left1 HingeJoint {
      jointParameters HingeJointParameters {
        position 270.1828187972517
        anchor 0.055 0.03 0
      }
      device [
        DEF Left_motor1 RotationalMotor {
          name "Left_motor1"
        }
      ]
      endPoint Solid {
        translation -0.07200259129342837 0.03000171848803132 -4.125143140353599e-06
        rotation -0.20253771300653664 0.9585969862422912 -0.2001756548066682 1.6265620384920991
        children [
          DEF wheel Shape {
            appearance PBRAppearance {
              baseColor 0 0 1
              metalness 0
            }
            geometry Cylinder {
              height 0.01
              radius 0.03
            }
          }
        ]
        name "solid(1)"
        boundingObject USE wheel
        physics Physics {
        }
        linearVelocity 7.171676980365828e-07 -6.676594852301202e-08 -7.36633125244663e-07
        angularVelocity -2.4986589714279996e-05 -3.1733679672198374e-05 -3.824832228431634e-05
      }
    }
    DEF Body Shape {
      appearance PBRAppearance {
        metalness 0
      }
      geometry Box {
        size 0.13 0.2 0.0195
      }
    }
    DEF right1 HingeJoint {
      jointParameters HingeJointParameters {
        position -22.716158522022646
        anchor -0.055 0.03 0
      }
      device [
        RotationalMotor {
          name "Right_motor1"
        }
      ]
      endPoint Solid {
        translation 0.07199999999999929 0.029987413188806197 8.53290718170826e-06
        rotation 0.6829717692960027 0.2590285082482078 0.6829742266435799 2.634678668020583
        children [
          DEF Wheel Shape {
            appearance PBRAppearance {
              baseColor 0 0 1
              metalness 0
            }
            geometry Cylinder {
              height 0.01
              radius 0.03
            }
          }
        ]
        name "solid_motor"
        boundingObject USE Wheel
        physics Physics {
        }
        linearVelocity -4.648123382369378e-06 -4.38376069211886e-07 3.0900939764239692e-06
        angularVelocity -2.4958430482919186e-05 -3.205519514372778e-05 -3.8248328980797455e-05
      }
    }
  ]
  boundingObject USE Body
  physics Physics {
  }
  controller "my_controller"
  linearVelocity -2.0550502246349222e-06 8.996332181616306e-07 2.99841590301294e-07
  angularVelocity -2.4981817504927536e-05 -3.183100016956327e-05 -3.82565520608897e-05
}
