#VRML_SIM R2023a utf8

EXTERNPROTO "https://raw.githubusercontent.com/cyberbotics/webots/R2023a/projects/objects/backgrounds/protos/TexturedBackground.proto"
EXTERNPROTO "https://raw.githubusercontent.com/cyberbotics/webots/R2023a/projects/objects/backgrounds/protos/TexturedBackgroundLight.proto"
EXTERNPROTO "https://raw.githubusercontent.com/cyberbotics/webots/R2023a/projects/objects/floors/protos/RectangleArena.proto"
EXTERNPROTO "https://raw.githubusercontent.com/cyberbotics/webots/R2023a/projects/appearances/protos/BrushedAluminium.proto"

WorldInfo {
}
Viewpoint {
  orientation 0.30960033024194483 0.0032897867280714745 -0.9508610901795082 3.1213782360877906
  position -0.660027035729452 -0.9854605138130665 0.11508735403152207
}
TexturedBackground {
}
TexturedBackgroundLight {
  texture "empty_office"
}
RectangleArena {
  floorSize 2.52 2.52
  floorTileSize 2.52 2.52
  floorAppearance Appearance {
    material Material {
      ambientIntensity 0.8
      diffuseColor 1 1 1
      shininess 0
    }
    texture ImageTexture {
      url [
        "../Assests/corrected.jpg.png"
      ]
      filtering 0
    }
  }
  wallHeight 0.15
  wallAppearance BrushedAluminium {
    IBLStrength 8
  }
}
Robot {
  translation -0.9339 -0.994754 0.0301601
  rotation -0.005546738726679452 0.00521877943489768 -0.9999709985948132 1.5016893376063885
  children [
    DEF LineSensor-3 DistanceSensor {
      translation -0.035 0.101 0
      rotation 0 1 0 1.5707996938995747
      name "linesensor(1)"
      type "infra-red"
    }
    DEF LineSensor-2 DistanceSensor {
      translation -0.025 0.101 0
      rotation 0 1 0 1.5707996938995747
      name "linesensor(2)"
      type "infra-red"
    }
    DEF LineSensor-1 DistanceSensor {
      translation -0.015 0.101 0
      rotation 0 1 0 1.5707996938995747
      name "linesensor(3)"
      type "infra-red"
    }
    DEF LineSensor5 DistanceSensor {
      translation 0.035 0.101 0
      rotation 0 1 0 1.5707996938995747
      name "linesensor(8)"
      type "infra-red"
    }
    DEF LineSensor4 DistanceSensor {
      translation 0.025 0.101 0
      rotation 0 1 0 1.5707996938995747
      name "linesensor(7)"
      type "infra-red"
    }
    DEF LineSensor3 DistanceSensor {
      translation 0.015 0.101 0
      rotation 0 1 0 1.5707996938995747
      name "linesensor(6)"
      type "infra-red"
    }
    DEF LineSensor2 DistanceSensor {
      translation 0.005 0.101 0
      rotation 0 1 0 1.5707996938995747
      name "linesensor(5)"
      type "infra-red"
    }
    DEF LineSensor1 DistanceSensor {
      translation -0.005 0.101 0
      rotation 0 1 0 1.5707996938995747
      name "linesensor(4)"
      type "infra-red"
    }
    DEF ClasterWheel BallJoint {
      jointParameters BallJointParameters {
        position 0.3058693305752484
        anchor 0 -0.05 -0.017
      }
      jointParameters2 JointParameters {
        position 1.403873712261021
      }
      jointParameters3 JointParameters {
        position -0.8033847985655889
        axis 0 1 0
      }
      endPoint Solid {
        translation 1.0227660036189081e-06 -0.050001944667162 -0.01699815840714849
        rotation 0.6997279541656038 -0.09393715197539992 -0.7082066094283287 0.6113228998406675
        children [
          DEF Claster Shape {
            appearance PBRAppearance {
              baseColor 0 0 1
              metalness 0
            }
            geometry Sphere {
              radius 0.014
            }
          }
        ]
        name "solid(2)"
        boundingObject USE Claster
        physics Physics {
        }
      }
    }
    DEF d4 DistanceSensor {
      translation -0.05 0.07 0.005
      rotation 0 0 1 3.141592653589793
      name "distance sensor(4)"
    }
    DEF d3 DistanceSensor {
      translation 0 0.07 0.005
      rotation 0 0 1 2.3561996938995744
      name "distance sensor(3)"
    }
    DEF d2 DistanceSensor {
      translation 0.05 0.07 0.005
      name "distance sensor(2)"
    }
    DEF d1 DistanceSensor {
      translation 0 0.07 0.005
      rotation 0 0 1 0.7854003061004253
      name "distance sensor(1)"
      type "infra-red"
    }
    DEF d0 DistanceSensor {
      translation 0 0.07 0.005
      rotation 0 0 1 1.5707996938995747
    }
    DEF left1 HingeJoint {
      jointParameters HingeJointParameters {
        position 270.18281873082236
        anchor 0.055 0.03 0
      }
      device [
        DEF Left_motor1 RotationalMotor {
          name "Left_motor1"
        }
      ]
      endPoint Solid {
        translation -0.07200259129342629 0.03000171848775729 -4.125143254511527e-06
        rotation -0.2025377431301722 0.9585969734947785 -0.20017568537259336 1.6265620519465431
        children [
          DEF wheel Shape {
            appearance PBRAppearance {
              baseColor 0 0 1
              metalness 0
            }
            geometry Cylinder {
              height 0.01
              radius 0.03
            }
          }
        ]
        name "solid(1)"
        boundingObject USE wheel
        physics Physics {
        }
      }
    }
    DEF Body Shape {
      appearance PBRAppearance {
        metalness 0
      }
      geometry Box {
        size 0.13 0.2 0.0195
      }
    }
    DEF right1 HingeJoint {
      jointParameters HingeJointParameters {
        position -22.716158744095356
        anchor -0.055 0.03 0
      }
      device [
        RotationalMotor {
          name "Right_motor1"
        }
      ]
      endPoint Solid {
        translation 0.0719999999999984 0.029987413190701126 8.532909976895389e-06
        rotation 0.6829717539503285 0.2590285891713465 0.6829742112978452 2.6346785163511934
        children [
          DEF Wheel Shape {
            appearance PBRAppearance {
              baseColor 0 0 1
              metalness 0
            }
            geometry Cylinder {
              height 0.01
              radius 0.03
            }
          }
        ]
        name "solid_motor"
        boundingObject USE Wheel
        physics Physics {
        }
      }
    }
  ]
  boundingObject USE Body
  physics Physics {
  }
  controller "Line_Maze"
}
