#VRML_SIM R2023a utf8

EXTERNPROTO "https://raw.githubusercontent.com/cyberbotics/webots/R2023a/projects/objects/backgrounds/protos/TexturedBackground.proto"
EXTERNPROTO "https://raw.githubusercontent.com/cyberbotics/webots/R2023a/projects/objects/backgrounds/protos/TexturedBackgroundLight.proto"
EXTERNPROTO "https://raw.githubusercontent.com/cyberbotics/webots/R2023a/projects/objects/floors/protos/RectangleArena.proto"
EXTERNPROTO "https://raw.githubusercontent.com/cyberbotics/webots/R2023a/projects/appearances/protos/BrushedAluminium.proto"

WorldInfo {
}
Viewpoint {
  orientation 0.5090457897676307 -0.6406518322969765 -0.5748370322920888 4.3941741346340395
  position -0.0880257104261867 -0.6102168691866225 4.450030409553572
}
TexturedBackground {
}
TexturedBackgroundLight {
  texture "empty_office"
}
RectangleArena {
  floorSize 4 3
  floorTileSize 2.52 2.52
  floorAppearance Appearance {
    material Material {
    }
  }
  wallHeight 0.15
  wallAppearance BrushedAluminium {
    IBLStrength 8
  }
}
DEF obstacle Solid {
  translation 0.4 0.05 0.05
  children [
    DEF obs Shape {
      appearance PBRAppearance {
        metalness 0
      }
      geometry Box {
        size 0.03 0.05 0.1
      }
    }
  ]
  name "solid(3)"
  boundingObject USE obs
}
DEF obstacle4 Solid {
  translation -0.6 0.05 0.05
  children [
    DEF obs Shape {
      appearance PBRAppearance {
        metalness 0
      }
      geometry Box {
        size 0.03 0.05 0.1
      }
    }
  ]
  name "solid(6)"
  boundingObject USE obs
}
DEF obstacle2 Solid {
  translation 0 -0.3 0.05
  children [
    DEF obs Shape {
      appearance PBRAppearance {
        metalness 0
      }
      geometry Box {
        size 0.03 0.05 0.1
      }
    }
  ]
  name "solid(4)"
  boundingObject USE obs
}
DEF obstacle3 Solid {
  translation -0.6 -0.3 0.05
  children [
    DEF obs Shape {
      appearance PBRAppearance {
        metalness 0
      }
      geometry Box {
        size 0.03 0.05 0.1
      }
    }
  ]
  name "solid(5)"
  boundingObject USE obs
}
DEF wall1 Solid {
  translation -0.17 -0.43 0.075
  children [
    DEF wall1 Shape {
      appearance PBRAppearance {
        metalness 0
      }
      geometry Box {
        size 2.05 0.1 0.15
      }
    }
  ]
  name "solid(2)"
  boundingObject USE wall1
}
DEF wall1 Solid {
  translation 0 0.21 0.075
  children [
    DEF wall1 Shape {
      appearance PBRAppearance {
        metalness 0
      }
      geometry Box {
        size 2.35 0.1 0.15
      }
    }
  ]
  boundingObject USE wall1
}
Solid {
  translation 1.2 -0.11 0.075
  children [
    DEF wall2 Shape {
      appearance PBRAppearance {
        metalness 0
      }
      geometry Box {
        size 0.1 0.55 0.15
      }
    }
  ]
  name "solid(1)"
  boundingObject USE wall2
}
Robot {
  translation 1.04401 -0.607198 0.0093879
  rotation -0.0045270712191771475 0.14860504002054747 0.9888862663151249 0.0699123
  children [
    DEF LineSensor-3 DistanceSensor {
      translation -0.035 0.101 0
      rotation 0 1 0 1.5707996938995747
      name "linesensor(1)"
      type "infra-red"
    }
    DEF LineSensor-2 DistanceSensor {
      translation -0.025 0.101 0
      rotation 0 1 0 1.5707996938995747
      name "linesensor(2)"
      type "infra-red"
    }
    DEF LineSensor-1 DistanceSensor {
      translation -0.015 0.101 0
      rotation 0 1 0 1.5707996938995747
      name "linesensor(3)"
      type "infra-red"
    }
    DEF LineSensor5 DistanceSensor {
      translation 0.035 0.101 0
      rotation 0 1 0 1.5707996938995747
      name "linesensor(8)"
      type "infra-red"
    }
    DEF LineSensor4 DistanceSensor {
      translation 0.025 0.101 0
      rotation 0 1 0 1.5707996938995747
      name "linesensor(7)"
      type "infra-red"
    }
    DEF LineSensor3 DistanceSensor {
      translation 0.015 0.101 0
      rotation 0 1 0 1.5707996938995747
      name "linesensor(6)"
      type "infra-red"
    }
    DEF LineSensor2 DistanceSensor {
      translation 0.005 0.101 0
      rotation 0 1 0 1.5707996938995747
      name "linesensor(5)"
      type "infra-red"
    }
    DEF LineSensor1 DistanceSensor {
      translation -0.005 0.101 0
      rotation 0 1 0 1.5707996938995747
      name "linesensor(4)"
    }
    DEF ClasterWheel BallJoint {
      jointParameters BallJointParameters {
        position 0.3058693305752484
        anchor 0 -0.05 -0.017
      }
      jointParameters2 JointParameters {
        position 1.403873712261021
      }
      jointParameters3 JointParameters {
        position -0.8033847985655889
        axis 0 1 0
      }
      endPoint Solid {
        translation 1.022766003609946e-06 -0.050001944667162 -0.01699815840714849
        rotation 0.6997279541655967 -0.09393715197539405 -0.7082066094283364 0.6113228998406667
        children [
          DEF Claster Shape {
            appearance PBRAppearance {
              baseColor 0 0 1
              metalness 0
            }
            geometry Sphere {
              radius 0.014
            }
          }
        ]
        name "solid(2)"
        boundingObject USE Claster
        physics Physics {
        }
      }
    }
    DEF d4 DistanceSensor {
      translation -0.05 0.07 0.005
      rotation 0 0 1 3.141592653589793
      name "distance sensor(4)"
    }
    DEF d3 DistanceSensor {
      translation 0 0.07 0.005
      rotation 0 0 1 2.3561996938995744
      name "distance sensor(3)"
    }
    DEF d2 DistanceSensor {
      translation 0.05 0.07 0.005
      name "distance sensor(2)"
    }
    DEF d1 DistanceSensor {
      translation 0 0.07 0.005
      rotation 0 0 1 0.7854003061004253
      name "distance sensor(1)"
      type "infra-red"
    }
    DEF d0 DistanceSensor {
      translation 0 0.07 0.005
      rotation 0 0 1 1.5707996938995747
    }
    DEF left1 HingeJoint {
      jointParameters HingeJointParameters {
        position 270.18281873082236
        anchor 0.055 0.03 0
      }
      device [
        DEF Left_motor1 RotationalMotor {
          name "Left_motor1"
        }
      ]
      endPoint Solid {
        translation -0.07200259129342779 0.03000171848775729 -4.125143254511589e-06
        rotation -0.202537743130172 0.9585969734947785 -0.2001756853725932 1.6265620519465431
        children [
          DEF wheel Shape {
            appearance PBRAppearance {
              baseColor 0 0 1
              metalness 0
            }
            geometry Cylinder {
              height 0.01
              radius 0.03
            }
          }
        ]
        name "solid(1)"
        boundingObject USE wheel
        physics Physics {
        }
      }
    }
    DEF Body Shape {
      appearance PBRAppearance {
        metalness 0
      }
      geometry Box {
        size 0.13 0.2 0.0195
      }
    }
    DEF right1 HingeJoint {
      jointParameters HingeJointParameters {
        position -22.716158744095356
        anchor -0.055 0.03 0
      }
      device [
        RotationalMotor {
          name "Right_motor1"
        }
      ]
      endPoint Solid {
        translation 0.07199999999999918 0.029987413190701123 8.53290997689254e-06
        rotation 0.6829717539503262 0.25902858917134636 0.6829742112978476 2.634678516351194
        children [
          DEF Wheel Shape {
            appearance PBRAppearance {
              baseColor 0 0 1
              metalness 0
            }
            geometry Cylinder {
              height 0.01
              radius 0.03
            }
          }
        ]
        name "solid_motor"
        boundingObject USE Wheel
        physics Physics {
        }
      }
    }
  ]
  boundingObject USE Body
  physics Physics {
  }
  controller "my_controller"
}
